Workbook
Name _Toc375818453: SA!#REF!
Name _Toc375818454: SA!#REF!
Name _Toc375818456: SA!#REF!

Sheet 设备参数数据表
A1: 分类 | B1: 节点 | C1: 英文名称 | D1: 中文名称 | E1: 取值范围 | F1: 默认值 | G1: 类型 | H1: OAM读写权限 | I1: 网管读写权限 | J1: 前置条件 | K1: 后置影响 | L1: 注意事项 | M1: 规范/厂家定义
A2: OAM/专业/系统 | B2: 专业 | E2: （包括单位） | H2: 专业写 | I2: OAM/系统写 | J2: 专业/算法/系统 | K2: 专业/算法/系统 | L2: 填写参数的功能描述和特殊注意事项
B3: 网管信息参数表 | C3: IuhIpAddr | D3: AU板iuh口IP | G3: String(20) | I3: RW | L3: AU板iuh口IP，IP协议层所使用的IP。
B4: 网管信息参数表 | C4: IuhPort | D4: AU板iuh口port | G4: unsignedInt | I4: RW | L4: AU板iuh口port。
A5: 不在网管上显示 | B5: 网管信息参数表 | C5: SrcIpAddr | D5: AU板上层源ip | G5: String | L5: AU板上层源ip。未有用到。
A6: 不在网管上显示 | B6: 网管信息参数表 | C6: SrcPort | D6: AU板上层源port | G6: unsignedInt | L6: AU板上层源port，未有用到。
B7: 网管信息参数表 | C7: FapAddr1 | D7: GU网关ip | G7: String(20) | I7: RW | L7: GU网关ip 一
B8: 网管信息参数表 | C8: FapAddr2 | D8: GU网关ip | G8: String(20) | I8: RW | L8: GU网关ip 二（未有用到）
A9: 不在网管上显示 | B9: 网管信息参数表 | C9: FapAddr3 | D9: GU网关ip | G9: String | L9: GU网关ip 三（未有用到）
B10: 网管信息参数表 | C10: SecIpAddr1 | D10: 安全网关ip1 | G10: String(20) | I10: RW | L10: 安全网关ip一。
B11: 网管信息参数表 | C11: SecIpAddr2 | D11: 安全网关ip2 | G11: String(20) | I11: RW | L11: 安全网关ip二（未有用到）
A12: 不在网管上显示 | B12: 网管信息参数表 | C12: SecIpAddr3 | D12: 安全网关ip3 | G12: String | L12: 安全网关ip三（未有用到）
B13: 网管信息参数表 | C13: Seckey | D13: 安全网关建立密钥 | G13: String(64) | I13: R | L13: 安全网关建立密钥
B14: 网管信息参数表 | C14: SecUseImsi | D14: 建立安全网关imsi | G14: String(16) | I14: R | L14: 建立安全网关imsi
B15: 网管信息参数表 | C15: FapPort | D15: GU网关port | E15: 0~4294967295 | F15: 29169 | G15: unsignedInt | I15: RW | L15: GU网关port。
B16: 网管信息参数表 | C16: IpSecStartAllowedInd | D16: IPSec是否启动开关 | E16: true、false | F16: true | G16: boolean | I16: RW | L16: IpSec开关。 取值false：关闭Ipsec功能 取值true：打开Ipsec功能
B17: 网管信息参数表 | C17: IpSecRekeyTime | D17: ipSec rekey时间 | E17: 0~4294967295(分钟） | F17: 80000 | G17: unsignedInt | I17: RW | L17: IpSec重协商时间。单位：分钟
B18: 网管信息参数表 | C18: IpSecSaLifetime | D18: IPSec SA的生命周期 | E18: 0~4294967295（秒） | F18: 30 | G18: unsignedInt | I18: RW | L18: IPSec SA的生命周期。单位：秒
B19: 网管信息参数表 | C19: IpSecLivenessTimeInterval | D19: liveness时间间隔 | G19: unsignedInt | I19: RW | L19: liveness时间间隔。
A20: 不在网管上显示 | B20: 网管信息参数表 | C20: FapPcSocketIpAddr | D20: 调试日志放置设备IP | G20: String | L20: 调试日志放置设备IP（调试电脑）
A21: 不在网管上显示 | B21: 网管信息参数表 | C21: FapPcSocketPort | D21: 调试日志放置设备端口 | G21: unsignedInt | L21: 调试日志放置设备端口（调试电脑）
B22: 网管信息参数表 | C22: RealIpAddrToPing | D22: 用于ping功能的真实站点IpAddr | G22: String | I22: R | L22: 用于ping功能的真实站点IpAddr
B23: 网管信息参数表 | C23: GateWaySupported | D23: 指示当前所要连接的网关能力 | G23: unsignedInt | I23: RW | L23: 用于指示当前所要连接的网关能力 取值0：网关支持E1+Surf 取值1：网关支持STM-1+ATCA9100 取值2：网关支持AoIP
B24: 网管信息参数表 | C24: Mode | D24: 认证模式 | E24: 0~2 | G24: int | I24: RW | L24: mode为0,为PSK认证，mode为1为usim卡认证，mode为2为sim卡证（预留），-1为非法值，mode为其它值暂时保留
B25: 公共参数表 | C25: AuId | D25: AU注册是使用的基站Id | E25: 0~65535 | G25: unsignedInt | I25: RW | L25: AU注册是使用的基站Id。 取值范围：0~65535
B26: 公共参数表 | C26: A50 | D26: 是否支持A5_0类型加密 | E26: true、false | F26: true | G26: boolean | I26: RW | L26: 物理层是否支持A5_0类型加密。 取值false：不支持 取值true：支持
B27: 公共参数表 | C27: A51 | D27: 是否支持A5_1类型加密 | E27: true、false | F27: true | G27: boolean | I27: RW | L27: 物理层是否支持A5_1类型加密。 取值false：不支持 取值true：支持
B28: 公共参数表 | C28: A52 | D28: 是否支持A5_2类型加密 | E28: true、false | F28: true | G28: boolean | I28: RW | L28: 物理层是否支持A5_2类型加密。 取值false：不支持 取值true：支持
B29: 公共参数表 | C29: A53 | D29: 是否支持A5_3类型加密 | E29: true、false | F29: true | G29: boolean | I29: RW | L29: 物理层是否支持A5_3类型加密。 取值false：不支持 取值true：支持
B30: 公共参数表 | C30: A54 | D30: 是否支持A5_4类型加密 | E30: true、false | F30: false | G30: boolean | I30: RW | L30: 物理层是否支持A5_4类型加密。 取值false：不支持 取值true：支持
B31: 公共参数表 | C31: A55 | D31: 是否支持A5_5类型加密 | E31: true、false | F31: false | G31: boolean | I31: RW | L31: 物理层是否支持A5_5类型加密。 取值false：不支持 取值true：支持
B32: 公共参数表 | C32: A56 | D32: 是否支持A5_6类型加密 | E32: true、false | F32: false | G32: boolean | I32: RW | L32: 物理层是否支持A5_6类型加密。 取值false：不支持 取值true：支持
B33: 公共参数表 | C33: A57 | D33: 是否支持A5_7类型加密 | E33: true、false | F33: false | G33: boolean | I33: RW | L33: 物理层是否支持A5_7类型加密。 取值false：不支持 取值true：支持
A34: 不在网管上显示 | B34: 公共参数表 | C34: AuUserAccessMax | D34: 户型允许接入的用户数上限 | G34: unsignedInt | L34: 根据户型允许接入的用户数上限。 该参数上层暂时未有使用，保留。
A35: 不在网管上显示 | B35: 公共参数表 | C35: AuAlowPwrMax | D35: 户型允许最大发射功率 | G35: unsignedInt | L35: 根据户型允许最大发射功率 该参数上层暂时未有使用，保留。
B36: 公共参数表 | C36: LogTotalSize | D36: 单个日志文件大小 | E36: 0~4294967295(KByte) | F36: 3*1024 | G36: unsignedInt | I36: RW | L36: 日志文件的总大小，以1k Byte为单位
A37: 不在网管上显示 | B37: 公共参数表 | C37: LogTxtNumberMax | D37: 同类型日志文件存储最大文件个数 | G37: unsignedInt | L37: 同类型日志文件存储最大文件个数。 该参数上层暂时未有使用，保留。
B38: 公共参数表 | C38: LogOutputLevel | D38: 日志输出类型 | E38: 0~4 | F38: 1 | G38: unsignedInt | I38: RW | L38: 日志输出级别。 取值范围：0~4 取值0：DEBUG 取值1：INFO 取值2：TRACE 取值3：WARN 取值4：ERROR
A39: 不在网管上显示 | B39: 公共参数表 | C39: AuProductType | D39: Au产品类型 | L39: Au产品类型,取值范围：0~3 取值0：普通型原型机产品 取值1：企业级大容量产品 取值2：企业级eNB 3+1产品 取值3：普通型降成本产品
A40: 不在网管上显示 | B40: 公共参数表 | C40: AuRfWorkBandCapability | D40: 基站射频支持的工作频段能力 | E40: 0~3 | F40: 0 | G40: unsignedInt | L40: 基站射频支持的工作频段能力，取值范围：0~3 取值0：基站支持1800工作频段 取值1：基站支持900工作频段 取值2：基站支持900E工作频段 取值3：基站支持1900工作频段
...

Sheet 修订历史
C2: 中国电信5G小基站南向接口数据模型修改记录
A4: 版本 | B4: 日期 | C4: 修订内容 | D4: 修订人
A5: v1.0.0 | B5: 44565 | C5: 创建初稿 | D5: 李慧云
A6: v2.0.0 | B6: 44648 | C6: 增加了ST：Qos参数管理 | D6: 李慧云
A7: V2.0.1 | B7: 44650 | C7: SA： Device.DeviceInfo.MU.{i}.ClockSyncmode修改为Device.DeviceInfo.MU.{i}.ClockSyncMode SG: 删掉了以下参数： Device.Services.FAPService.{i}.FAPControl.NR.AMFPoolConfigParam.{i}.LocalUpIPAddress Device.Services.FAPService.{i}.FAPControl.NR.AMFPoolConfigParam.{i}.LocalUpIPV6Address Device.Services.FAPService.{i}.FAPControl.NR.AMFPoolConfigParam.{i}.LocalCpIPAddress Device.Services.FAPService.{i}.FAPControl.NR.AMFPoolConfigParam.{i}.LocalCpIPV6Address SK： 新增以下参数： Device.Services.FAPService.{i}.CellConfig.{i}.NR.RAN.PHY.RfConfig.FrequencyInfoDl.AbsoluteFrequencySSB SO: Device.Ethernet.Interface.{i}.IPv4Address.{i}.PortType的读写属性从R变为RW Device.Ethernet.Interface.{i}.IPv6Address.{i}.PortType的读写属性从R变为RW Device.Ethernet.Interface.{i}.VlanInterface.{i}.IPv4Address.{i}.PortType的读写属性从R变为RW Device.Ethernet.Interface.{i}.VlanInterface.{i}.IPv6Address.{i}.PortType的读写属性从R变为RW | D7: 李慧云
A8: V2.0.2 | B8: 44672 | C8: SA： 修改了对Device.DeviceInfo.MU.{i}.Slot.{i}.EU.{i}.RouteIndex的描述 修改了对Device.DeviceInfo.MU.{i}.Slot.{i}.EU.{i}.RU.{i}.RouteIndex的描述 Device.DeviceInfo.MU.{i}.Slot.{i}.EU.{i}.RU.{i}.*的限定修改为MC 新增扩展型基站-扩展远端单元（ERU）参数管理 新增扩展型基站-拉远覆盖增强单元（DRU）参数管理 SL： Device.Services.FAPService.{i}.CellConfig.{i}.NR.RAN.NeighborList.NRCell.{i}.NoHO Device.Services.FAPService.{i}.CellConfig.{i}.NR.RAN.NeighborList.NRCell.{i}.NoRemove Device.Services.FAPService.{i}.CellConfig.{i}.NR.RAN.NeighborList.NRCell.{i}.NoXn 修改为： Device.Services.FAPService.{i}.CellConfig.{i}.NR.RAN.NeighborList.NRCell.{i}.NoHOEnable Device.Services.FAPService.{i}.CellConfig.{i}.NR.RAN.NeighborList.NRCell.{i}.NoRemoveEnable Device.Services.FAPService.{i}.CellConfig.{i}.NR.RAN.NeighborList.NRCell.{i}.NoXnEnable Device.Services.FAPService.{i}.CellConfig.{i}.NR.RAN.NeighborList.LTECell.{i}.NoHO Device.Services.FAPService.{i}.CellConfig.{i}.NR.RAN.NeighborList.LTECell.{i}.NoRemove Device.Services.FAPService.{i}.CellConfig.{i}.NR.RAN.NeighborList.LTECell.{i}.NoX2 修改为： Device.Services.FAPService.{i}.CellConfig.{i}.NR.RAN.NeighborList.LTECell.{i}.NoHOEnable Device.Services.FAPService.{i}.CellConfig.{i}.NR.RAN.NeighborList.LTECell.{i}.NoRemoveEnable Device.Services.FAPService.{i}.CellConfig.{i}.NR.RAN.NeighborList.LTECell.{i}.NoX2Enable | D8: 李慧云
A9: V2.0.3 | B9: 44673 | C9: SB： 增加以下节点： Device.DeviceInfo.AdditionalHardwareVersion Device.DeviceInfo.AdditionalSoftwareVersion Device.DeviceInfo.DataModelSpecVersion SG： 删除以下节点： Device.Services.FAPService.{i}.FAPControl.NR.AMFPoolConfigParam.{i}.SCTPInstId Device.Services.FAPService.{i}.FAPControl.NR.XnIpAddrMapInfo.{i}.SCTPInstId Device.Services.FAPService.{i}.FAPControl.NR.X2IpAddrMapInfo.{i}.SCTPInstId SK：增加以下节点： Device.Services.FAPService.{i}.CellConfig.{i}.NR.RAN.PHY.BWP.BWPUL.{i}.PUSCH.UlAdditionalDmrsPos Device.Services.FAPService.{i}.CellConfig.{i}.NR.RAN.PHY.BWP.BWPDL.{i}.PDSCH.DlAdditionalDmrsPos SM：增加以下节点： Device.Services.FAPService.{i}.CellConfig.{i}.NR.RAN.Mobility.ConnMode.NR.ReportCGI.{i}.PhysCellId SN： SCTP修改为单实例 去掉节点：Device.Services.FAPService.{i}.Transport.SCTP.{i}.SctpID SR: 增加以下节点： Device.FAP.MRMgmt.Config.{i}.MRNCGIList Device.FAP.MRMgmt.Config.{i}.PrbNum Device.FAP.MRMgmt.Config.{i}.SubFrameNum Device.FAP.MRMgmt.Config.{i}.MeasureItems ST： 以下节点的限定性从O修改为M： Device.Services.FAPService.{i}.CellConfig.{i}.NR.NGC.QoS.{i}.PDCP.SNSizeUL Device.Services.FAPService.{i}.CellConfig.{i}.NR.NGC.QoS.{i}.PDCP.SNSizeDL Device.Services.FAPService.{i}.CellConfig.{i}.NR.NGC.QoS.{i}.PDCP.DiscardTimer Device.Services.FAPService.{i}.CellConfig.{i}.NR.NGC.QoS.{i}.RLC.AM.SNSize Device.Services.FAPService.{i}.CellConfig.{i}.NR.NGC.QoS.{i}.RLC.UM.SNSize | D9: 李慧云
A10: V2.0.4 | B10: 44673 | C10: SO： 增加本地路由配置管理参数： Device.Ethernet.IpRoute.{i}.IpVer Device.Ethernet.IpRoute.{i}.DstIpNetwork Device.Ethernet.IpRoute.{i}.PrefixLength Device.Ethernet.IpRoute.{i}.GatewayIpAddress Device.Ethernet.IpRoute.{i}.InterfaceName 以下节点的限定从M修改为MC： Device.Ethernet.Interface.{i}.VlanInterface.{i}.IPv6Address.{i}.IPAddress Device.Ethernet.Interface.{i}.VlanInterface.{i}.IPv6Address.{i}.PrefixLength Device.Ethernet.Interface.{i}.VlanInterface.{i}.IPv6Address.{i}.Origin Device.Ethernet.Interface.{i}.VlanInterface.{i}.IPv6Address.{i}.DefaultGateway Device.Ethernet.Interface.{i}.VlanInterface.{i}.IPv6Address.{i}.PortType | D10: 李慧云
A11: V2.0.5 | B11: 44675 | C11: SI增加以下节点参数： Device.Services.FAPService.{i}.FAPControl.SelfConfig.Startup.Stage Device.Services.FAPService.{i}.FAPControl.SelfConfig.Startup.Status Device.Services.FAPService.{i}.FAPControl.SelfConfig.Startup.FailureCause | D11: 李慧云
A12: V2.0.6 | B12: 44685 | C12: SA增加以下节点参数： Device.DeviceInfo.MU.{i}.Slot.{i}.EU.{i}.ERU.{i}.DRU.{i}.DeviceId 修正了部分参数的数据类型 | D12: 李慧云
A13: V2.0.7 | B13: 44687 | C13: SK：修正了部分参数的数据类型，和行标保持一致 SR：Device.FAP.MRMgmt.Config.{i}.UploadPeriod的数据类型修改为15及15的倍数 | D13: 李慧云
A14: V2.0.8 | B14: 44698 | C14: SJ: Device.Services.FAPService.{i}.CellConfig.{i}.NR.VoNR.VoNRList.{i}.PLMNID Device.Services.FAPService.{i}.CellConfig.{i}.NR.VoNR.VoNRList.{i}.VoSupport Device.Services.FAPService.{i}.CellConfig.{i}.NR.VoNR.VoNRList.{i}.Vo5qi 限定性从O修改为M | D14: 李慧云
A15: V2.0.9 | B15: 44703 | C15: 1、SB:删除以下参数 Device.DeviceInfo.AccessCtrl.UeNumber Device.DeviceInfo.AccessCtrl.AccessTimelen Device.DeviceInfo.AccessCtrl.CtrlState Device.DeviceInfo.Status去掉“离线”状态的上报 2、SK：删除以下参数 Device.Services.FAPService.{i}.CellConfig.{i}.NR.RAN.PHY.FrequencyInfoULSIB.AbsoluteFrequencyPointA 3、删除高速场景相关的参数 SM： Device.Services.FAPService.{i}.CellConfig.{i}.NR.RAN.Mobility.IdleMode.Common.SpeedStateReselectionPars.Enable Device.Services.FAPService.{i}.CellConfig.{i}.NR.RAN.Mobility.IdleMode.Common.SpeedStateReselectionPars.MobState.TEvaluation Device.Services.FAPService.{i}.CellConfig.{i}.NR.RAN.Mobility.IdleMode.Common.SpeedStateReselectionPars.MobState.THystNormal Device.Services.FAPService.{i}.CellConfig.{i}.NR.RAN.Mobility.IdleMode.Common.SpeedStateReselectionPars.MobState.NCellChangeHigh Device.Services.FAPService.{i}.CellConfig.{i}.NR.RAN.Mobility.IdleMode.Common.SpeedStateReselectionPars.MobState.NCellChangeMedium Device.Services.FAPService.{i}.CellConfig.{i}.NR.RAN.Mobility.IdleMode.Common.SpeedStateReselectionPars.QHystSF.SFMedium Device.Services.FAPService.{i}.CellConfig.{i}.NR.RAN.Mobility.IdleMode.Common.SpeedStateReselectionPars.QHystSF.SFHigh Device.Services.FAPService.{i}.CellConfig.{i}.NR.RAN.Mobility.IdleMode.IntraFreq.TReselectionNRSF.Enable Device.Services.FAPService.{i}.CellConfig.{i}.NR.RAN.Mobility.IdleMode.IntraFreq.TReselectionNRSF.SFHigh Device.Services.FAPService.{i}.CellConfig.{i}.NR.RAN.Mobility.IdleMode.IntraFreq.TReselectionNRSF.SFMedium Device.Services.FAPService.{i}.CellConfig.{i}.NR.RAN.Mobility.IdleMode.InterFreq.Carrier.{i}.TReselectionNRSF.Enable Device.Services.FAPService.{i}.CellConfig.{i}.NR.RAN.Mobility.IdleMode.InterFreq.Carrier.{i}.TReselectionNRSF.SFHigh Device.Services.FAPService.{i}.CellConfig.{i}.NR.RAN.Mobility.IdleMode.InterFreq.Carrier.{i}.TReselectionNRSF.SFMedium Device.Services.FAPService.{i}.CellConfig.{i}.NR.RAN.Mobility.IdleMode.EUTRA.TReselectionSF.Enable Device.Services.FAPService.{i}.CellConfig.{i}.NR.RAN.Mobility.IdleMode.EUTRA.TReselectionSF.SFHigh Device.Services.FAPService.{i}.CellConfig.{i}.NR.RAN.Mobility.IdleMode.EUTRA.TReselectionSF.SFMedium 4、SS： Device.FAP.PerfMgmt.Config.{i}.PeriodicUploadInterval 文件上传周期间隔去掉600的周期 5、数据模型中的dateTime统一为UTC时间 6、修改了部分数据参数的限定性说明 7、SK删除以下配置参数 Device.Services.FAPService.{i}.CellConfig.{i}.NR.RAN.PHY.BWP.BWPDL.{i}.PDSCH.ResourceAllocationAdaptiveValue Device.Services.FAPService.{i}.CellConfig.{i}.NR.RAN.PHY.BWP.BWPDL.{i}.PDCCH..ControlResourceSetToAddModList.{i}.DciType Device.Services.FAPService.{i}.CellConfig.{i}.NR.RAN.PHY.BWP.BWPUL.{i}.PUCCHPowerControl.PucchPcSwitch Device.Services.FAPService.{i}.CellConfig.{i}.NR.RAN.PHY.BWP.BWPUL.{i}.PUSCHPowerControl.PuschPcSwitch Device.Services.FAPService.{i}.CellConfig.{i}.NR.RAN.PHY.PowerControl.PhrModeOtherCg Device.Services.FAPService.{i}.CellConfig.{i}.NR.RAN.UserLabel SK参数名称修改： Device.Services.FAPService.{i}.CellConfig.{i}.NR.RAN.PHY.MAC.LinkAdaptation.Reserved.McsForDbch修改为Device.Services.FAPService.{i}.CellConfig.{i}.NR.RAN.PHY.MAC.LinkAdaptation.Reserved.McsForSIB1 Device.Services.FAPService.{i}.CellConfig.{i}.NR.RAN.PHY.MAC.Dl.DlLayers修改为Device.Services.FAPService.{i}.CellConfig.{i}.NR.RAN.PHY.MAC.Dl.DlMaxLayers Device.Services.FAPService.{i}.CellConfig.{i}.NR.RAN.PHY.MAC.Ul.UlLayers修改为Device.Services.FAPService.{i}.CellConfig.{i}.NR.RAN.PHY.MAC.Ul.UlMaxLayers SK参数的数据类型修改： Device.Services.FAPService.{i}.CellConfig.{i}.NR.RAN.PHY.MAC.Dl.DlMaxLayers 约束修改为(1~8) Device.Services.FAPService.{i}.CellConfig.{i}.NR.RAN.PHY.MAC.Ul.UlMaxLayers 约束修改为(1~4) Device.Services.FAPService.{i}.CellConfig.{i}.NR.RAN.PHY.MAC.Ul.MaxHarqReTx 约束修改为(0~9) | D15: 李慧云

Sheet 封面
B3: TD-LTE NanoCell南向数据配置模型规范(推荐版)
B5: 概述（详细问题请查阅正文内容）：
B6: TD-LTE NanoCell南向数据配置模型规范(推荐版)
B7: 文档适应的产品 | D7: 移动 NanoCell
B10: 文档详细信息 | D10: 版本 | E10: 作者 | F10: 时间 | G10: 来源 | H10: 注释
B11: TD-LTE NanoCell网管数据模型规范(初稿) | D11: 首发 | E11: 京信团队 | F11: 42535
G15: 京信通信系统（广州）有限公司

Sheet 目录
A1: 索引 | B1: 参数管理类别 | C1: 参数管理说明 | D1: 必选（M）类属性数 | E1: 条件必选（MC）类属性数 | F1: 可选（O)类属性数 | G1: 小计
A2: SA | B2: DeviceInfo | C2: 扩展型基站设备信息参数管理 | D2: =COUNTIF(SA!$E:$E,"M") -> 56 | E2: =COUNTIF(SA!$E:$E,"MC") -> 49 | F2: =COUNTIF(SA!$E:$E,"O") -> 0 | G2: =SUM($D2:$F2) -> 105
A3: SB | B3: DeviceInfo | C3: 一体化基站设备信息参数管理 | D3: =COUNTIF(SB!$E:$E,"M") -> 20 | E3: =COUNTIF(SB!$E:$E,"MC") -> 0 | F3: =COUNTIF(SB!$E:$E,"O") -> 0 | G3: =SUM($D3:$F3) -> 20
A4: SC | B4: SoftwareCtrl | C4: 软件版本参数管理 | D4: =COUNTIF(SC!$E:$E,"M") -> 3 | E4: =COUNTIF(SC!$E:$E,"MC") -> 0 | F4: =COUNTIF(SC!$E:$E,"O") -> 2 | G4: =SUM($D4:$F4) -> 5
A5: SD | B5: ManagementServer | C5: 基站网管参数管理 | D5: =COUNTIF(SD!$E:$E,"M") -> 10 | E5: =COUNTIF(SD!$E:$E,"MC") -> 0 | F5: =COUNTIF(SD!$E:$E,"O") -> 9 | G5: =SUM($D5:$F5) -> 19
A6: SE | B6: FaultMgmt | C6: 告警参数管理 | D6: =COUNTIF(SE!$E:$E,"M") -> 59 | E6: =COUNTIF(SE!$E:$E,"MC") -> 0 | F6: =COUNTIF(SE!$E:$E,"O") -> 0 | G6: =SUM($D6:$F6) -> 59
A7: SF | B7: DeviceLogMgmt | C7: 日志参数管理 | D7: =COUNTIF(SF!$E:$E,"M") -> 5 | E7: =COUNTIF(SF!$E:$E,"MC") -> 0 | F7: =COUNTIF(SF!$E:$E,"O") -> 1 | G7: =SUM($D7:$F7) -> 6
A8: SG | B8: Services.FAPService.{i}.FAPControl.NR | C8: 基站配置参数管理 | D8: =COUNTIF(SG!$E:$E,"M") -> 29 | E8: =COUNTIF(SG!$E:$E,"MC") -> 0 | F8: =COUNTIF(SG!$E:$E,"O") -> 16 | G8: =SUM($D8:$F8) -> 45
A9: SH | B9: Services.FAPService.{i}.Capabilities.NR | C9: 基站能力参数管理 | D9: =COUNTIF(SH!$E:$E,"M") -> 1 | E9: =COUNTIF(SH!$E:$E,"MC") -> 0 | F9: =COUNTIF(SH!$E:$E,"O") -> 0 | G9: =SUM($D9:$F9) -> 1
A10: SI | B10: Services.FAPService.{i}.FAPControl.NR.SelfConfig.SONConfigParam | C10: SON参数管理 | D10: =COUNTIF(SI!$E:$E,"M") -> 3 | E10: =COUNTIF(SI!$E:$E,"MC") -> 17 | F10: =COUNTIF(SI!$E:$E,"O") -> 17 | G10: =SUM($D10:$F10) -> 37
A11: SJ | B11: Services.FAPService.{i}.CellConfig.{i}.NR | C11: 小区服务参数管理（总体） | D11: =COUNTIF(SJ!$E:$E,"M") -> 39 | E11: =COUNTIF(SJ!$E:$E,"MC") -> 0 | F11: =COUNTIF(SJ!$E:$E,"O") -> 34 | G11: =SUM($D11:$F11) -> 73
A12: SK | B12: Services.FAPService.{i}.CellConfig.{i}.NR.RAN | C12: RAN协议栈参数 | D12: =COUNTIF(SK!$E:$E,"M") -> 120 | E12: =COUNTIF(SK!$E:$E,"MC") -> 130 | F12: =COUNTIF(SK!$E:$E,"O") -> 15 | G12: =SUM($D12:$F12) -> 265
A13: SL | B13: Services.FAPService.{i}.CellConfig.{i}.NR.RAN.NeighborList | C13: 邻区参数管理 | D13: =COUNTIF(SL!$E:$E,"M") -> 24 | E13: =COUNTIF(SL!$E:$E,"MC") -> 8 | F13: =COUNTIF(SL!$E:$E,"O") -> 0 | G13: =SUM($D13:$F13) -> 32
A14: SM | B14: Services.FAPService.{i}.CellConfig.{i}.NR.RAN.Mobility | C14: 移动性参数管理 | D14: =COUNTIF(SM!$E:$E,"M") -> 128 | E14: =COUNTIF(SM!$E:$E,"MC") -> 59 | F14: =COUNTIF(SM!$E:$E,"O") -> 63 | G14: =SUM($D14:$F14) -> 250
A15: SN | B15: Services.FAPService.{i}.Transport.SCTP | C15: SCTP参数管理 | D15: =COUNTIF(SN!$E:$E,"M") -> 9 | E15: =COUNTIF(SN!$E:$E,"MC") -> 0 | F15: =COUNTIF(SN!$E:$E,"O") -> 0 | G15: =SUM($D15:$F15) -> 9
A16: SO | B16: Ethernet.Interface | C16: WAN口配置参数管理 | D16: =COUNTIF(SO!$E:$E,"M") -> 20 | E16: =COUNTIF(SO!$E:$E,"MC") -> 11 | F16: =COUNTIF(SO!$E:$E,"O") -> 5 | G16: =SUM($D16:$F16) -> 36
A17: SP | B17: Time | C17: 时间服务器参数管理 | D17: =COUNTIF(SP!$E:$E,"M") -> 5 | E17: =COUNTIF(SP!$E:$E,"MC") -> 0 | F17: =COUNTIF(SP!$E:$E,"O") -> 3 | G17: =SUM($D17:$F17) -> 8
A18: SQ | B18: FAP.GPS | C18: GPS信息参数管理 | D18: =COUNTIF(SQ!$E:$E,"M") -> 0 | E18: =COUNTIF(SQ!$E:$E,"MC") -> 0 | F18: =COUNTIF(SQ!$E:$E,"O") -> 3 | G18: =SUM($D18:$F18) -> 3
A19: SR | B19: FAP.MRMgmt | C19: MR参数管理 | D19: =COUNTIF(SR!$E:$E,"M") -> 0 | E19: =COUNTIF(SR!$E:$E,"MC") -> 13 | F19: =COUNTIF(SR!$E:$E,"O") -> 0 | G19: =SUM($D19:$F19) -> 13
A20: SS | B20: FAP.PerfMgmt | C20: 性能参数管理 | D20: =COUNTIF(SS!$E:$E,"M") -> 10 | E20: =COUNTIF(SS!$E:$E,"MC") -> 0 | F20: =COUNTIF(SS!$E:$E,"O") -> 0 | G20: =SUM($D20:$F20) -> 10
A21: ST | B21: Services.FAPService.{i}.CellConfig.{i}.NR.NGC.QoS. | C21: Qos参数管理 | D21: =COUNTIF(ST!$E:$E,"M") -> 8 | E21: =COUNTIF(ST!$E:$E,"MC") -> 0 | F21: =COUNTIF(ST!$E:$E,"O") -> 24 | G21: =SUM($D21:$F21) -> 32
A22: 合计 | D22: =SUM(D2:D21) -> 549 | E22: =SUM(E2:E21) -> 287 | F22: =SUM(F2:F21) -> 192 | G22: =SUM($D22:$F22) -> 1028

Sheet SA
A1: 归类 | B1: 参数路径 | C1: 英文名称 | D1: 中文名称 | E1: 限定 | F1: 网管读写权限 | G1: 类型 | H1: 描述 | I1: 备注
A2: 主机单元（MU）设备信息参数管理 | B2: Device.DeviceInfo.MU.{i}.ManufacturerOUI | C2: ManufacturerOUI | D2: 制造商OUI | E2: M | F2: R | G2: string(6) | H2: /
B3: Device.DeviceInfo.MU.{i}.Manufacturer | C3: Manufacturer | D3: 制造商 | E3: M | F3: R | G3: string(64) | H3: /
B4: Device.DeviceInfo.MU.{i}.ModelName | C4: ModelName | D4: 设备型号 | E4: M | F4: R | G4: string(64) | H4: /
B5: Device.DeviceInfo.MU.{i}.SerialNumber | C5: SerialNumber | D5: 序列号 | E5: M | F5: R | G5: string(64) | H5: /
B6: Device.DeviceInfo.MU.{i}.HardwareVersion | C6: HardwareVersion | D6: 硬件版本 | E6: M | F6: R | G6: string(64) | H6: /
B7: Device.DeviceInfo.MU.{i}.SoftwareVersion | C7: SoftwareVersion | D7: 软件版本 | E7: M | F7: R | G7: string(64) | H7: /
B8: Device.DeviceInfo.MU.{i}.HardwarePlatform | C8: HardwarePlatform | D8: 硬件平台 | E8: M | F8: R | G8: string(64) | H8: /
B9: Device.DeviceInfo.MU.{i}.AdditionalHardwareVersion | C9: AdditionalHardwareVersion | D9: 附加硬件版本 | E9: M | F9: R | G9: string(64) | H9: /
B10: Device.DeviceInfo.MU.{i}.AdditionalSoftwareVersion | C10: AdditionalSoftwareVersion | D10: 附加软件版本 | E10: M | F10: R | G10: string(64) | H10: /
B11: Device.DeviceInfo.MU.{i}.ProvisioningCode | C11: ProvisioningCode | D11: 供应商代号 | E11: M | F11: R | G11: string(64) | H11: /
B12: Device.DeviceInfo.MU.{i}.ProductClass | C12: ProductClass | D12: 产品分类 | E12: M | F12: R | G12: string(64) | H12: /
B13: Device.DeviceInfo.MU.{i}.Status | C13: Status | D13: 机框/服务器状态 | E13: M | F13: R | G13: unsignedInt[1:3] | H13: 1:正常 2:离线 3:告警
B14: Device.DeviceInfo.MU.{i}.Reboot | C14: Reboot | D14: 重启开关 | E14: M | F14: RW | G14: boolean | H14: 0:不重启 1:重启
B15: Device.DeviceInfo.MU.{i}.UpTime | C15: UpTime | D15: 运行时间 | E15: M | F15: R | G15: unsignedInt | H15: 设备从上次重启后的运行时间，单位：秒 | I15: 0-‭4294967295‬
B16: Device.DeviceInfo.MU.{i}.FirstUseDate | C16: FirstUseDate | D16: 首次使用日期 | E16: M | F16: R | G16: dateTime | H16: UTC时间格式，YYYY-MM-DDTHH:MM:SSZ，例如2012-12-11T09:15:00Z
B17: Device.DeviceInfo.MU.{i}.ClockSource | C17: ClockSource | D17: 时钟源 | E17: M | F17: R | G17: unsignedInt[1:11] | H17: Enumerate{ GPS, GLONASS, BDS, 1588v2, GPS/GLONASS, // GPS 为主，GLONASS 为从 BDS/GPS， GPS/BDS， GALILEO， GPS/GALILEO， GPS/GALILEO/GLONASS, GPS/GALILEO/BDS }
B18: Device.DeviceInfo.MU.{i}.ClockSyncMode | C18: ClockSyncMode | D18: 时钟同步方式 | E18: M | F18: R | G18: unsignedInt[1:3] | H18: 1:空口同步 2:人工同步 3:自动同步
B19: Device.DeviceInfo.MU.{i}.SwUpgrade.Stage | C19: Stage | D19: 升级阶段 | E19: M | F19: R | G19: unsignedInt[1:5] | H19: 1:初始化 2:下载 3:安装 4:等待激活 5.激活
B20: Device.DeviceInfo.MU.{i}.SwUpgrade.Status | C20: Status | D20: 状态 | E20: M | F20: R | G20: unsignedInt[1:3] | H20: 1:成功 2:进行中 3:失败
B21: Device.DeviceInfo.MU.{i}.SwUpgrade.FailureCause | C21: FailureCause | D21: 升级失败原因 | E21: M | F21: R | G21: string | H21: 升级失败原因描述
B22: Device.DeviceInfo.MU.{i}.DateOfManufacture | C22: DateOfManufacture | D22: 生产日期 | E22: M | F22: R | G22: dateTime | H22: UTC时间格式，YYYY-MM-DDTHH:MM:SSZ，例如2012-12-11T09:15:00Z
B23: Device.DeviceInfo.MU.{i}.Slot.{i}.PackPosition | C23: PackPosition | D23: 板卡位置 | E23: M | F23: R | G23: string(64) | H23: 板卡在机框内的相对位置，通常用编号表示。数据格式定义为“机柜-机框-槽号”
B24: Device.DeviceInfo.MU.{i}.Slot.{i}.SlotsOccupied | C24: SlotsOccupied | D24: 占用槽位 | E24: M | F24: R | G24: string(64) | H24: 应表示板卡占用的槽位号列表。（注：一些板卡较宽，可能会占用两个或以上槽位）
B25: Device.DeviceInfo.MU.{i}.Slot.{i}.ManufacturerOUI | C25: ManufacturerOUI | D25: 制造商OUI | E25: M | F25: R | G25: string(6) | H25: /
B26: Device.DeviceInfo.MU.{i}.Slot.{i}.Manufacturer | C26: Manufacturer | D26: 制造商 | E26: M | F26: R | G26: string(64) | H26: /
B27: Device.DeviceInfo.MU.{i}.Slot.{i}.ModelName | C27: ModelName | D27: 设备型号 | E27: M | F27: R | G27: string(64) | H27: /
... B32: Device.DeviceInfo.MU.{i}.Slot.{i}.VendorUnitFamilyType | C32: VendorUnitFamilyType | D32: 板卡类型 | E32: M | F32: R | G32: string(64) | H32: 描述板卡功能类型。List of Enum{ 板卡类型（枚举）}。其中板卡类型的为Enumerate{MainControl，Carrier，Trans，Other}，分别表示主控板、载频板、传输板、其他板卡类型。对跨类型的板卡，列表中应包括该板卡的全部功能类型。（必须上报）
B33: Device.DeviceInfo.MU.{i}.Slot.{i}.UpTime | C33: UpTime | D33: 运行时间 | E33: M | F33: R | G33: unsignedInt | H33: 设备从上次重启后的运行时间，单位：秒 | I33: 0-‭4294967295‬
B34: Device.DeviceInfo.MU.{i}.Slot.{i}.DateOfManufacture | C34: DateOfManufacture | D34: 生产日期 | E34: M | F34: R | G34: dateTime | H34: UTC时间格式，YYYY-MM-DDTHH:MM:SSZ，例如2012-12-11T09:15:00Z
B35: Device.DeviceInfo.MU.{i}.Slot.{i}.DataModelSpecVersion | C35: DataModelSpecVersion | D35: 数据模型版本 | E35: M | F35: R | G35: string | H35: /
B36: Device.DeviceInfo.MU.{i}.Slot.{i}.3GPPSpecVersion | C36: 3GPPSpecVersion | D36: 3GPP协议版本 | E36: M | F36: R | G36: string | H36: /
B37: Device.DeviceInfo.MU.{i}.Slot.{i}.FirstUseDate | C37: FirstUseDate | D37: 首次使用日期 | E37: M | F37: R | G37: dateTime | H37: UTC时间格式，YYYY-MM-DDTHH:MM:SSZ，例如2012-12-11T09:15:00Z
B38: Device.DeviceInfo.MU.{i}.Slot.{i}.Status | C38: Status | D38: 板卡状态 | E38: M | F38: R | G38: unsignedInt[1:3] | H38: 1:正常 2:离线 3:告警
B39: Device.DeviceInfo.MU.{i}.Slot.{i}.Reboot | C39: Reboot | D39: 重启开关 | E39: M | F39: RW | G39: boolean | H39: 0:不重启 1:重启
B40: Device.DeviceInfo.MU.{i}.Slot.{i}.SwUpgrade.Stage | C40: Stage | D40: 升级阶段 | E40: M | F40: R | G40: unsignedInt[1:5] | H40: 1:初始化 2:下载 3:安装 4:等待激活 5.激活
B41: Device.DeviceInfo.MU.{i}.Slot.{i}.SwUpgrade.Status | C41: Status | D41: 状态 | E41: M | F41: R | G41: unsignedInt[1:3] | H41: 1:成功 2:进行中 3:失败
B42: Device.DeviceInfo.MU.{i}.Slot.{i}.SwUpgrade.FailureCause | C42: FailureCause | D42: 升级失败原因 | E42: M | F42: R | G42: string | H42: 升级失败原因描述
A43: 扩展型基站-扩展单元（EU）参数管理 | B43: Device.DeviceInfo.MU.{i}.Slot.{i}.EU.{i}.RouteIndex | C43: RouteIndex | D43: 扩展单元路由指示 | E43: M | F43: R | G43: string(64) | H43: 1.扩展型皮基站主机单元与各扩展单元和远端单元可采用树状组网方式（包含菊花链、星形等）：主机单元为根节点，扩展单元为树枝节点，远端单元为叶节点； 2.本参数指示从扩展型主机单元某一板卡的某一端口或非板卡形态的主机单元的某一端口到扩展单元 EU.{i}的路由路径，并与每个扩展单元的唯一标识对应，通过本参数和 EU.{i}.RU.{i}可呈现整个组网拓扑结构及各单元所处位置； 3.RouteIndex 取值规则从左至右根据主机单元，当某一板卡的某一端口(板卡与端口间以“.”分割。非板卡结构 MU直接使用端口号)到扩展单元 EU.{i}的路由使用的各级设备端口号逐级取值，每级之间以下划线“_”分割，直至到达本节点 EU.{i}。例如：“EU.{i}.RouteIndex = 3.2_1_5_4”代表该路由起始于主机单元（第零级）占用第3槽位的板卡的端口 2，经过第一级扩展单元南向级联端口1，第二级扩展单元南向级联端口5，第三级扩展单元南向级联端口4路由到本扩展单元 EU.{i}；非板卡类型主机单元，路由表示为 2_1_5_4，2表示该路由起始于主机单元（第零级）的端口2； 4.通过 RouteIndex取值中数值个数还能体现本扩展单元EU.{i}所处级数，例如“EU.{i}.RouteIndex = 3.2_1_5_4”说明该扩展单元EU.{i}位于第四级（主机单元为第零级）。 | I43: MU、EU和RU的端口从1开始
B44: Device.DeviceInfo.MU.{i}.Slot.{i}.EU.{i}.ManufacturerOUI | C44: ManufacturerOUI | D44: 制造商OUI | E44: M | F44: R | G44: string(6) | H44: /
...

Sheet SB
A1: 归类 | B1: 参数路径 | C1: 英文名称 | D1: 中文名称 | E1: 限定 | F1: 网管读写权限 | G1: 类型 | H1: 描述 | I1: 备注
A2: 设备信息参数管理 | B2: Device.DeviceInfo.ManufacturerOUI | C2: ManufacturerOUI | D2: 制造商OUI | E2: M | F2: R | G2: string(6) | H2: /
B3: Device.DeviceInfo.Manufacturer | C3: Manufacturer | D3: 制造商 | E3: M | F3: R | G3: string(64) | H3: /
B4: Device.DeviceInfo.ModelName | C4: ModelName | D4: 设备型号 | E4: M | F4: R | G4: string(64) | H4: /
B5: Device.DeviceInfo.SerialNumber | C5: SerialNumber | D5: 序列号 | E5: M | F5: R | G5: string(64) | H5: /
B6: Device.DeviceInfo.HardwareVersion | C6: HardwareVersion | D6: 硬件版本 | E6: M | F6: R | G6: string(64) | H6: /
B7: Device.DeviceInfo.SoftwareVersion | C7: SoftwareVersion | D7: 软件版本 | E7: M | F7: R | G7: string(64) | H7: /
B8: Device.DeviceInfo.HardwarePlatform | C8: HardwarePlatform | D8: 硬件平台 | E8: M | F8: R | G8: string(64) | H8: /
B9: Device.DeviceInfo.AdditionalHardwareVersion | C9: AdditionalHardwareVersion | D9: 附加硬件版本 | E9: M | F9: R | G9: string(64)
B10: Device.DeviceInfo.AdditionalSoftwareVersion | C10: AdditionalSoftwareVersion | D10: 附加软件版本 | E10: M | F10: R | G10: string(64)
B11: Device.DeviceInfo.DataModelSpecVersion | C11: DataModelSpecVersion | D11: 数据模型版本 | E11: M | F11: R | G11: string
B12: Device.DeviceInfo.ProvisioningCode | C12: ProvisioningCode | D12: 供应商代号 | E12: M | F12: R | G12: string(64) | H12: /
B13: Device.DeviceInfo.ProductClass | C13: ProductClass | D13: 产品分类 | E13: M | F13: R | G13: string(64) | H13: /
B14: Device.DeviceInfo.UpTime | C14: UpTime | D14: 运行时间 | E14: M | F14: R | G14: unsignedInt | H14: / | I14: 0-‭4294967295‬
B15: Device.DeviceInfo.3GPPSpecVersion | C15: 3GPPSpecVersion | D15: 3GPP协议版本 | E15: M | F15: R | G15: string | H15: /
B16: Device.DeviceInfo.FirstUseDate | C16: FirstUseDate | D16: 首次使用日期 | E16: M | F16: R | G16: dateTime | H16: UTC时间格式，YYYY-MM-DDTHH:MM:SSZ，例如2012-12-11T09:15:00Z
B17: Device.DeviceInfo.Reboot | C17: Reboot | D17: 重启开关 | E17: M | F17: RW | G17: boolean | H17: 0:不重启 1:重启
B18: Device.DeviceInfo.Status | C18: Status | D18: 硬件状态 | E18: M | F18: R | G18: unsignedInt[1:3] | H18: 1:正常 3:告警
B19: Device.DeviceInfo.SwUpgrade.Stage | C19: Stage | D19: 升级阶段 | E19: M | F19: R | G19: unsignedInt[1:5] | H19: 1:初始化 2:下载 3:安装 4:等待激活 5.激活
B20: Device.DeviceInfo.SwUpgrade.Status | C20: Status | D20: 状态 | E20: M | F20: R | G20: unsignedInt[1:3] | H20: 1:成功 2:进行中 3:失败
B21: Device.DeviceInfo.SwUpgrade.FailureCause | C21: FailureCause | D21: 升级失败原因 | E21: M | F21: R | G21: string | H21: 升级失败原因描述

Sheet SC
A1: 归类 | B1: 参数路径 | C1: 英文名称 | D1: 中文名称 | E1: 限定 | F1: 网管读写权限 | G1: 类型 | H1: 描述 | I1: 备注
A2: 版本参数管理 | B2: Device.SoftwareCtrl.AutoActivateEnable | C2: AutoActivateEnable | D2: 立即激活目标升级版本使能开关 | E2: M | F2: RW | G2: boolean | H2: (0=false,1=true)，立即激活目标升级版本使能开关，当为true时，设备下载成功目标升级版本后立即激活版本，当为flase时，需要和ActivateTime这两个参数一起使用。
B3: Device.SoftwareCtrl.ActivateTime | C3: ActivateTime | D3: 软件激活时间 | E3: M | F3: RW | G3: dateTime | H3: UTC时间格式，YYYY-MM-DDTHH:MM:SSZ，例如2012-12-11T09:15:00Z，下发命令后设备只要在大于等于激活时间里开启，就会激活系统备份版本。
B4: Device.SoftwareCtrl.ActivateEnable | C4: ActivateEnable | D4: 激活备份版本使能开关 | E4: O | F4: RW | G4: boolean | H4: (0=false,1=true)激活备份版本使能开关，当为true时立即激活备份版本。
B5: Device.SoftwareCtrl.SystemCurrentVersion | C5: SystemCurrentVersion | D5: 系统当前版本 | E5: M | F5: R | G5: string(64) | H5: 系统正在使用的版本。表示gNB整体版本。
B6: Device.SoftwareCtrl.SystemBackupVersion | C6: SystemBackupVersion | D6: 系统备份版本 | E6: O | F6: R | G6: string(64) | H6: 系统备份版本，新下载的或以前使用的版本。

Sheet SD
A1: 归类 | B1: 参数路径 | C1: 英文名称 | D1: 中文名称 | E1: 限定 | F1: 网管读写权限 | G1: 类型 | H1: 描述 | I1: 备注
A2: 网管参数管理 | B2: Device.ManagementServer.URL | C2: URL | D2: 网管服务器URL | E2: M | F2: RW | G2: string(256) | H2: ACS使用CWMP连接ACS的URL。格式必须为合法的HTTP/HTTPS的形式。
B3: Device.ManagementServer.Username | C3: Username | D3: 连接用户名 | E3: M | F3: RW | G3: string(256) | H3: ACS使用CWMP连接基站时使用的认证用户名。仅用于基站的基于HTTP的认证。
B4: Device.ManagementServer.Password | C4: Password | D4: 连接密码 | E4: M | F4: RW | G4: string(256) | H4: 基站使用CWMP连接ACS时使用的认证密码。仅用于基站的基于HTTP的认证。读取时返回一个空字符串.
B5: Device.ManagementServer.PeriodicInformEnable | C5: PeriodicInformEnable | D5: 连接使能开关 | E5: M | F5: RW | G5: boolean | H5: 基站是否必须利用Inform方法调用定时向服务器端发送基站信息。当PeriodicInformEnable=true时，PeriodicInformInterval才起作用
B6: Device.ManagementServer.PeriodicInformTime | C6: PeriodicInformTime | D6: 上报周期 | E6: M | F6: RW | G6: dateTime | H6: UTC时间格式，YYYY-MM-DDTHH:MM:SSZ，例如2012-12-11T09:15:00Z
B7: Device.ManagementServer.PeriodicInformInterval | C7: PeriodicInformInterval | D7: 周期上报时间间隔 | E7: M | F7: RW | G7: unsignedInt[1:] | H7: 在PeriodicInformEnable为真时，基站必须尝试连接ACS并调用Inform方法的时间间隔。当PeriodicInformEnable=true才生效
B8: Device.ManagementServer.ParameterKey | C8: ParameterKey | D8: 键值 | E8: M | F8: R | G8: string(32) | H8: 来自于服务器的最新的 SetParameterValues，AddObject 或 DeleteObject 方法调用的 ParameterKey 自变量数值。如果没有此类调用，此数值为空。
B9: Device.ManagementServer.ConnectionRequestURL | C9: ConnectionRequestURL | D9: 连接请求URL | E9: M | F9: R | G9: string(256) | H9: ACS向基站发起连接请求通知时所使用的HTTPURL。其形式如下：http://host:port/SOAP/HNBServlet?a=1的"主机"部分可以是基站管理接口的IP地址，用以替代域名。
B10: Device.ManagementServer.ConnectionRequestUsername | C10: ConnectionRequestUsername | D10: 连接请求用户名 | E10: M | F10: RW | G10: string(256) | H10: ACS向基站发起连接请求时，鉴权过程使用的用户名。
B11: Device.ManagementServer.ConnectionRequestPassword | C11: ConnectionRequestPassword | D11: 连接请求密码 | E11: M | F11: RW | G11: string(256) | H11: ACS向基站发起连接请求时，鉴权过程使用的密码。在被读取时，该参数会忽略实际值而返回一个空字符串。
B12: Device.ManagementServer.UDPConnectionRequestAddress | C12: UDPConnectionRequestAddress | D12: UDP连接请求地址 | E12: O | F12: RW | G12: string(256) | H12: /
B13: Device.ManagementServer.STUNEnable | C13: STUNEnable | D13: STUN使能开关 | E13: O | F13: RW | G13: boolean | H13: (0=false,1=true)
B14: Device.ManagementServer.STUNServerAddress | C14: STUNServerAddress | D14: STUN服务器地址 | E14: O | F14: RW | G14: string(256) | H14: /
... B20: Device.ManagementServer.NATDetected | C20: NATDetected | D20: NAT转换地址 | E20: O | F20: R | G20: boolean | H20: (0=false,1=true)

Sheet SE
A1: 归类 | B1: 参数路径 | C1: 英文名称 | D1: 中文名称 | E1: 限定 | F1: 网管读写权限 | G1: 类型 | H1: 描述 | I1: 备注
A2: 告警管理 | B2: Device.FaultMgmt.SupportedAlarmNumberOfEntries | C2: SupportedAlarmNumberOfEntries | D2: 最大告警实例数量 | E2: M | F2: R | G2: unsignedInt | H2: /
B3: Device.FaultMgmt.MaxCurrentAlarmEntries | C3: MaxCurrentAlarmEntries | D3: 最大当前告警实例数量 | E3: M | F3: R | G3: unsignedInt | H3: /
B4: Device.FaultMgmt.CurrentAlarmNumberOfEntries | C4: CurrentAlarmNumberOfEntries | D4: 当前告警实例数量 | E4: M | F4: R | G4: unsignedInt | H4: /
B5: Device.FaultMgmt.HistoryEventNumberOfEntries | C5: HistoryEventNumberOfEntries | D5: 历史事件实例数量 | E5: M | F5: R | G5: unsignedInt | H5: /
B6: Device.FaultMgmt.ExpeditedEventNumberOfEntries | C6: ExpeditedEventNumberOfEntries | D6: 紧急事件实例数量 | E6: M | F6: R | G6: unsignedInt | H6: /
B7: Device.FaultMgmt.QueuedEventNumberOfEntries | C7: QueuedEventNumberOfEntries | D7: 队列事件实例数量 | E7: M | F7: R | G7: unsignedInt | H7: /
B8: Device.FaultMgmt.SupportedAlarm.{i}.EventType | C8: EventType | D8: 告警类型 | E8: M | F8: R | G8: string(64) | H8: 设备上报告警消息中的告警类型，包括通讯告警、环境告警、设备告警、处理错误告警、服务质量告警等
B9: Device.FaultMgmt.SupportedAlarm.{i}.ProbableCause | C9: ProbableCause | D9: 告警原因 | E9: M | F9: R | G9: string(64) | H9: /
B10: Device.FaultMgmt.SupportedAlarm.{i}.SpecificProblem | C10: SpecificProblem | D10: 告警描述 | E10: M | F10: R | G10: string(128) | H10: /
B11: Device.FaultMgmt.SupportedAlarm.{i}.PerceivedSeverity | C11: PerceivedSeverity | D11: 支持告警级别 | E11: M | F11: R | G11: string | H11: 设备上报告警消息中的告警级别：Critical,严重；Major,重要；Minor,次要；Warning,警告；
B12: Device.FaultMgmt.SupportedAlarm.{i}.ReportingMechanism | C12: ReportingMechanism | D12: 告警上报机制 | E12: M | F12: RW | G12: string | H12: / | I12: 修改网管读写权限
B13: Device.FaultMgmt.CurrentAlarm.{i}.AlarmIdentifier | C13: AlarmIdentifier | D13: 该告警的唯一序列号 | E13: M | F13: R | G13: string(64) | H13: /
B14: Device.FaultMgmt.CurrentAlarm.{i}.SerialNumber | C14: SerialNumber | D14: 设备序列号 | E14: M | F14: R | G14: string(64) | H14: /
B15: Device.FaultMgmt.CurrentAlarm.{i}.OUI | C15: OUI | D15: 设备OUI | E15: M | F15: R | G15: string(64) | H15: /
B16: Device.FaultMgmt.CurrentAlarm.{i}.AlarmRaisedTime | C16: AlarmRaisedTime | D16: 告警发生时间 | E16: M | F16: R | G16: dateTime | H16: UTC时间格式，YYYY-MM-DDTHH:MM:SSZ，例如2012-12-11T09:15:00Z
B17: Device.FaultMgmt.CurrentAlarm.{i}.AlarmChangedTime | C17: AlarmChangedTime | D17: 告警改变时间 | E17: M | F17: R | G17: dateTime | H17: UTC时间格式，YYYY-MM-DDTHH:MM:SSZ，例如2012-12-11T09:15:00Z
B18: Device.FaultMgmt.CurrentAlarm.{i}.ManagedObjectInstance | C18: ManagedObjectInstance | D18: 管理对象实例 | E18: M | F18: R | G18: string(512) | H18: 定义了承载该对象实例DN时发生的基站告警的信息对象等级的实例
B19: Device.FaultMgmt.CurrentAlarm.{i}.EventType | C19: EventType | D19: 告警类型 | E19: M | F19: R | G19: string(64) | H19: 设备上报告警消息中的告警类型，包括通讯告警、环境告警、设备告警、处理错误告警、服务质量告警等
B20: Device.FaultMgmt.CurrentAlarm.{i}.ProbableCause | C20: ProbableCause | D20: 告警原因 | E20: M | F20: R | G20: string(64) | H20: /
B21: Device.FaultMgmt.CurrentAlarm.{i}.SpecificProblem | C21: SpecificProblem | D21: 告警描述 | E21: M | F21: R | G21: string(128) | H21: /
B22: Device.FaultMgmt.CurrentAlarm.{i}.PerceivedSeverity | C22: PerceivedSeverity | D22: 当前告警级别 | E22: M | F22: R | G22: string | H22: 设备上报告警消息中的告警级别：Critical,严重；Major,重要；Minor,次要；Warning,警告；
B23: Device.FaultMgmt.CurrentAlarm.{i}.AdditionalText | C23: AdditionalText | D23: 告警附加文本 | E23: M | F23: R | G23: string(256) | H23: 本规范规定内容为厂家告警编码
B24: Device.FaultMgmt.CurrentAlarm.{i}.AdditionalInformation | C24: AdditionalInformation | D24: 告警附加信息 | E24: M | F24: R | G24: string(256) | H24: （格式：英文）统一采用此参数作为告警附加信息，映射到北向的AlarmText字段
... B60: Device.FaultMgmt.QueuedEvent.{i}.AdditionalInformation | C60: AdditionalInformation | D60: 告警附加信息 | E60: M | F60: R | G60: string(256) | H60: 格式：英文。统一采用此参数作为告警附加信息，映射到北向的AlarmText字段

Sheet SF
A1: 归类 | B1: 参数路径 | C1: 英文名称 | D1: 中文名称 | E1: 限定 | F1: 网管读写权限 | G1: 类型 | H1: 描述 | I1: 备注
A2: 日志参数管理 | B2: Device.LogMgmt.PeriodicUploadEnable | C2: PeriodicUploadEnable | D2: 日志周期上传使能开关 | E2: M | F2: RW | G2: boolean | H2: (0=false,1=true),禁止或启用将设备日志周期性地发送到指定的文件服务器。在使能开关开启的情况下，如果还未达到上报周期，设备日志文件已达到存储容量上限，则应立即将该时段的增量日志上报到网管，并开启一个新的上报周期的要求。
B3: Device.LogMgmt.URL | C3: URL | D3: 日志上传URL | E3: M | F3: RW | G3: string(256) | H3: 指定了目的日志的位置，没有以任何方式指明需要上传的本地文件的名字和位置
B4: Device.LogMgmt.Username | C4: Username | D4: 日志管理用户名 | E4: M | F4: RW | G4: string(256) | H4: 用户名用于设备到日志服务器的鉴权，如果不需要鉴权，此字符串为空，当PeriodicUploadEnable=true时，才生效。
B5: Device.LogMgmt.Password | C5: Password | D5: 日志管理密码 | E5: M | F5: RW | G5: string(256) | H5: 密码用于设备到日志服务器的鉴权，如果不需要鉴权，此字符串为空 当为读时，该参数返回一个空字符串，而不是一个实际的值，当PeriodicUploadEnable=true时，才生效。
B6: Device.LogMgmt.PeriodicUploadInterval | C6: PeriodicUploadInterval | D6: 日志周期上传时间间隔 | E6: M | F6: RW | G6: unsignedInt[1:65535] | H6: 单位：秒，取值包括（300,600,900,1800,3600）
B7: Device.LogMgmt.LogLevel | C7: LogLevel | D7: 日志重要等级 | E7: O | F7: RW | G7: string(64) | H7: 日志重要等级： Enumerate{ERROR;WARN;INFO;DEBUG}

Sheet SG
A1: 归类 | B1: 参数路径 | C1: 英文名称 | D1: 中文名称 | E1: 限定 | F1: 网管读写权限 | G1: 类型 | H1: 描述 | I1: 备注
A2: AMF配置 | B2: Device.Services.FAPService.{i}.FAPControl.NR.AMFPoolConfigParam.{i}.LocalPort | C2: LocalPort | D2: 本地端口 | E2: M | F2: RW | G2: unsignedInt[1000:65535]
B3: Device.Services.FAPService.{i}.FAPControl.NR.AMFPoolConfigParam.{i}.AmfPort | C3: AmfPort | D3: 对端端口 | E3: M | F3: RW | G3: unsignedInt[1000:65535] | H3: 默认38412
B4: Device.Services.FAPService.{i}.FAPControl.NR.AMFPoolConfigParam.{i}.PLMNID | C4: PLMN ID | D4: 主PLMN | E4: M | F4: RW | G4: string(6) | H4: 每个AMF需要指定一个primary plmn id
B5: Device.Services.FAPService.{i}.FAPControl.NR.AMFPoolConfigParam.{i}.AmfName | C5: AmfName | D5: AMF名称 | E5: M | F5: R | G5: string[1:150] | H5: /
B6: Device.Services.FAPService.{i}.FAPControl.NR.AMFPoolConfigParam.{i}.GnbId | C6: GnbId | D6: 基站Id | E6: O | F6: R | G6: unsignedInt[0:4294967295]
B7: Device.Services.FAPService.{i}.FAPControl.NR.AMFPoolConfigParam.{i}.GnbIdLength | C7: GnbIdLength | D7: 基站Id长度 | E7: O | F7: R | G7: unsignedShort[22:32]
B8: Device.Services.FAPService.{i}.FAPControl.NR.AMFPoolConfigParam.{i}.AdminState | C8: AdminState | D8: AMF管理状态（开关SCTP链路） | E8: M | F8: RW | G8: boolean | H8: 0：关闭 1：开启
B9: Device.Services.FAPService.{i}.FAPControl.NR.AMFPoolConfigParam.{i}.State | C9: State | D9: AMF运行状态 | E9: M | F9: R | G9: boolean
B10: Device.Services.FAPService.{i}.FAPControl.NR.AMFPoolConfigParam.{i}.AmfIP1 | C10: AmfIP1 | D10: AmfIP1 | E10: M | F10: RW | G10: string(64) | H10: /
B11: Device.Services.FAPService.{i}.FAPControl.NR.AMFPoolConfigParam.{i}.AmfIP2 | C11: AmfIP2 | D11: AmfIP2 | E11: M | F11: RW | G11: string(64) | H11: /
B12: Device.Services.FAPService.{i}.FAPControl.NR.AMFPoolConfigParam.{i}.GUAMI.{i}.PLMNID | C12: PLMNID | D12: PLMNID | E12: M | F12: R | G12: string(6) | H12: /
B13: Device.Services.FAPService.{i}.FAPControl.NR.AMFPoolConfigParam.{i}.GUAMI.{i}.AmfRegionID | C13: AmfRegionID | D13: AmfGroup标识 | E13: M | F13: R | G13: string: [0:255] | H13: /
B14: Device.Services.FAPService.{i}.FAPControl.NR.AMFPoolConfigParam.{i}.GUAMI.{i}.AmfSetID | C14: AmfSetID | D14: Amf代码 | E14: M | F14: R | G14: string: [0:1023] | H14: /
B15: Device.Services.FAPService.{i}.FAPControl.NR.AMFPoolConfigParam.{i}.GUAMI.{i}.AmfPointer | C15: AmfPointer | D15: AmfPointer | E15: M | F15: R | G15: string: [0:63] | H15: /
B16: Device.Services.FAPService.{i}.FAPControl.NR.AMFPoolConfigParam.{i}.RelativeAmfCapacity | C16: RelativeAMFCapacity | D16: RelativeAmfCapacity | E16: M | F16: R | G16: unsignedInt[0:255] | H16: /
B17: Device.Services.FAPService.{i}.FAPControl.NR.AMFPoolConfigParam.{i}.SupportPLMNList.{i}.PLMNID | C17: PLMNID | D17: 小区PLMNID | E17: O | F17: RW | G17: string(6) | H17: PLMN信息
B18: Device.Services.FAPService.{i}.FAPControl.NR.AMFPoolConfigParam.{i}.SupportPLMNList.{i}.SliceList.{i}.SNSSAI | C18: SNSSAI | D18: SNSSAI | E18: O | F18: R | G18: string(8) | H18: SNSSAI信息
A19: 邻站管理 | B19: Device.Services.FAPService.{i}.FAPControl.NR.XnIpAddrMapInfo.{i}.RemoteAddress | C19: RemoteAddress | D19: IP地址 | E19: M | F19: RW | G19: string(0...64)
B20: Device.Services.FAPService.{i}.FAPControl.NR.XnIpAddrMapInfo.{i}.RemotePort | C20: RemotePort | D20: 对端端口 | E20: M | F20: RW | G20: unsignedInt[1000:65535]
B21: Device.Services.FAPService.{i}.FAPControl.NR.XnIpAddrMapInfo.{i}.GnbId | C21: GnbId | D21: 基站ID | E21: M | F21: R | G21: unsignedInt[0:4294967295]
B22: Device.Services.FAPService.{i}.FAPControl.NR.XnIpAddrMapInfo.{i}.AdminState | C22: AdminState | D22: 邻站管理状态 | E22: M | F22: RW | G22: boolean | H22: 0:关闭 1:开启
B23: Device.Services.FAPService.{i}.FAPControl.NR.XnIpAddrMapInfo.{i}.State | C23: State | D23: 邻站运行状态 | E23: M | F23: R | G23: boolean | H23: 0:关闭 1:开启
B24: Device.Services.FAPService.{i}.FAPControl.NR.XnIpAddrMapInfo.{i}.TAISupportList.{i}.TAC | C24: TAC | D24: 跟踪区代码 | E24: M | F24: R | G24: unsignedInt[0:16777215]
B25: Device.Services.FAPService.{i}.FAPControl.NR.XnIpAddrMapInfo.{i}.TAISupportList.{i}.BroadcastPLMNs.{i}.PLMNID | C25: PLMNID | D25: PLMN | E25: M | F25: R | G25: string(6)
B26: Device.Services.FAPService.{i}.FAPControl.NR.XnIpAddrMapInfo.{i}.LocGnbIdLength | C26: LocGnbIdLength | D26: 本端GnbIdlength | E26: O | F26: RW | G26: unsignedInt[22,32]
B27: Device.Services.FAPService.{i}.FAPControl.NR.XnIpAddrMapInfo.{i}.LocGnbId | C27: LocGnbId | D27: 本地GnbId | E27: O | F27: RW | G27: unsignedInt[0:4294967295]
B28: Device.Services.FAPService.{i}.FAPControl.NR.XnIpAddrMapInfo.{i}.SubnetMask | C28: SubnetMask | D28: 子网掩码 | E28: M | F28: R | G28: string(0...64)
B29: Device.Services.FAPService.{i}.FAPControl.NR.XnIpAddrMapInfo.{i}.LocalAddress | C29: LocalAddress | D29: 本地Ip | E29: M | F29: R | G29: string(0...64)
B30: Device.Services.FAPService.{i}.FAPControl.NR.XnIpAddrMapInfo.{i}.GnbIdLength | C30: GnbIdLength | D30: 对端基站ID长度 | E30: M | F30: RW | G30: unsignedInt[22:32]
B31: Device.Services.FAPService.{i}.FAPControl.NR.Xn.LocalServerIp | C31: LocalServerIp | D31: Xn 服务端本地IP | E31: M | F31: RW | G31: string(0...64)
B32: Device.Services.FAPService.{i}.FAPControl.NR.Xn.LocalPort | C32: LocalPort | D32: 本地端口 | E32: M | F32: RW | G32: unsignedInt[1000:65535]
B33: Device.Services.FAPService.{i}.FAPControl.NR.X2IpAddrMapInfo.{i}.IPV4Address | C33: IPV4Address | D33: IP地址 | E33: O | F33: RW | G33: string(0...64)
B34: Device.Services.FAPService.{i}.FAPControl.NR.X2IpAddrMapInfo.{i}.RemotePort | C34: RemotePort | D34: 对端端口 | E34: O | F34: RW | G34: unsignedInt[1000:65535]
B35: Device.Services.FAPService.{i}.FAPControl.NR.X2IpAddrMapInfo.{i}.EnbId | C35: EnbId | D35: 基站ID | E35: O | F35: RW | G35: unsignedInt[0:4294967295]
B36: Device.Services.FAPService.{i}.FAPControl.NR.X2IpAddrMapInfo.{i}.EnbType | C36: EnbType | D36: Enb站型 | E36: O | F36: RW | G36: enumeration | H36: {Macro,Home}
B37: Device.Services.FAPService.{i}.FAPControl.NR.X2IpAddrMapInfo.{i}.AdminState | C37: AdminState | D37: 邻站管理状态 | E37: O | F37: RW | G37: boolean | H37: 0:关闭 1:开启
B38: Device.Services.FAPService.{i}.FAPControl.NR.X2IpAddrMapInfo.{i}.State | C38: State | D38: 邻站运行状态 | E38: O | F38: R | G38: boolean | H38: 0:关闭 1:开启
B39: Device.Services.FAPService.{i}.FAPControl.NR.X2IpAddrMapInfo.{i}.TAC | C39: TAC | D39: 跟踪区代码 | E39: O | F39: R | G39: unsignedInt[0:16777215]
B40: Device.Services.FAPService.{i}.FAPControl.NR.X2IpAddrMapInfo.{i}.PLMNID | C40: PLMNID | D40: PLMN | E40: O | F40: R | G40: string(6)
...

Sheet SH
A1: 归类 | B1: 参数路径 | C1: 英文名称 | D1: 中文名称 | E1: 限定 | F1: 网管读写权限 | G1: 类型 | H1: 描述 | I1: 备注
A2: NNSF参数管理 | B2: Device.Services.FAPService.{i}.Capabilities.NR.NNSFSupported | C2: NNSFSupported | D2: 负载均衡参数 | E2: M | F2: RW | G2: boolean | H2: (0=false,1=true)

Sheet SI
A1: 归类 | B1: 参数路径 | C1: 英文名称 | D1: 中文名称 | E1: 限定 | F1: 网管读写权限 | G1: 类型 | H1: 描述 | I1: 备注
A2: SON参数管理 | B2: Device.Services.FAPService.{i}.FAPControl.NR.SelfConfig.SONConfigParam.SONSysMode | C2: SONSysMode | D2: SON系统模式 | E2: O | F2: RW | G2: string | H2: SON系统模式（分布式，集中式）,{Distributed，Centralized}
B3: Device.Services.FAPService.{i}.FAPControl.NR.SelfConfig.SONConfigParam.SONWorkMode | C3: SONWorkMode | D3: SON模式设置 | E3: O | F3: RW | G3: string | H3: 自优化模式（自由模式，受控模式）,{Free，Control}，自由模式下系统给出的参数优化建议无需人工确认，可直接执行；受控模式下系统给出的参数优化建议需要人工确认同意才可执行，否则（不同意或超时）不执行优化，保持原参数配置不变。
B4: Device.Services.FAPService.{i}.FAPControl.NR.SelfConfig.SONConfigParam.PCI.Enable | C4: Enable | D4: PCI冲突和混淆检测功能开关 | E4: MC | F4: RW | G4: boolean | H4: PCI冲突和混淆检测功能开关,(0=false,1=true)
B5: Device.Services.FAPService.{i}.FAPControl.NR.SelfConfig.SONConfigParam.PCIOptEnable | C5: PCIOptEnable | D5: PCI自优化算法开关 | E5: MC | F5: RW | G5: boolean | H5: PCI自优化算法开关,(0=false,1=true)
B6: Device.Services.FAPService.{i}.FAPControl.NR.SelfConfig.SONConfigParam.PCIReconfigWaitTime | C6: PCIReconfigWaitTime | D6: PCI重配等待定时器 | E6: MC | F6: RW | G6: unsignedInt | H6: 表征PCI重配置等待时间，在PCI自优化阶段，该计时器超时后使用新的PCI
B7: Device.Services.FAPService.{i}.FAPControl.NR.SelfConfig.SONConfigParam.CandidateARFCNList | C7: CandidateARFCNList | D7: 候选频点列表 | E7: O | F7: RW | G7: string(64) | H7: 候选频点列表
B8: Device.Services.FAPService.{i}.FAPControl.NR.SelfConfig.SONConfigParam.CandidatePCIList | C8: CandidatePCIList | D8: 候选PCI列表 | E8: O | F8: RW | G8: string(64) | H8: 候选PCI列表
B9: Device.Services.FAPService.{i}.FAPControl.NR.SelfConfig.SONConfigParam.ANR.Enable | C9: Enable | D9: ANR算法总开关 | E9: O | F9: RW | G9: boolean | H9: (0=false,1=true)，ANR算法总开关
B10: Device.Services.FAPService.{i}.FAPControl.NR.SelfConfig.SONConfigParam.ANR.InterFeqEnable | C10: InterFeqEnable | D10: NR异频ANR算法开关 | E10: MC | F10: RW | G10: boolean | H10: (0=false,1=true)，NR异频ANR算法开关
B11: Device.Services.FAPService.{i}.FAPControl.NR.SelfConfig.SONConfigParam.ANR.InterFeqCandidateARFCNList | C11: InterFeqCandidateARFCNList | D11: SSB频点号 | E11: MC | F11: RW | G11: string(64) | H11: 小区载频的SSB ARFCN列表，ARFCN间以“,”分割
B12: Device.Services.FAPService.{i}.FAPControl.NR.SelfConfig.SONConfigParam.ANR.EUTRANEnable | C12: EUTRANEnable | D12: E-UTRAN异系统ANR算法开关 | E12: O | F12: RW | G12: boolean | H12: (0=false,1=true)，E-UTRAN异系统ANR算法开关
B13: Device.Services.FAPService.{i}.FAPControl.NR.SelfConfig.SONConfigParam.ANR.BiNRCellEnable | C13: BiNRCellEnable | D13: ANR双向邻区添加开关 | E13: MC | F13: RW | G13: boolean | H13: (0=false,2=true)，ANR双向邻区添加开关
B14: Device.Services.FAPService.{i}.FAPControl.NR.SelfConfig.SONConfigParam.ANR.RSRPReferenceEnable | C14: RSRPReferenceEnable | D14: 事件性MR添加邻区依照绝对电平开关 | E14: MC | F14: RW | G14: boolean | H14: (0=false,1=true)，该开关打开后，添加邻区需同时考虑绝对电平和相对电平
... B35: Device.Services.FAPService.{i}.FAPControl.NR.SelfConfig.SONConfigParam.SyncMode | C35: SyncMode | D35: 时钟同步模式 | E35: O | F35: R | G35: string(64) | H35: 时钟同步模式，取值范围： GNSS IEEE1588V2 Sniffer Freedom
A36: 自动开站阶段 | B36: Device.Services.FAPService.{i}.FAPControl.SelfConfig.Startup.Stage | C36: Stage | D36: 开站阶段 | E36: M | F36: R | G36: unsignedInt[1:3] | H36: 开站阶段取值如下： 1:参数校验 2:参数配置 3:小区激活
A37: 自动开站结果 | B37: Device.Services.FAPService.{i}.FAPControl.SelfConfig.Startup.Status | C37: Status | D37: 开站状态 | E37: M | F37: R | G37: unsignedInt[1:2] | H37: 1：开站成功（全部小区被激活，即标记为开站成功） 2：开站失败（存在一个小区未激活，即标记为开站失败）
B38: Device.Services.FAPService.{i}.FAPControl.SelfConfig.Startup.FailureCause | C38: FailureCause | D38: 开站失败原因 | E38: M | F38: R | G38: string(512) | H38: 开站失败原因描述

Sheet SJ
A1: 归类 | B1: 参数路径 | C1: 英文名称 | D1: 中文名称 | E1: 限定 | F1: 网管读写权限 | G1: 类型 | H1: 描述 | I1: 备注
A2: 接入UE数量管理 | B2: Device.Services.FAPService.{i}.CellConfig.{i}.NR.Capabilities.UeInactiveTimer | C2: UeInactiveTimer | D2: 连接态UE不活动定时器 | E2: M | F2: RW | G2: unsignedInt[0:65535] | H2: /
B3: Device.Services.FAPService.{i}.CellConfig.{i}.NR.Capabilities.InactiveSwitch | C3: InactiveSwitch | D3: ue非激活态开关 | E3: M | F3: RW | G3: boolean | H3: 0:非激活超时后进入空闲态 1:非激活超时后进入非激活态
B4: Device.Services.FAPService.{i}.CellConfig.{i}.NR.Capabilities.MaxUEsServed | C4: SupportRRCNumbers | D4: 同时支持RRC连接最大用户数 | E4: M | F4: RW | G4: int | H4: /
B5: Device.Services.FAPService.{i}.CellConfig.{i}.NR.Capabilities.UserNumberThreshold1 | C5: UserNumberThreshold1 | D5: CAC用户数门限1百分比 | E5: O | F5: RW | G5: unsignedInt[0:100]
B6: Device.Services.FAPService.{i}.CellConfig.{i}.NR.Capabilities.UserNumberThreshold2 | C6: UserNumberThreshold2 | D6: CAC用户数门限2百分比 | E6: O | F6: RW | G6: unsignedInt[0:100]
B7: Device.Services.FAPService.{i}.CellConfig.{i}.NR.Capabilities.UserNumberThreshold3 | C7: UserNumberThreshold3 | D7: CAC用户数门限3百分比 | E7: O | F7: RW | G7: unsignedInt[0:100]
B8: Device.Services.FAPService.{i}.CellConfig.{i}.NR.Capabilities.UserNumberReservedForHo | C8: UserNumberReservedForHo | D8: CAC切换预留用户数百分比 | E8: O | F8: RW | G8: unsignedInt[0:100]
B9: Device.Services.FAPService.{i}.CellConfig.{i}.NR.Capabilities.GbrThresholdSwitch | C9: GbrThresholdSwitch | D9: 基于Gbr门限接纳控制开关 | E9: O | F9: RW | G9: boolean | H9: 基于GBR门限接纳控制开关
B10: Device.Services.FAPService.{i}.CellConfig.{i}.NR.Capabilities.GbrUlThreshold | C10: GbrUlThreshold | D10: Gbr上行门限 | E10: O | F10: RW | G10: unsignedLong[0..4,000,000,000,000]
B11: Device.Services.FAPService.{i}.CellConfig.{i}.NR.Capabilities.GbrDlThreshold | C11: GbrDlThreshold | D11: Gbr下行门限 | E11: O | F11: RW | G11: unsignedLong[0..4,000,000,000,000]
B12: Device.Services.FAPService.{i}.CellConfig.{i}.NR.Capabilities.SupportActiveRRCNumbers | C12: SupportActiveRRCNumbers | D12: 同时支持RRC激活最大用户数 | E12: M | F12: RW | G12: unsignedInt[0:65535] | H12: /
A13: 小区参数管理 | B13: Device.Services.FAPService.{i}.CellConfig.{i}.NR.RAN.RF.NRARFCNDL | C13: NRARFCNDL | D13: 下行NRARFCN | E13: M | F13: RW | G13: unsignedInt[0:3279165] | H13: 下行EARFCN
B14: Device.Services.FAPService.{i}.CellConfig.{i}.NR.RAN.RF.PhyCellID | C14: PhyCellID | D14: PCI | E14: M | F14: RW | G14: unsignedInt[0:1007] | H14: PCI
B15: Device.Services.FAPService.{i}.CellConfig.{i}.NR.RAN.RF.DLBandwidth | C15: DLBandwidth | D15: 下行带宽 | E15: M | F15: RW | G15: unsignedInt | H15: 下行带宽,约束：{5，10，15，20，25，30，40，50，60，80，90，100，200，400}
B16: Device.Services.FAPService.{i}.CellConfig.{i}.NR.RAN.RF.ULBandwidth | C16: ULBandwidth | D16: 上行带宽 | E16: M | F16: RW | G16: unsignedInt | H16: 上行带宽，约束{5，10，15，20，25，30，40，50，60，80，90，100，200，400}
B17: Device.Services.FAPService.{i}.CellConfig.{i}.NR.RAN.RF.NRARFCNUL | C17: NRARFCNUL | D17: 上行NRARFCN | E17: M | F17: RW | G17: unsignedInt[0:3279165] | H17: 上行或双向E-UTRA载频
B18: Device.Services.FAPService.{i}.CellConfig.{i}.NR.RAN.RF.FreqBandIndicator | C18: FreqBandIndicator | D18: 频带指示 | E18: M | F18: RW | G18: unsignedInt[1:1024] | H18: 频带指示
B19: Device.Services.FAPService.{i}.CellConfig.{i}.NR.RAN.RF.SsbFrequency | C19: ssbFrequency | D19: SSB频点号 | E19: M | F19: RW | G19: unsignedInt[0:3279165] | H19: 小区载频的SSB ARFCN
B20: Device.Services.FAPService.{i}.CellConfig.{i}.NR.RAN.RF.SsPBCHBlockPower | C20: SsPBCHBlockPower | D20: SSB Block功率值 | E20: M | F20: RW | G20: int[-60:50] | H20: SSB Block功率值
B21: Device.Services.FAPService.{i}.CellConfig.{i}.NR.RAN.Common.CellType | C21: CellType | D21: 小区类型 | E21: M | F21: R | G21: string {SUB1G,SUB6G,ABOVE6G} | H21: 小区类型
B22: Device.Services.FAPService.{i}.CellConfig.{i}.NR.RAN.Common.CellIdWithinGnb | C22: CellIdWithinGnb | D22: 站内小区Id | E22: M | F22: RW | G22: unsignedShort[0:16383] | H22: Gnb内唯一标识
B23: Device.Services.FAPService.{i}.CellConfig.{i}.NR.CN.EnableSliceAccessControl | C23: EnableSliceAccessControl | D23: 基于切片接纳控制开关 | E23: O | F23: RW | G23: boolean | H23: 基于切片接纳控制开关
A24: 小区闭塞 | B24: Device.Services.FAPService.{i}.CellConfig.{i}.NR.RAN.CellRestriction.CellBarred | C24: CellBarred | D24: 小区闭塞 | E24: M | F24: RW | G24: boolean | H24: {barred, notBarred}
A25: 小区激活/去激活 | B25: Device.Services.FAPService.{i}.CellConfig.{i}.NR.RAN.CellEnable.AdminState | C25: AdminState | D25: 小区管理状态 | E25: M | F25: RW | G25: boolean | H25: 0:关闭 1:开启
A26: 小区状态参数 | B26: Device.Services.FAPService.{i}.CellConfig.{i}.NR.RAN.OpState | C26: OpState | D26: 小区运行状态 | E26: M | F26: R | G26: boolean | H26: 0:禁止 1:启动
A27: 广播参数管理 | B27: Device.Services.FAPService.{i}.CellConfig.{i}.NR.RAN.SysInfoCtrlParam.MultiBandInfoListSIB1 | C27: MultiBandInfoListSIB1 | D27: SIB1中多频段指示参数 | E27: O | F27: RW | G27: unsignedInt[1:1024] | H27: /
B28: Device.Services.FAPService.{i}.CellConfig.{i}.NR.RAN.SysInfoCtrlParam.IdleModeRATMobile.{i}.MultiBandInfoListSIB5 | C28: MultiBandInfoListSIB5 | D28: SIB5中多频段指示参数 | E28: O | F28: RW | G28: unsignedInt[1:64]
A29: 安全算法 | B29: Device.Services.FAPService.{i}.CellConfig.{i}.NR.RAN.Common.Security.Integrity.{i}.Priority | C29: IntPrority | D29: 完保算法优先级 | E29: M | F29: RW | G29: unsignedInt[0:3]
B30: Device.Services.FAPService.{i}.CellConfig.{i}.NR.RAN.Common.Security.Integrity.{i}.Algorithm | C30: IntAlgorithm | D30: 完保算法 | E30: M | F30: RW | G30: string(64) | H30: {NIA0;128-NIA1;128-NIA2;128-NIA3}
B31: Device.Services.FAPService.{i}.CellConfig.{i}.NR.RAN.Common.Security.Cipher.{i}.Priority | C31: CipherPrority | D31: 加密算法优先级 | E31: M | F31: RW | G31: unsignedInt[0:3]
B32: Device.Services.FAPService.{i}.CellConfig.{i}.NR.RAN.Common.Security.Cipher.{i}.Algorithm | C32: CipherAlgorithm | D32: 加密算法 | E32: M | F32: RW | G32: string(64) | H32: {NEA0;128-NEA1;128-NEA2;128-NEA3}
A33: VoNR参数 | B33: Device.Services.FAPService.{i}.CellConfig.{i}.NR.VoNR.VoNRList.{i}.PLMNID | C33: PLMNID | D33: PLMN | E33: M | F33: RW | G33: string(6) | H33: PLMNID
B34: Device.Services.FAPService.{i}.CellConfig.{i}.NR.VoNR.VoNRList.{i}.VoSupport | C34: VoSupport | D34: 支持vonr方式 | E34: M | F34: RW | G34: string {vonr; fallback; auto} | H34: {vonr; fallback; auto}
B35: Device.Services.FAPService.{i}.CellConfig.{i}.NR.VoNR.VoNRList.{i}.Vo5qi | C35: Vo5qi | D35: vonr的专用承载 | E35: M | F35: RW | G35: unsignedInt[1…63] | H35: [1:63]
B36: Device.Services.FAPService.{i}.CellConfig.{i}.NR.VoNR.PdcpInitParam.{i}.RohcEn | C36: RohcEn | D36: 分QCI头压缩功能开关 | E36: M | F36: RW | G36: string(64) | H36: （ON，OFF, NA）,{i}取值范围[1,…,9]
B37: Device.Services.FAPService.{i}.CellConfig.{i}.NR.VoNR.VoNRSwitch | C37: VoNRSwitch | D37: VoNR开关 | E37: M | F37: RW | G37: boolean | H37: VoNR开关，0：不开启，1：开启
B38: Device.Services.FAPService.{i}.CellConfig.{i}.NR.VoNR.SPSSwitchQCI1Ul | C38: SPSSwitchQCI1Ul | D38: QCI1上行SPS功能开关 | E38: O | F38: RW | G38: string(64) | H38: （ON，OFF, NA）
A39: 负载均衡参数 | B39: Device.Services.FAPService.{i}.CellConfig.{i}.NR.Capabilities.LoadBalanceConfig.LoadBalanceSwitch | C39: LoadBalanceSwitch | D39: 负载均衡开关 | E39: O | F39: RW | G39: boolean | H39: 负载均衡开关
B40: Device.Services.FAPService.{i}.CellConfig.{i}.NR.Capabilities.LoadBalanceConfig.TimeToTrigger | C40: TimeToTrigger | D40: 触发时间 | E40: O | F40: RW | G40: unsignedInt[1:60] | H40: 触发负载均衡的时间
...

Sheet SK
A1: 归类 | B1: 参数路径 | C1: 英文名称 | D1: 中文名称 | E1: 限定 | F1: 网管读写权限 | G1: 类型 | H1: 描述 | I1: 备注
A2: 物理层参数管理 | B2: Device.Services.FAPService.{i}.CellConfig.{i}.NR.RAN.PHY.FrequencyInfoDLSIB.OffsetToPointA | C2: OffsetToPointA | D2: SSB的PRB0中子载波0位置与PointA之间偏移值 | E2: M | F2: R | G2: unsignedInt[0:2199] | H2: 取值范围：0~2199 默认值为0
B3: Device.Services.FAPService.{i}.CellConfig.{i}.NR.RAN.PHY.FrequencyInfoDLSIB.MultiFrequencyBandListNRSIB.{i}.FreqBandIndicatorNR | C3: FreqBandIndicatorNR | D3: NR频段指示 | E3: M | F3: RW | G3: unsignedInt[1:1024] | H3: FreqBandIndList实际值 总个数最大为8，即i最大取8
B4: Device.Services.FAPService.{i}.CellConfig.{i}.NR.RAN.PHY.FrequencyInfoDLSIB.ScsSpecificCarrierList.{i}.SCSSpecificCarrier.OffsetToCarrier | C4: OffsetToCarrier | D4: 载波偏置(下行) | E4: M | F4: RW | G4: unsignedInt[0:2199] | H4: INTEGER (0..2199),i最大值取5
B5: Device.Services.FAPService.{i}.CellConfig.{i}.NR.RAN.PHY.FrequencyInfoDLSIB.ScsSpecificCarrierList.{i}.SCSSpecificCarrier.subcarrierSpacing | C5: SubcarrierSpacing | D5: 子载波间隔(下行) | E5: M | F5: RW | G5: unsignedInt[0:4] | H5: 子载波间隔 取值范围：{0, 1, 2, 3, 4} 0代表kHz15，1代表kHz30，2代表kHz60，3代表kHz120，4代表kHz240.,i最大值取5
B6: Device.Services.FAPService.{i}.CellConfig.{i}.NR.RAN.PHY.FrequencyInfoDLSIB.ScsSpecificCarrierList.{i}.SCSSpecificCarrier.CarrierBandwidth | C6: CarrierBandwidth | D6: 带宽值(下行) | E6: M | F6: RW | G6: unsignedInt[1:275] | H6: 取值范围：[1~275],i最大值取5
B7: Device.Services.FAPService.{i}.CellConfig.{i}.NR.RAN.PHY.FrequencyInfoULSIB.AbsoluteFrequencyPointA | C7: AbsoluteFrequencyPointA | D7: PointA绝对频点号 | E7: O | F7: R | G7: unsignedInt[0:3279165] | H7: PointA绝对频点号
B8: Device.Services.FAPService.{i}.CellConfig.{i}.NR.RAN.PHY.FrequencyInfoULSIB.ScsSpecificCarrierList.{i}.SCSSpecificCarrier.OffsetToCarrier | C8: OffsetToCarrier | D8: 载波偏置(上行) | E8: M | F8: RW | G8: unsignedInt[0:2199] | H8: 取值范围：[0~2199],i最大值取5
B9: Device.Services.FAPService.{i}.CellConfig.{i}.NR.RAN.PHY.FrequencyInfoULSIB.ScsSpecificCarrierList.{i}.SCSSpecificCarrier.SubcarrierSpacing | C9: SubcarrierSpacing | D9: 子载波间隔(上行) | E9: M | F9: RW | G9: unsignedInt[0:4] | H9: 子载波间隔 取值范围：{0, 1, 2, 3, 4} 0代表kHz15，1代表kHz30，2代表kHz60，3代表kHz120，4代表kHz240.,i最大值取5
B10: Device.Services.FAPService.{i}.CellConfig.{i}.NR.RAN.PHY.FrequencyInfoULSIB.ScsSpecificCarrierList.{i}.SCSSpecificCarrier.CarrierBandwidth | C10: CarrierBandwidth | D10: 带宽值(上行) | E10: M | F10: RW | G10: unsignedInt[1:275] | H10: 取值范围：[1~275],i最大值取5
B11: Device.Services.FAPService.{i}.CellConfig.{i}.NR.RAN.PHY.SSB.SsbPositionsInBurst.InOneGroup | C11: InOneGroup | D11: SSB索引bit位 | E11: M | F11: RW | G11: string(8) | H11: 指示SS-Burst-Set中的SSB的时域位置
B12: Device.Services.FAPService.{i}.CellConfig.{i}.NR.RAN.PHY.SSB.SsbPeriodicityServingCell | C12: SsbPeriodicityServingCell | D12: SSB周期 | E12: M | F12: RW | G12: unsignedInt[0:5] | H12: SS-Burst-Set的周期
B13: Device.Services.FAPService.{i}.CellConfig.{i}.NR.RAN.PHY.SSB.SsbSubcarrierOffset | C13: SsbSubcarrierOffset | D13: SSB子载波偏置 | E13: M | F13: R | G13: unsignedInt[0:15] | H13: kSSB的低4位，表示PointA相对于SSB子载波0的子载波偏移
B14: Device.Services.FAPService.{i}.CellConfig.{i}.NR.RAN.PHY.SubCarrierSpacingCommon | C14: SubCarrierSpacingCommon | D14: 公共子载波间隔 | E14: M | F14: RW | G14: string(64) | H14: 公共子载波间隔，SIB1、初始接入Msg.2/4、和SI-message使用的子载波间隔。 取值范围{scs15or60, scs30or120},
... B53: Device.Services.FAPService.{i}.CellConfig.{i}.NR.RAN.PHY.Antenna.NumOfRxAntenna | C53: NumOfRxAntenna | D53: 接收通道数 | E53: M | F53: RW | G53: unsignedInt[1:4] | H53: 小基站接收通道的数量
A54: MAC层参数管理 | B54: Device.Services.FAPService.{i}.CellConfig.{i}.NR.RAN.PHY.BWP.BWPUL.{i}.PUSCH.PuschTpcAccumulation | C54: PuschTpcAccumulation | D54: PUSCH累积式功控开关 | E54: MC | F54: RW | G54: boolean | H54: { 关闭:0, 打开:1 }
B55: Device.Services.FAPService.{i}.CellConfig.{i}.NR.RAN.PHY.BWP.BWPUL.{i}.PUCCHConfig.IntraSlotFrequencyHoppingPeriodEnable | C55: IntraSlotFrequencyHoppingPeriodEnable | D55: 时隙内跳频 | E55: MC | F55: RW | G55: boolean | H55: (0=false,1=true)
B56: Device.Services.FAPService.{i}.CellConfig.{i}.NR.RAN.PHY.BWP.BWPUL.{i}.PUCCHConfig.PucchTpcEnabled | C56: PucchTpcEnabled | D56: PucchTpc开启 | E56: M | F56: RW | G56: boolean | H56: 约束：(true, false)
B57: Device.Services.FAPService.{i}.CellConfig.{i}.NR.RAN.PHY.BWP.BWPUL.{i}.PUSCHConfig.TxConfig | C57: TxConfig | D57: Tx配置 | E57: MC | F57: RW | G57: string | H57: 约束：(codebook, noncodebook)
B58: Device.Services.FAPService.{i}.CellConfig.{i}.NR.RAN.PHY.BWP.BWPUL.{i}.PUSCHConfig.FrequencyHopping | C58: FrequencyHopping | D58: PUSCH跳频 | E58: O | F58: RW | G58: enumeration {freq-hopping-disable,intra-slot-freq-hopping,inter-slot-freq-hopping} | H58: PUSCH跳频使能
B59: Device.Services.FAPService.{i}.CellConfig.{i}.NR.RAN.PHY.BWP.BWPUL.{i}.PUSCHConfig.FrequencyHoppingOffsetLists.{i}.FrequencyHoppingOffset | C59: FrequencyHoppingOffsetLists | D59: PUSCH跳频偏移列表 | E59: O | F59: RW | G59: Int[0,274] | H59: PUSCH跳频偏移列表
B60: Device.Services.FAPService.{i}.CellConfig.{i}.NR.RAN.PHY.BWP.BWPUL.{i}.PUSCHConfig.DmrsUplinkForPUSCHMappingTypeA.DmrsType | C60: DmrsType | D60: PUSCH类型A的解调参考信号类型 | E60: MC | F60: RW | G60: enumeration {type1,type2} | H60: PUSCH类型A的解调参考信号类型
B61: Device.Services.FAPService.{i}.CellConfig.{i}.NR.RAN.PHY.BWP.BWPUL.{i}.PUSCHConfig.DmrsUplinkForPUSCHMappingTypeA.DmrsAdditionalPosition | C61: DmrsAdditionalPosition | D61: PUSCH类型A的解调参考信号额外位置 | E61: MC | F61: RW | G61: enumeration[pos0,pos1,pos2,pos3] | H61: PUSCH类型A的解调参考信号额外位置
B62: Device.Services.FAPService.{i}.CellConfig.{i}.NR.RAN.PHY.BWP.BWPUL.{i}.PUSCHConfig.DmrsUplinkForPUSCHMappingTypeB.DmrsType | C62: DmrsType | D62: PUSCH类型B的解调参考信号类型 | E62: MC | F62: RW | G62: enumeration {type1,type2} | H62: PUSCH类型B的解调参考信号类型
B63: Device.Services.FAPService.{i}.CellConfig.{i}.NR.RAN.PHY.BWP.BWPUL.{i}.PUSCHConfig.DmrsUplinkForPUSCHMappingTypeB.DmrsAdditionalPosition | C63: DmrsAdditionalPosition | D63: PUSCH类型B的解调参考信号额外位置 | E63: MC | F63: RW | G63: enumeration[pos0,pos1,pos2,pos3] | H63: PUSCH类型B的解调参考信号额外位置
B64: Device.Services.FAPService.{i}.CellConfig.{i}.NR.RAN.PHY.BWP.BWPUL.{i}.PUSCHConfig.PuschTpcEnabled | C64: PuschTpcEnabled | D64: PuschTpc开启 | E64: M | F64: RW | G64: boolean | H64: 约束：(true, false)
B65: Device.Services.FAPService.{i}.CellConfig.{i}.NR.RAN.PHY.BWP.BWPUL.{i}.PUSCHConfig.ResourceAllocationType | C65: ResourceAllocationType | D65: 资源分配类型 | E65: MC | F65: RW | G65: enumeration {type0, type1, dynamic} | H65: 约束：(type0, type1, dynamic)
B66: Device.Services.FAPService.{i}.CellConfig.{i}.NR.RAN.PHY.BWP.BWPUL.{i}.PUSCHConfig.ResourceAllocationAdaptiveValue | C66: ResourceAllocationAdaptiveValue | D66: 上行分配自适应值 | E66: MC | F66: RW | G66: unsignedShort[0:273] | H66: [0:273]
