Workbook
Name _Toc375818453: SA!$D$4
Name _Toc375818454: SA!$D$5
Name _Toc375818456: SA!#REF!

Sheet 设备参数数据表
A1: 分类 | B1: 节点 | C1: 英文名称 | D1: 中文名称 | E1: 取值范围 | F1: 默认值 | G1: 类型 | H1: OAM读写权限 | I1: 网管读写权限 | J1: 前置条件 | K1: 后置影响 | L1: 注意事项 | M1: 规范/厂家定义
A2: OAM/专业/系统 | B2: 专业 | E2: （包括单位） | H2: 专业写 | I2: OAM/系统写 | J2: 专业/算法/系统 | K2: 专业/算法/系统 | L2: 填写参数的功能描述和特殊注意事项
B3: 网管信息参数表 | C3: IuhIpAddr | D3: AU板iuh口IP | G3: String(20) | I3: RW | L3: AU板iuh口IP，IP协议层所使用的IP。
B4: 网管信息参数表 | C4: IuhPort | D4: AU板iuh口port | G4: unsignedInt | I4: RW | L4: AU板iuh口port。
A5: 不在网管上显示 | B5: 网管信息参数表 | C5: SrcIpAddr | D5: AU板上层源ip | G5: String | L5: AU板上层源ip。未有用到。
A6: 不在网管上显示 | B6: 网管信息参数表 | C6: SrcPort | D6: AU板上层源port | G6: unsignedInt | L6: AU板上层源port，未有用到。
B7: 网管信息参数表 | C7: FapAddr1 | D7: GU网关ip | G7: String(20) | I7: RW | L7: GU网关ip 一
B8: 网管信息参数表 | C8: FapAddr2 | D8: GU网关ip | G8: String(20) | I8: RW | L8: GU网关ip 二（未有用到）
A9: 不在网管上显示 | B9: 网管信息参数表 | C9: FapAddr3 | D9: GU网关ip | G9: String | L9: GU网关ip 三（未有用到）
B10: 网管信息参数表 | C10: SecIpAddr1 | D10: 安全网关ip1 | G10: String(20) | I10: RW | L10: 安全网关ip一。
B11: 网管信息参数表 | C11: SecIpAddr2 | D11: 安全网关ip2 | G11: String(20) | I11: RW | L11: 安全网关ip二（未有用到）
A12: 不在网管上显示 | B12: 网管信息参数表 | C12: SecIpAddr3 | D12: 安全网关ip3 | G12: String | L12: 安全网关ip三（未有用到）
B13: 网管信息参数表 | C13: Seckey | D13: 安全网关建立密钥 | G13: String(64) | I13: R | L13: 安全网关建立密钥
B14: 网管信息参数表 | C14: SecUseImsi | D14: 建立安全网关imsi | G14: String(16) | I14: R | L14: 建立安全网关imsi
B15: 网管信息参数表 | C15: FapPort | D15: GU网关port | E15: 0~4294967295 | F15: 29169 | G15: unsignedInt | I15: RW | L15: GU网关port。
B16: 网管信息参数表 | C16: IpSecStartAllowedInd | D16: IPSec是否启动开关 | E16: true、false | F16: true | G16: boolean | I16: RW | L16: IpSec开关。 取值false：关闭Ipsec功能 取值true：打开Ipsec功能
B17: 网管信息参数表 | C17: IpSecRekeyTime | D17: ipSec rekey时间 | E17: 0~4294967295(分钟） | F17: 80000 | G17: unsignedInt | I17: RW | L17: IpSec重协商时间。单位：分钟
B18: 网管信息参数表 | C18: IpSecSaLifetime | D18: IPSec SA的生命周期 | E18: 0~4294967295（秒） | F18: 30 | G18: unsignedInt | I18: RW | L18: IPSec SA的生命周期。单位：秒
B19: 网管信息参数表 | C19: IpSecLivenessTimeInterval | D19: liveness时间间隔 | G19: unsignedInt | I19: RW | L19: liveness时间间隔。
A20: 不在网管上显示 | B20: 网管信息参数表 | C20: FapPcSocketIpAddr | D20: 调试日志放置设备IP | G20: String | L20: 调试日志放置设备IP（调试电脑）
A21: 不在网管上显示 | B21: 网管信息参数表 | C21: FapPcSocketPort | D21: 调试日志放置设备端口 | G21: unsignedInt | L21: 调试日志放置设备端口（调试电脑）
B22: 网管信息参数表 | C22: RealIpAddrToPing | D22: 用于ping功能的真实站点IpAddr | G22: String | I22: R | L22: 用于ping功能的真实站点IpAddr
B23: 网管信息参数表 | C23: GateWaySupported | D23: 指示当前所要连接的网关能力 | G23: unsignedInt | I23: RW | L23: 用于指示当前所要连接的网关能力 取值0：网关支持E1+Surf 取值1：网关支持STM-1+ATCA9100 取值2：网关支持AoIP
B24: 网管信息参数表 | C24: Mode | D24: 认证模式 | E24: 0~2 | G24: int | I24: RW | L24: mode为0,为PSK认证，mode为1为usim卡认证，mode为2为sim卡证（预留），-1为非法值，mode为其它值暂时保留
B25: 公共参数表 | C25: AuId | D25: AU注册是使用的基站Id | E25: 0~65535 | G25: unsignedInt | I25: RW | L25: AU注册是使用的基站Id。 取值范围：0~65535
B26: 公共参数表 | C26: A50 | D26: 是否支持A5_0类型加密 | E26: true、false | F26: true | G26: boolean | I26: RW | L26: 物理层是否支持A5_0类型加密。 取值false：不支持 取值true：支持
B27: 公共参数表 | C27: A51 | D27: 是否支持A5_1类型加密 | E27: true、false | F27: true | G27: boolean | I27: RW | L27: 物理层是否支持A5_1类型加密。 取值false：不支持 取值true：支持
B28: 公共参数表 | C28: A52 | D28: 是否支持A5_2类型加密 | E28: true、false | F28: true | G28: boolean | I28: RW | L28: 物理层是否支持A5_2类型加密。 取值false：不支持 取值true：支持
B29: 公共参数表 | C29: A53 | D29: 是否支持A5_3类型加密 | E29: true、false | F29: true | G29: boolean | I29: RW | L29: 物理层是否支持A5_3类型加密。 取值false：不支持 取值true：支持
B30: 公共参数表 | C30: A54 | D30: 是否支持A5_4类型加密 | E30: true、false | F30: false | G30: boolean | I30: RW | L30: 物理层是否支持A5_4类型加密。 取值false：不支持 取值true：支持
B31: 公共参数表 | C31: A55 | D31: 是否支持A5_5类型加密 | E31: true、false | F31: false | G31: boolean | I31: RW | L31: 物理层是否支持A5_5类型加密。 取值false：不支持 取值true：支持
B32: 公共参数表 | C32: A56 | D32: 是否支持A5_6类型加密 | E32: true、false | F32: false | G32: boolean | I32: RW | L32: 物理层是否支持A5_6类型加密。 取值false：不支持 取值true：支持
B33: 公共参数表 | C33: A57 | D33: 是否支持A5_7类型加密 | E33: true、false | F33: false | G33: boolean | I33: RW | L33: 物理层是否支持A5_7类型加密。 取值false：不支持 取值true：支持
A34: 不在网管上显示 | B34: 公共参数表 | C34: AuUserAccessMax | D34: 户型允许接入的用户数上限 | G34: unsignedInt | L34: 根据户型允许接入的用户数上限。 该参数上层暂时未有使用，保留。
A35: 不在网管上显示 | B35: 公共参数表 | C35: AuAlowPwrMax | D35: 户型允许最大发射功率 | G35: unsignedInt | L35: 根据户型允许最大发射功率 该参数上层暂时未有使用，保留。
B36: 公共参数表 | C36: LogTotalSize | D36: 单个日志文件大小 | E36: 0~4294967295(KByte) | F36: 3*1024 | G36: unsignedInt | I36: RW | L36: 日志文件的总大小，以1k Byte为单位
A37: 不在网管上显示 | B37: 公共参数表 | C37: LogTxtNumberMax | D37: 同类型日志文件存储最大文件个数 | G37: unsignedInt | L37: 同类型日志文件存储最大文件个数。 该参数上层暂时未有使用，保留。
B38: 公共参数表 | C38: LogOutputLevel | D38: 日志输出类型 | E38: 0~4 | F38: 1 | G38: unsignedInt | I38: RW | L38: 日志输出级别。 取值范围：0~4 取值0：DEBUG 取值1：INFO 取值2：TRACE 取值3：WARN 取值4：ERROR
A39: 不在网管上显示 | B39: 公共参数表 | C39: AuProductType | D39: Au产品类型 | L39: Au产品类型,取值范围：0~3 取值0：普通型原型机产品 取值1：企业级大容量产品 取值2：企业级eNB 3+1产品 取值3：普通型降成本产品
A40: 不在网管上显示 | B40: 公共参数表 | C40: AuRfWorkBandCapability | D40: 基站射频支持的工作频段能力 | E40: 0~3 | F40: 0 | G40: unsignedInt | L40: 基站射频支持的工作频段能力，取值范围：0~3 取值0：基站支持1800工作频段 取值1：基站支持900工作频段 取值2：基站支持900E工作频段 取值3：基站支持1900工作频段
...

Sheet 修订历史
C2: 中国移动TD-LTE一体化皮站/飞站基站设备网络管理南向接口数据配置模型规范
A4: 版本 | B4: 日期 | C4: 修订内容 | D4: 修订人
A5: v0.1 | B5: 42557 | C5: 创建初稿 | D5: 贾辉，曹汐
A6: v0.2 | B6: 42579 | C6: 完成征求意见稿 | D6: 贾辉，曹汐
A7: v0.3 | B7: 42619 | C7: 完成集中讨论修订稿 | D7: 贾辉，曹汐
A8: v0.4 | B8: 42642 | C8: 完成省公司征求意见稿 | D8: 贾辉，曹汐
A9: v0.5 | B9: 42657 | C9: 完成根据省公司讨论意见修改 | D9: 贾辉，曹汐
A10: V1.0 | B10: 42660 | C10: 发布稿第一版 | D10: 贾辉，曹汐
A11: V1.1 | B11: 42716 | C11: 基于近期反馈意见修订 | D11: 贾辉，曹汐
A12: V1.2 | B12: 42727 | C12: 修订SF、SH、SJ页笔误及部分参数，SQ页补充网管南向接口性能文件格式规范要求（遵循3GPP规范） | D12: 贾辉，曹汐
A13: V1.3 | B13: 42802 | C13: 修订SF、SG、SJ页数据类型笔误、取值范围等问题 | D13: 贾辉，曹汐
A14: V1.4 | B14: 42944 | C14: 根据一阶段现网试点建议，修订SF页补充3项基站运行状态参数，补充多实例参数Object个数读写属性页要求 | D14: 贾辉，曹汐
A15: V1.5 | B15: 42983 | C15: 新增SR页支持扩展型一体化皮站参数 | D15: 贾辉，曹汐
A16: V1.6 | B16: 43242 | C16: 更正SR页*.EU.{i}.Status和*.RU.{i}.Status两个参数的网管读写属性为只读 | D16: 贾辉，曹汐
A17: V1.7 | B17: 44355 | C17: 更正SF页“基站运行状态参数”为A类参数 | D17: 贾辉，李响
B18: 44356 | C18: Device,DeviceInfo,SerialNumber增加描述“设备序列号，以“-LTE”结尾” | D18: 贾辉，李响
B19: 44370 | C19: 更新SN页LocalTimeZone为string（64） SA页增加UserLabel和DnPrefix SF页增加UserLabel
A20: v1.8 | B20: 44375 | C20: SL页增加UserLabel和PortLocation 目录页增加告警说明 SD页删除serialNumber和OUI
A21: v1.9 | B21: 44377 | C21: 目录页 LDN移除“SA”、“NSA”字段
A22: v2.0 | B22: 44385 | C22: 目录页更新小区LDN为ECI SA也增加软件升级状态 SD页增加FaultLocation，AlarmIdentifier改为string（20） SP页增加MR Item SQ也增加PM补采
A23: v2.1 | B23: 44398 | C23: SD页增加History FaultLocation

Sheet 封面
B3: TD-LTE NanoCell南向数据配置模型规范(推荐版)
B5: 概述（详细问题请查阅正文内容）：
B6: TD-LTE NanoCell南向数据配置模型规范(推荐版)
B7: 文档适应的产品 | D7: 移动 NanoCell
B10: 文档详细信息 | D10: 版本 | E10: 作者 | F10: 时间 | G10: 来源 | H10: 注释
B11: TD-LTE NanoCell网管数据模型规范(初稿) | D11: 首发 | E11: 京信团队 | F11: 42535
G15: 京信通信系统（广州）有限公司

Sheet 目录
A1: 索引 | B1: 参数管理类别 | C1: 参数管理说明 | D1: A类属性数 | E1: B类属性数 | F1: CA类属性数 | G1: CB类属性数 | H1: 小计
A2: SA | B2: DeviceInfo | C2: 设备信息参数管理 | D2: =COUNTIF(SA!$F:$F,"A") -> 20 | E2: =COUNTIF(SA!$F:$F,"B") -> 0 | F2: =COUNTIF(SA!$F:$F,"CA") -> 0 | G2: =COUNTIF(SA!$F:$F,"CB") -> 0 | H2: =SUM($D2:$G2) -> 20
A3: SB | B3: SoftwareCtrl | C3: 软件版本参数管理 | D3: =COUNTIF(SB!$F:$F,"A") -> 5 | E3: =COUNTIF(SB!$F:$F,"B") -> 0 | F3: =COUNTIF(SB!$F:$F,"CA") -> 0 | G3: =COUNTIF(SB!$F:$F,"CB") -> 0 | H3: =SUM($D3:$G3) -> 5
A4: SC | B4: ManagementServer | C4: 基站网管参数管理 | D4: =COUNTIF(SC!$F:$F,"A") -> 19 | E4: =COUNTIF(SC!$F:$F,"B") -> 0 | F4: =COUNTIF(SC!$F:$F,"CA") -> 0 | G4: =COUNTIF(SC!$F:$F,"CB") -> 0 | H4: =SUM($D4:$G4) -> 19
A5: SD | B5: FaultMgmt | C5: 告警参数管理 | D5: =COUNTIF(SD!$F:$F,"A") -> 55 | E5: =COUNTIF(SD!$F:$F,"B") -> 0 | F5: =COUNTIF(SD!$F:$F,"CA") -> 0 | G5: =COUNTIF(SD!$F:$F,"CB") -> 0 | H5: =SUM($D5:$G5) -> 55
A6: SE | B6: DeviceLogMgmt | C6: 日志参数管理 | D6: =COUNTIF(SE!$F:$F,"A") -> 5 | E6: =COUNTIF(SE!$F:$F,"B") -> 0 | F6: =COUNTIF(SE!$F:$F,"CA") -> 0 | G6: =COUNTIF(SE!$F:$F,"CB") -> 0 | H6: =SUM($D6:$G6) -> 5
A7: SF | B7: Services.FAPService | C7: 小区服务参数管理（总体） | D7: =COUNTIF(SF!$F:$F,"A") -> 37 | E7: =COUNTIF(SF!$F:$F,"B") -> 0 | F7: =COUNTIF(SF!$F:$F,"CA") -> 17 | G7: =COUNTIF(SF!$F:$F,"CB") -> 0 | H7: =SUM($D7:$G7) -> 54
A8: SG | B8: Services.FAPService.{i}.SCTP.Transport | C8: SCTP参数管理 | D8: =COUNTIF(SG!$F:$F,"A") -> 13 | E8: =COUNTIF(SG!$F:$F,"B") -> 0 | F8: =COUNTIF(SG!$F:$F,"CA") -> 0 | G8: =COUNTIF(SG!$F:$F,"CB") -> 0 | H8: =SUM($D8:$G8) -> 13
A9: SH | B9: Services.FAPService.{i}.CellConfig.LTE.RAN | C9: RAN协议栈参数 | D9: =COUNTIF(SH!$F:$F,"A") -> 65 | E9: =COUNTIF(SH!$F:$F,"B") -> 0 | F9: =COUNTIF(SH!$F:$F,"CA") -> 6 | G9: =COUNTIF(SH!$F:$F,"CB") -> 0 | H9: =SUM($D9:$G9) -> 71
A10: SI | B10: Services.FAPService.{i}.CellConfig.LTE.RAN.NeighborList | C10: 邻区参数管理 | D10: =COUNTIF(SI!$F:$F,"A") -> 17 | E10: =COUNTIF(SI!$F:$F,"B") -> 0 | F10: =COUNTIF(SI!$F:$F,"CA") -> 10 | G10: =COUNTIF(SI!$F:$F,"CB") -> 0 | H10: =SUM($D10:$G10) -> 27
A11: SJ | B11: Services.FAPService.{i}.CellConfig.LTE.RAN.Mobility | C11: 移动性参数管理 | D11: =COUNTIF(SJ!$F:$F,"A") -> 209 | E11: =COUNTIF(SJ!$F:$F,"B") -> 33 | F11: =COUNTIF(SJ!$F:$F,"CA") -> 74 | G11: =COUNTIF(SJ!$F:$F,"CB") -> 11 | H11: =SUM($D11:$G11) -> 327
A12: SK | B12: Services.FAPService.{i}.FAPControl.LTE.SelfConfig.SONConfigParam | C12: SON参数管理 | D12: =COUNTIF(SK!$F:$F,"A") -> 17 | E12: =COUNTIF(SK!$F:$F,"B") -> 3 | F12: =COUNTIF(SK!$F:$F,"CA") -> 4 | G12: =COUNTIF(SK!$F:$F,"CB") -> 1 | H12: =SUM($D12:$G12) -> 25
A13: SL | B13: WANDevice | C13: WAN口配置参数管理 | D13: =COUNTIF(SL!$F:$F,"A") -> 12 | E13: =COUNTIF(SL!$F:$F,"B") -> 1 | F13: =COUNTIF(SL!$F:$F,"CA") -> 0 | G13: =COUNTIF(SL!$F:$F,"CB") -> 0 | H13: =SUM($D13:$G13) -> 13
A14: SM | B14: Ipsec | C14: IPsec参数管理 | D14: =COUNTIF(SM!$F:$F,"A") -> 9 | E14: =COUNTIF(SM!$F:$F,"B") -> 0 | F14: =COUNTIF(SM!$F:$F,"CA") -> 0 | G14: =COUNTIF(SM!$F:$F,"CB") -> 0 | H14: =SUM($D14:$G14) -> 9
A15: SN | B15: Time | C15: 时间服务器参数管理 | D15: =COUNTIF(SN!$F:$F,"A") -> 5 | E15: =COUNTIF(SN!$F:$F,"B") -> 0 | F15: =COUNTIF(SN!$F:$F,"CA") -> 3 | G15: =COUNTIF(SN!$F:$F,"CB") -> 0 | H15: =SUM($D15:$G15) -> 8
A16: SO | B16: FAP.GPS | C16: GPS信息参数管理 | D16: =COUNTIF(SO!$F:$F,"A") -> 0 | E16: =COUNTIF(SO!$F:$F,"B") -> 0 | F16: =COUNTIF(SO!$F:$F,"CA") -> 0 | G16: =COUNTIF(SO!$F:$F,"CB") -> 3 | H16: =SUM($D16:$G16) -> 3
A17: SP | B17: FAP.MRMgmt | C17: MR参数管理 | D17: =COUNTIF(SP!$F:$F,"A") -> 0 | E17: =COUNTIF(SP!$F:$F,"B") -> 14 | F17: =COUNTIF(SP!$F:$F,"CA") -> 0 | G17: =COUNTIF(SP!$F:$F,"CB") -> 0 | H17: =SUM($D17:$G17) -> 14
A18: SQ | B18: FAP.PerfMgmt | C18: 性能参数管理 | D18: =COUNTIF(SQ!$F:$F,"A") -> 10 | E18: =COUNTIF(SQ!$F:$F,"B") -> 0 | F18: =COUNTIF(SQ!$F:$F,"CA") -> 0 | G18: =COUNTIF(SQ!$F:$F,"CB") -> 0 | H18: =SUM($D18:$G18) -> 10
A19: SR | B19: ENanocell | C19: 扩展型一体化皮基站参数 | D19: =COUNTIF(SR!$F:$F,"A") -> 25 | E19: =COUNTIF(SR!$F:$F,"B") -> 6 | F19: =COUNTIF(SR!$F:$F,"CA") -> 0 | G19: =COUNTIF(SR!$F:$F,"CB") -> 0 | H19: =SUM($D19:$G19) -> 31
A20: 合计 | D20: =SUM(D2:D19) -> 523 | E20: =SUM(E2:E19) -> 57 | F20: =SUM(F2:F19) -> 114 | G20: =SUM(G2:G19) -> 15 | H20: =SUM(H2:H19) -> 709
B21: 说明： 1.LDN的组成方式，按照《中国移动室分系统OMC南向接口要求 第2部分：皮基站技术要求_0611_clean》规范中附录B3.2的样例： i. eNB的LDN的组成如：localDn="ManagedElement=SN,Type=eNB",其中，ManagedElement的SN取SA页InternetGatewayDevice.DeviceInfo.SerialNumber ii. 小区的LDN，其组成如localDn="Type=Cell,eNBID=123,CellIdentity=22" iii. EU的LDN组成如：localDn="ManagedElement=SN,Type=EU,EU=EUSN",其中，EUSN取SA页 InternetGatewayDevice.DeviceInfo.EU.{i}.SerialNumber iv. RU的LDN组成如：localDn="ManagedElement=SN,Type=RU,RU=RUSN",其中，RUSN取SA页InternetGatewayDevice.DeviceInfo.EU.{i}.RU.{i}.SerialNumber v. 网卡的LDN组成如：localDn="ManagedElement=SN,Type=NIC,PortLocation=..." 2.SD页告警ManagedObjectInstance须填写DN，DN后以"|"结尾，并可以携带其他辅助信息，信息以"|"分割 样例(InternetGatewayDevice.DeviceInfo.SerialNumber=1234567)： 1. MU产生告警，则MOI中信息如： "DN='DC=BJ,SubNetwork=1,ManagedElement=1234567,Type=eNB'|......" 2. MU产生小区告警，则MOI中信息如："DN='DC=BJ,SubNetwork=1,ManagedElement=1234567,Type=Cell,eNBID=123,CellIdentity=22'|......" 3. MU产生网卡告警，则MOI中信息如："DN='DC=BJ,SubNetwork=1,ManagedElement=1234567,Type=NIC,PortLocation=...|......"

Sheet SA
A1: 归类 | B1: 网管数据模型(TR098) | C1: 网管数据模型(TR181) | D1: 参数名称 | E1: 中文名 | F1: 重要性 | G1: 北向Index | H1: 北向NRM参数映射 | I1: 网管读写权限 | J1: 类型 | K1: 描述 | L1: 来源 | M1: 备注
A2: 设备信息参数管理 | B2: InternetGatewayDevice.DeviceInfo.UserLabel | C2: Device.DeviceInfo.UserLabel | D2: UserLabel | E2: 用户友好名 | F2: A | G2: AA | H2: UserLabel | I2: RW | J2: string | K2: 字段必须与OMC系统内配置资源名称保持一致。且要求UserLabel与告警、性能数据中同一资源对象使用的网元用户友好名保持一致，即用户有好名在OMC内部以及北向接口交互过程中全局唯一。OMC系统内配置资源命名建议参考《中国移动网络资源命名规范-无线分册》，基站命名要求。 | L2: 技术规范_NanoCell eNB网元统计数据需求规范-NRM(V2.9.0)
B3: InternetGatewayDevice.DeviceInfo.DnPrefix | C3: Device.DeviceInfo.DnPrefix | D3: DnPrefix | E3: DN前缀 | F3: A | G3: / | H3: / | I3: RW | J3: string | K3: 例如"DC=BJ,SubNetwork=1" | L3: 中国移动室分系统OMC南向接口要求 第2部分：皮基站技术要求_0611_clean
B4: InternetGatewayDevice.DeviceInfo.ManufacturerOUI | C4: Device.DeviceInfo.ManufacturerOUI | D4: ManufacturerOUI | E4: 制造商OUI | F4: A | G4: AA | H4: ManufacturerData | I4: R | J4: string(6) | K4: / | L4: TR系列规范(TR098/TR181)/NRM数据配置要求
B5: InternetGatewayDevice.DeviceInfo.Manufacturer | C5: Device.DeviceInfo.Manufacturer | D5: Manufacturer | E5: 制造商 | F5: A | H5: VendorName | I5: R | J5: string(64) | K5: / | L5: TR系列规范(TR098/TR181)/NRM数据配置要求
B6: InternetGatewayDevice.DeviceInfo.ModelName | C6: Device.DeviceInfo.ModelName | D6: ModelName | E6: 设备型号 | F6: A | H6: NeType | I6: R | J6: string(64) | K6: / | L6: TR系列规范(TR098/TR181)/NRM数据配置要求
B7: InternetGatewayDevice.DeviceInfo.SerialNumber | C7: Device.DeviceInfo.SerialNumber | D7: SerialNumber | E7: 序列号 | F7: A | H7: SerialNumber | I7: R | J7: string(64) | K7: 序列号，以“-LTE”结尾 | L7: TR系列规范(TR098/TR181)/NRM数据配置要求
B8: InternetGatewayDevice.DeviceInfo.HardwareVersion | C8: Device.DeviceInfo.HardwareVersion | D8: HardwareVersion | E8: 硬件版本 | F8: A | H8: Version | I8: R | J8: string(64) | K8: / | L8: TR系列规范(TR098/TR181)/NRM数据配置要求
B9: InternetGatewayDevice.DeviceInfo.SoftwareVersion | C9: Device.DeviceInfo.SoftwareVersion | D9: SoftwareVersion | E9: 软件版本 | F9: A | H9: SwVersion | I9: R | J9: string(64) | K9: / | L9: TR系列规范(TR098/TR181)/NRM数据配置要求
B10: InternetGatewayDevice.DeviceInfo.HardwarePlatform | C10: Device.DeviceInfo.HardwarePlatform | D10: HardwarePlatform | E10: 硬件平台 | F10: A | H10: HardwarePlatform | I10: R | J10: string(64) | K10: / | L10: NRM数据配置要求
B11: InternetGatewayDevice.DeviceInfo.AdditionalHardwareVersion | C11: Device.DeviceInfo.AdditionalHardwareVersion | D11: AdditionalHardwareVersion | E11: 附加硬件版本 | F11: A | H11: / | I11: R | J11: string(64) | K11: / | L11: TR系列规范(TR098/TR181)/NRM数据配置要求
B12: InternetGatewayDevice.DeviceInfo.AdditionalSoftwareVersion | C12: Device.DeviceInfo.AdditionalSoftwareVersion | D12: AdditionalSoftwareVersion | E12: 附加软件版本 | F12: A | H12: / | I12: R | J12: string(64) | K12: / | L12: TR系列规范(TR098/TR181)/NRM数据配置要求
B13: InternetGatewayDevice.DeviceInfo.ProvisioningCode | C13: Device.DeviceInfo.ProvisioningCode | D13: ProvisioningCode | E13: 供应商代号 | F13: A | H13: VendorName | I13: R | J13: string(64) | K13: / | L13: TR系列规范(TR098/TR181)/NRM数据配置要求
B14: InternetGatewayDevice.DeviceInfo.ProductClass | C14: Device.DeviceInfo.ProductClass | D14: ProductClass | E14: 产品分类 | F14: A | H14: VendorUnitFamilyType | I14: R | J14: string(64) | K14: / | L14: TR系列规范(TR098/TR181)/NRM数据配置要求
B15: InternetGatewayDevice.DeviceInfo.UpTime | C15: Device.DeviceInfo.UpTime | D15: UpTime | E15: 运行时间 | F15: A | H15: DateOfLastService | I15: R | J15: unsignedInt | K15: / | L15: TR系列规范(TR098/TR181)/NRM数据配置要求
B16: InternetGatewayDevice.DeviceInfo.3GPPSpecVersion | C16: Device.DeviceInfo.3GPPSpecVersion | D16: 3GPPSpecVersion | E16: 3GPP协议版本 | F16: A | H16: / | I16: R | J16: string | K16: / | L16: TR系列规范(TR098/TR181)/NRM数据配置要求
B17: InternetGatewayDevice.DeviceInfo.FirstUseDate | C17: Device.DeviceInfo.FirstUseDate | D17: FirstUseDate | E17: 首次使用日期 | F17: A | H17: DateOfManufacture | I17: R | J17: dateTime | K17: / | L17: TR系列规范(TR098/TR181)/NRM数据配置要求
B18: InternetGatewayDevice.DeviceInfo.SwUpgrade.Stage | C18: Device.DeviceInfo.SwUpgrade.Stage | D18: Stage | E18: 升级阶段 | F18: A | G18: / | H18: / | I18: R | J18: unsignedInt[1:5] | K18: 1:初始化 2:下载 3:安装 4:等待激活 5.激活
B19: InternetGatewayDevice.DeviceInfo.SwUpgrade.FailureCause | C19: Device.DeviceInfo.SwUpgrade.FailureCause | D19: FailureCause | E19: 升级失败原因 | F19: A | G19: / | H19: / | I19: R | J19: string(512) | K19: 升级失败原因描述
B20: InternetGatewayDevice.DeviceInfo.SwUpgrade.Status | C20: Device.DeviceInfo.SwUpgrade.Status | D20: Status | E20: 状态 | F20: A | G20: / | H20: / | I20: R | J20: unsignedInt[1:3] | K20: 1:成功 2:失败
B21: InternetGatewayDevice.DeviceInfo.DataModelSpecVersion | C21: Device.DeviceInfo.DataModelSpecVersion | D21: DataModelSpecVersion | E21: 数据模型版本 | F21: A | G21: / | H21: / | I21: R | J21: string | K21: 描述中国移动技术规范发布的小基站南向数据模型版本号

Sheet SB
A1: 归类 | B1: 网管数据模型(TR098) | C1: 网管数据模型(TR181) | D1: 参数名称 | E1: 中文名 | F1: 重要性 | G1: 北向Index | H1: 北向NRM参数映射 | I1: 网管读写权限 | J1: 类型 | K1: 描述 | L1: 来源 | M1: 备注
A2: 版本参数管理 | B2: InternetGatewayDevice.SoftwareCtrl.AutoActivateEnable | C2: Device.SoftwareCtrl.AutoActivateEnable | D2: AutoActivateEnable | E2: 立即激活目标升级版本使能开关 | F2: A | G2: / | H2: / | I2: RW | J2: boolean | K2: (0=false,1=true)，立即激活目标升级版本使能开关，当为true时，设备下载成功目标升级版本后立即激活版本，当为flase时，需要和ActivateTime这两个参数一起使用。 | L2: 自定义
B3: InternetGatewayDevice.SoftwareCtrl.ActivateTime | C3: Device.SoftwareCtrl.ActivateTime | D3: ActivateTime | E3: 软件激活时间 | F3: A | I3: RW | J3: dateTime | K3: 激活时间，格式如：2012-12-11T19:15:00，下发命令后设备只要在大于等于激活时间里开启，就会激活系统备份版本。
B4: InternetGatewayDevice.SoftwareCtrl.ActivateEnable | C4: Device.SoftwareCtrl.ActivateEnable | D4: ActivateEnable | E4: 激活备份版本使能开关 | F4: A | I4: RW | J4: boolean | K4: (0=false,1=true)激活备份版本使能开关，当为true时立即激活备份版本。
B5: InternetGatewayDevice.SoftwareCtrl.SystemCurrentVersion | C5: Device.SoftwareCtrl.SystemCurrentVersion | D5: SystemCurrentVersion | E5: 系统当前版本 | F5: A | I5: R | J5: string(64) | K5: 系统正在使用的版本。
B6: InternetGatewayDevice.SoftwareCtrl.SystemBackupVersion | C6: Device.SoftwareCtrl.SystemBackupVersion | D6: SystemBackupVersion | E6: 系统备份版本 | F6: A | I6: R | J6: string(64) | K6: 系统备份版本，新下载的或以前使用的版本。

Sheet SC
A1: 归类 | B1: 网管数据模型(TR098) | C1: 网管数据模型(TR181) | D1: 参数名称 | E1: 中文名 | F1: 重要性 | G1: 北向Index | H1: 北向NRM参数映射 | I1: 网管读写权限 | J1: 类型 | K1: 描述 | L1: 来源 | M1: 备注
A2: 网管参数管理 | B2: InternetGatewayDevice.ManagementServer.URL | C2: Device.ManagementServer.URL | D2: URL | E2: 网管服务器URL | F2: A | H2: / | I2: RW | J2: string(256) | K2: ACS使用CWMP连接ACS的URL。格式必须为合法的HTTP/HTTPS的形式。 | L2: TR系列规范(TR098/TR181)
B3: InternetGatewayDevice.ManagementServer.Username | C3: Device.ManagementServer.Username | D3: Username | E3: 连接用户名 | F3: A | H3: / | I3: RW | J3: string(256) | K3: ACS使用CWMP连接基站时使用的认证用户名。仅用于基站的基于HTTP的认证。 | L3: TR系列规范(TR098/TR181)
B4: InternetGatewayDevice.ManagementServer.Password | C4: Device.ManagementServer.Password | D4: Password | E4: 连接密码 | F4: A | H4: / | I4: RW | J4: string(256) | K4: 基站使用CWMP连接ACS时使用的认证密码。仅用于基站的基于HTTP的认证。读取时返回一个空字符串. | L4: TR系列规范(TR098/TR181)
B5: InternetGatewayDevice.ManagementServer.PeriodicInformEnable | C5: Device.ManagementServer.PeriodicInformEnable | D5: PeriodicInformEnable | E5: 连接使能开关 | F5: A | H5: / | I5: RW | J5: boolean | K5: 基站是否必须利用Inform方法调用定时向服务器端发送基站信息。当PeriodicInformEnable=true时，PeriodicInformInterval才起作用 | L5: TR系列规范(TR098/TR181)
B6: InternetGatewayDevice.ManagementServer.PeriodicInformTime | C6: Device.ManagementServer.PeriodicInformTime | D6: PeriodicInformTime | E6: 上报周期 | F6: A | H6: / | I6: RW | J6: dateTime | K6: 2012-12-11T19:15:00 | L6: TR系列规范(TR098/TR181)
B7: InternetGatewayDevice.ManagementServer.PeriodicInformInterval | C7: Device.ManagementServer.PeriodicInformInterval | D7: PeriodicInformInterval | E7: 周期上报时间间隔 | F7: A | H7: / | I7: RW | J7: unsignedInt[1:] | K7: 在PeriodicInformEnable为真时，基站必须尝试连接ACS并调用Inform方法的时间间隔。当PeriodicInformEnable=true才生效 | L7: TR系列规范(TR098/TR181)
B8: InternetGatewayDevice.ManagementServer.ParameterKey | C8: Device.ManagementServer.ParameterKey | D8: ParameterKey | E8: 键值 | F8: A | H8: / | I8: R | J8: string(32) | K8: 来自于服务器的最新的 SetParameterValues，AddObject 或 DeleteObject 方法调用的 ParameterKey 自变量数值。如果没有此类调用，此数值为空。 | L8: TR系列规范(TR098/TR181)
B9: InternetGatewayDevice.ManagementServer.ConnectionRequestURL | C9: Device.ManagementServer.ConnectionRequestURL | D9: ConnectionRequestURL | E9: 连接请求URL | F9: A | G9: AA | H9: ManagementIpAddress | I9: R | J9: string(256) | K9: ACS向基站发起连接请求通知时所使用的HTTPURL。其形式如下：http://host:port/SOAP/HNBServlet?a=1的"主机"部分可以是基站管理接口的IP地址，用以替代域名。 | L9: TR系列规范(TR098/TR181)
B10: InternetGatewayDevice.ManagementServer.ConnectionRequestUsername | C10: Device.ManagementServer.ConnectionRequestUsername | D10: ConnectionRequestUsername | E10: 连接请求用户名 | F10: A | H10: / | I10: RW | J10: string(256) | K10: ACS向基站发起连接请求时，鉴权过程使用的用户名。 | L10: TR系列规范(TR098/TR181)
B11: InternetGatewayDevice.ManagementServer.ConnectionRequestPassword | C11: Device.ManagementServer.ConnectionRequestPassword | D11: ConnectionRequestPassword | E11: 连接请求密码 | F11: A | H11: / | I11: RW | J11: string(256) | K11: ACS向基站发起连接请求时，鉴权过程使用的密码。在被读取时，该参数会忽略实际值而返回一个空字符串。 | L11: TR系列规范(TR098/TR181)
B12: InternetGatewayDevice.ManagementServer.UDPConnectionRequestAddress | C12: Device.ManagementServer.UDPConnectionRequestAddress | D12: UDPConnectionRequestAddress | E12: UDP连接请求地址 | F12: A | H12: / | I12: R | J12: string(256) | K12: / | L12: TR系列规范(TR098/TR181)
B13: InternetGatewayDevice.ManagementServer.STUNEnable | C13: Device.ManagementServer.STUNEnable | D13: STUNEnable | E13: STUN使能开关 | F13: A | H13: / | I13: RW | J13: boolean | K13: (0=false,1=true) | L13: TR系列规范(TR098/TR181)
B14: InternetGatewayDevice.ManagementServer.STUNServerAddress | C14: Device.ManagementServer.STUNServerAddress | D14: STUNServerAddress | E14: STUN服务器地址 | F14: A | H14: / | I14: RW | J14: string(256) | K14: / | L14: TR系列规范(TR098/TR181)
B15: InternetGatewayDevice.ManagementServer.STUNServerPort | C15: Device.ManagementServer.STUNServerPort | D15: STUNServerPort | E15: STUN服务器端口 | F15: A | H15: / | I15: RW | J15: unsignedInt[0:65535] | K15: / | L15: TR系列规范(TR098/TR181)
B16: InternetGatewayDevice.ManagementServer.STUNUsername | C16: Device.ManagementServer.STUNUsername | D16: STUNUsername | E16: STUN用户名 | F16: A | H16: / | I16: RW | J16: string(256) | K16: / | L16: TR系列规范(TR098/TR181)
B17: InternetGatewayDevice.ManagementServer.STUNPassword | C17: Device.ManagementServer.STUNPassword | D17: STUNPassword | E17: STUN密码 | F17: A | H17: / | I17: RW | J17: string(256) | K17: / | L17: TR系列规范(TR098/TR181)
B18: InternetGatewayDevice.ManagementServer.STUNMaximumKeepAlivePeriod | C18: Device.ManagementServer.STUNMaximumKeepAlivePeriod | D18: STUNMaximumKeepAlivePeriod | E18: STUN最大生存周期 | F18: A | H18: / | I18: RW | J18: int[-1:65535] | K18: / | L18: TR系列规范(TR098/TR181)
B19: InternetGatewayDevice.ManagementServer.STUNMinimumKeepAlivePeriod | C19: Device.ManagementServer.STUNMinimumKeepAlivePeriod | D19: STUNMinimumKeepAlivePeriod | E19: STUN最小生存周期 | F19: A | H19: / | I19: RW | J19: unsignedInt[0:65535] | K19: / | L19: TR系列规范(TR098/TR181)
B20: InternetGatewayDevice.ManagementServer.NATDetected | C20: Device.ManagementServer.NATDetected | D20: NATDetected | E20: NAT转换地址 | F20: A | H20: / | I20: R | J20: boolean | K20: (0=false,1=true) | L20: TR系列规范(TR098/TR181)

Sheet SD
A1: 类型 | B1: 网管数据模型(TR098) | C1: 网管数据模型(TR181) | D1: 参数名称 | E1: 中文名 | F1: 重要性 | G1: 北向Index | H1: 北向NRM参数映射 | I1: 网管读写权限 | J1: 类型 | K1: 描述 | L1: 来源 | M1: 备注
A2: 告警管理 | B2: InternetGatewayDevice.FaultMgmt.SupportedAlarmNumberOfEntries | C2: Device.FaultMgmt.SupportedAlarmNumberOfEntries | D2: SupportedAlarmNumberOfEntries | E2: 最大告警实例数量 | F2: A | G2: / | H2: / | I2: R | J2: unsignedInt | K2: / | L2: TR系列规范(TR098/TR181/中国移动Nanocell基站设备网络管理南向接口技术规范v1.3.0)
B3: InternetGatewayDevice.FaultMgmt.MaxCurrentAlarmEntries | C3: Device.FaultMgmt.MaxCurrentAlarmEntries | D3: MaxCurrentAlarmEntries | E3: 最大当前告警实例数量 | F3: A | I3: R | J3: unsignedInt | K3: /
B4: InternetGatewayDevice.FaultMgmt.CurrentAlarmNumberOfEntries | C4: Device.FaultMgmt.CurrentAlarmNumberOfEntries | D4: CurrentAlarmNumberOfEntries | E4: 当前告警实例数量 | F4: A | I4: R | J4: unsignedInt | K4: /
B5: InternetGatewayDevice.FaultMgmt.HistoryEventNumberOfEntries | C5: Device.FaultMgmt.HistoryEventNumberOfEntries | D5: HistoryEventNumberOfEntries | E5: 历史事件实例数量 | F5: A | I5: R | J5: unsignedInt | K5: /
B6: InternetGatewayDevice.FaultMgmt.ExpeditedEventNumberOfEntries | C6: Device.FaultMgmt.ExpeditedEventNumberOfEntries | D6: ExpeditedEventNumberOfEntries | E6: 紧急事件实例数量 | F6: A | I6: R | J6: unsignedInt | K6: /
B7: InternetGatewayDevice.FaultMgmt.QueuedEventNumberOfEntries | C7: Device.FaultMgmt.QueuedEventNumberOfEntries | D7: QueuedEventNumberOfEntries | E7: 队列事件实例数量 | F7: A | I7: R | J7: unsignedInt | K7: /
B8: InternetGatewayDevice.FaultMgmt.SupportedAlarm.{i}.EventType | C8: Device.FaultMgmt.SupportedAlarm.{i}.EventType | D8: EventType | E8: 告警类型 | F8: A | I8: R | J8: string(64) | K8: 设备上报告警消息中的告警类型，包括通讯告警、环境告警、设备告警、处理错误告警、服务质量告警等
B9: InternetGatewayDevice.FaultMgmt.SupportedAlarm.{i}.ProbableCause | C9: Device.FaultMgmt.SupportedAlarm.{i}.ProbableCause | D9: ProbableCause | E9: 告警原因 | F9: A | I9: R | J9: string(64) | K9: /
B10: InternetGatewayDevice.FaultMgmt.SupportedAlarm.{i}.SpecificProblem | C10: Device.FaultMgmt.SupportedAlarm.{i}.SpecificProblem | D10: SpecificProblem | E10: 告警描述 | F10: A | I10: R | J10: string(128) | K10: /
B11: InternetGatewayDevice.FaultMgmt.SupportedAlarm.{i}.PerceivedSeverity | C11: Device.FaultMgmt.SupportedAlarm.{i}.PerceivedSeverity | D11: PerceivedSeverity | E11: 支持告警级别 | F11: A | I11: R | J11: string | K11: 设备上报告警消息中的告警级别：Critical,严重；Major,重要；Minor,次要；Warning,警告；
B12: InternetGatewayDevice.FaultMgmt.SupportedAlarm.{i}.ReportingMechanism | C12: Device.FaultMgmt.SupportedAlarm.{i}.ReportingMechanism | D12: ReportingMechanism | E12: 告警上报机制 | F12: A | I12: RW | J12: string | K12: / | M12: 修改网管读写权限
B13: InternetGatewayDevice.FaultMgmt.CurrentAlarm.{i}.AlarmIdentifier | C13: Device.FaultMgmt.CurrentAlarm.{i}.AlarmIdentifier | D13: AlarmIdentifier | E13: 该告警的唯一序列号 | F13: A | I13: R | J13: string(20) | K13: /
B14: InternetGatewayDevice.FaultMgmt.CurrentAlarm.{i}.AlarmRaisedTime | C14: Device.FaultMgmt.CurrentAlarm.{i}.AlarmRaisedTime | D14: AlarmRaisedTime | E14: 告警发生时间 | F14: A | I14: R | J14: dateTime | K14: /
B15: InternetGatewayDevice.FaultMgmt.CurrentAlarm.{i}.AlarmChangedTime | C15: Device.FaultMgmt.CurrentAlarm.{i}.AlarmChangedTime | D15: AlarmChangedTime | E15: 告警改变时间 | F15: A | I15: R | J15: dateTime | K15: /
B16: InternetGatewayDevice.FaultMgmt.CurrentAlarm.{i}.FaultLocation | C16: Device.FaultMgmt.CurrentAlarm.{i}.FaultLocation | D16: FaultLocation | E16: 告警源定位信息 | F16: A | G16: / | H16: / | I16: R | J16: string(512) | K16: 表示故障源对应的资源对象信息，通常用管理对象实例（MOI）的DN表示。其中对于MOI的DN定义，5G皮基站参考《中国移动5G扩展型皮基站网管南向接口数据模型规范》相关说明，4G皮基站参考《中国移动一体化皮站_飞站基站设备网络管理南向接口数据配置模型规范》相关说明
B17: InternetGatewayDevice.FaultMgmt.CurrentAlarm.{i}.ManagedObjectInstance | C17: Device.FaultMgmt.CurrentAlarm.{i}.ManagedObjectInstance | D17: ManagedObjectInstance | E17: 管理对象实例 | F17: A | I17: R | J17: string(512) | K17: 定义了承载该对象实例DN时发生的基站告警的信息对象等级的实例 | M17: 手动同步告警采用该模型节点上报
B18: InternetGatewayDevice.FaultMgmt.CurrentAlarm.{i}.EventType | C18: Device.FaultMgmt.CurrentAlarm.{i}.EventType | D18: EventType | E18: 告警类型 | F18: A | I18: R | J18: string(64) | K18: 设备上报告警消息中的告警类型，包括通讯告警、环境告警、设备告警、处理错误告警、服务质量告警等
B19: InternetGatewayDevice.FaultMgmt.CurrentAlarm.{i}.ProbableCause | C19: Device.FaultMgmt.CurrentAlarm.{i}.ProbableCause | D19: ProbableCause | E19: 告警原因 | F19: A | I19: R | J19: string(64) | K19: /
B20: InternetGatewayDevice.FaultMgmt.CurrentAlarm.{i}.SpecificProblem | C20: Device.FaultMgmt.CurrentAlarm.{i}.SpecificProblem | D20: SpecificProblem | E20: 告警描述 | F20: A | I20: R | J20: string(128) | K20: /
B21: InternetGatewayDevice.FaultMgmt.CurrentAlarm.{i}.PerceivedSeverity | C21: Device.FaultMgmt.CurrentAlarm.{i}.PerceivedSeverity | D21: PerceivedSeverity | E21: 当前告警级别 | F21: A | I21: R | J21: string | K21: 设备上报告警消息中的告警级别：Critical,严重；Major,重要；Minor,次要；Warning,警告；
B22: InternetGatewayDevice.FaultMgmt.CurrentAlarm.{i}.AdditionalText | C22: Device.FaultMgmt.CurrentAlarm.{i}.AdditionalText | D22: AdditionalText | E22: 告警附加文本 | F22: A | I22: R | J22: string(256) | K22: 本规范规定内容为厂家告警编码
B23: InternetGatewayDevice.FaultMgmt.CurrentAlarm.{i}.AdditionalInformation | C23: Device.FaultMgmt.CurrentAlarm.{i}.AdditionalInformation | D23: AdditionalInformation | E23: 告警附加信息 | F23: A | I23: R | J23: string(256) | K23: （格式：英文）统一采用此参数作为告警附加信息，映射到北向的AlarmText字段
B24: InternetGatewayDevice.FaultMgmt.HistoryEvent.{i}.EventTime | C24: Device.FaultMgmt.HistoryEvent.{i}.EventTime | D24: EventTime | E24: 告警发生、改变、清除的时间 | F24: A | I24: R | J24: dateTime | K24: /
B25: InternetGatewayDevice.FaultMgmt.HistoryEvent.{i}.AlarmIdentifier | C25: Device.FaultMgmt.HistoryEvent.{i}.AlarmIdentifier | D25: AlarmIdentifier | E25: 该告警的唯一序列号 | F25: A | I25: R | J25: string(20) | K25: /
B26: InternetGatewayDevice.FaultMgmt.HistoryEvent.{i}.NotificationType | C26: Device.FaultMgmt.HistoryEvent.{i}.NotificationType | D26: NotificationType | E26: 通知类型 | F26: A | I26: R | J26: string | K26: /
B27: InternetGatewayDevice.FaultMgmt.HistoryEvent.{i}.FaultLocation | C27: Device.FaultMgmt.HistoryEvent.{i}.FaultLocation | D27: FaultLocation | E27: 告警源定位信息 | F27: A | G27: / | H27: / | I27: R | J27: string(512) | K27: 表示故障源对应的资源对象信息，通常用管理对象实例（MOI）的DN表示。其中对于MOI的DN定义，5G皮基站参考《中国移动5G扩展型皮基站网管南向接口数据模型规范》相关说明，4G皮基站参考《中国移动一体化皮站_飞站基站设备网络管理南向接口数据配置模型规范》相关说明
B28: InternetGatewayDevice.FaultMgmt.HistoryEvent.{i}.ManagedObjectInstance | C28: Device.FaultMgmt.HistoryEvent.{i}.ManagedObjectInstance | D28: ManagedObjectInstance | E28: 管理对象实例 | F28: A | I28: R | J28: string(512) | K28: 定义了承载该对象实例DN时发生的基站告警的信息对象等级的实例
B29: InternetGatewayDevice.FaultMgmt.HistoryEvent.{i}.EventType | C29: Device.FaultMgmt.HistoryEvent.{i}.EventType | D29: EventType | E29: 告警类型 | F29: A | I29: R | J29: string(64) | K29: 设备上报告警消息中的告警类型，包括通讯告警、环境告警、设备告警、处理错误告警、服务质量告警等
B30: InternetGatewayDevice.FaultMgmt.HistoryEvent.{i}.ProbableCause | C30: Device.FaultMgmt.HistoryEvent.{i}.ProbableCause | D30: ProbableCause | E30: 告警原因 | F30: A | I30: R | J30: string(64) | K30: /
B31: InternetGatewayDevice.FaultMgmt.HistoryEvent.{i}.SpecificProblem | C31: Device.FaultMgmt.HistoryEvent.{i}.SpecificProblem | D31: SpecificProblem | E31: 告警描述 | F31: A | I31: R | J31: string(128) | K31: /
B32: InternetGatewayDevice.FaultMgmt.HistoryEvent.{i}.PerceivedSeverity | C32: Device.FaultMgmt.HistoryEvent.{i}.PerceivedSeverity | D32: PerceivedSeverity | E32: 告警级别 | F32: A | I32: R | J32: string | K32: 设备上报告警消息中的告警级别：Critical,严重；Major,重要；Minor,次要；Warning,警告；
B33: InternetGatewayDevice.FaultMgmt.HistoryEvent.{i}.AdditionalText | C33: Device.FaultMgmt.HistoryEvent.{i}.AdditionalText | D33: AdditionalText | E33: 告警附加文本 | F33: A | I33: R | J33: string(256) | K33: 本规范规定内容为厂家告警编码
B34: InternetGatewayDevice.FaultMgmt.HistoryEvent.{i}.AdditionalInformation | C34: Device.FaultMgmt.HistoryEvent.{i}.AdditionalInformation | D34: AdditionalInformation | E34: 告警附加信息 | F34: A | I34: R | J34: string(256) | K34: 格式：英文。统一采用此参数作为告警附加信息，映射到北向的AlarmText字段
B35: InternetGatewayDevice.FaultMgmt.ExpeditedEvent.{i}.EventTime | C35: Device.FaultMgmt.ExpeditedEvent.{i}.EventTime | D35: EventTime | E35: 告警发生、改变、清除的时间 | F35: A | I35: R | J35: dateTime | K35: /
B36: InternetGatewayDevice.FaultMgmt.ExpeditedEvent.{i}.AlarmIdentifier | C36: Device.FaultMgmt.ExpeditedEvent.{i}.AlarmIdentifier | D36: AlarmIdentifier | E36: 该告警的唯一序列号 | F36: A | I36: R | J36: string(20) | K36: /
B37: InternetGatewayDevice.FaultMgmt.ExpeditedEvent.{i}.NotificationType | C37: Device.FaultMgmt.ExpeditedEvent.{i}.NotificationType | D37: NotificationType | E37: 通知类型 | F37: A | I37: R | J37: string | K37: /
B38: InternetGatewayDevice.FaultMgmt.ExpeditedEvent.{i}.FaultLocation | C38: Device.FaultMgmt.ExpeditedEvent.{i}.FaultLocation | D38: FaultLocation | E38: 告警源定位信息 | F38: A | G38: / | H38: / | I38: R | J38: string(512) | K38: 表示故障源对应的资源对象信息，通常用管理对象实例（MOI）的DN表示。其中对于MOI的DN定义，5G皮基站参考《中国移动5G扩展型皮基站网管南向接口数据模型规范》相关说明，4G皮基站参考《中国移动一体化皮站_飞站基站设备网络管理南向接口数据配置模型规范》相关说明
B39: InternetGatewayDevice.FaultMgmt.ExpeditedEvent.{i}.ManagedObjectInstance | C39: Device.FaultMgmt.ExpeditedEvent.{i}.ManagedObjectInstance | D39: ManagedObjectInstance | E39: 管理对象实例 | F39: A | I39: R | J39: string(512) | K39: 定义了承载该对象实例DN时发生的基站告警的信息对象等级的实例
B40: InternetGatewayDevice.FaultMgmt.ExpeditedEvent.{i}.EventType | C40: Device.FaultMgmt.ExpeditedEvent.{i}.EventType | D40: EventType | E40: 告警类型 | F40: A | I40: R | J40: string(64) | K40: 设备上报告警消息中的告警类型，包括通讯告警、环境告警、设备告警、处理错误告警、服务质量告警等
...

Sheet SE
A1: 归类 | B1: 网管数据模型(TR098) | C1: 网管数据模型(TR181) | D1: 参数名称 | E1: 中文名 | F1: 重要性 | G1: 北向Index | H1: 北向NRM参数映射 | I1: 网管读写权限 | J1: 类型 | K1: 描述 | L1: 来源 | M1: 备注
A2: 日志参数管理 | B2: InternetGatewayDevice.LogMgmt.PeriodicUploadEnable | C2: Device.LogMgmt.PeriodicUploadEnable | D2: PeriodicUploadEnable | E2: 日志周期上传使能开关 | F2: A | G2: / | H2: / | I2: RW | J2: boolean | K2: (0=false,1=true),禁止或启用将设备日志周期性地发送到指定的文件服务器。在使能开关开启的情况下，如果还未达到上报周期，设备日志文件已达到存储容量上限，则应立即将该时段的增量日志上报到HeMS，并开启一个新的上报周期的要求。 | L2: 2015年中国移动一体化皮基站网管南向接口技术规范.docx
B3: InternetGatewayDevice.LogMgmt.URL | C3: Device.LogMgmt.URL | D3: URL | E3: 日志上传URL | F3: A | I3: RW | J3: string(256) | K3: 指定了目的日志的位置，没有以任何方式指明需要上传的本地文件的名字和位置
B4: InternetGatewayDevice.LogMgmt.Username | C4: Device.LogMgmt.Username | D4: Username | E4: 日志管理用户名 | F4: A | I4: RW | J4: string(256) | K4: 用户名用于设备到日志服务器的鉴权，如果不需要鉴权，此字符串为空，当PeriodicUploadEnable=true时，才生效。
B5: InternetGatewayDevice.LogMgmt.Password | C5: Device.LogMgmt.Password | D5: Password | E5: 日志管理密码 | F5: A | I5: RW | J5: string(256) | K5: 密码用于设备到日志服务器的鉴权，如果不需要鉴权，此字符串为空 当为读时，该参数返回一个空字符串，而不是一个实际的值，当PeriodicUploadEnable=true时，才生效。
B6: InternetGatewayDevice.LogMgmt.PeriodicUploadInterval | C6: Device.LogMgmt.PeriodicUploadInterval | D6: PeriodicUploadInterval | E6: 日志周期上传时间间隔 | F6: A | I6: RW | J6: unsignedInt[1:]

Sheet SF
A1: 归类 | B1: 网管数据模型(TR098) | C1: 网管数据模型(TR181) | D1: 参数名称 | E1: 中文名 | F1: 重要性 | G1: 北向Index | H1: 北向NRM参数映射 | I1: 网管读写权限 | J1: 类型 | K1: 描述 | L1: 来源 | M1: 备注
A2: NNSF参数管理 | B2: InternetGatewayDevice.Services.FAPService.{i}.Capabilities.LTE.NNSFSupported | C2: Device.Services.FAPService.{i}.Capabilities.LTE.NNSFSupported | D2: NNSFSupported | E2: 负载均衡参数 | F2: A | H2: IsLbAllowed | I2: RW | J2: boolean | K2: (0=false,1=true) | L2: TR系列规范(TR098/TR181/TR196)/NRM数据配置要求
A3: EPC参数管理 | B3: InternetGatewayDevice.Services.FAPService.{i}.CellConfig.LTE.EPC.EAID | C3: Device.Services.FAPService.{i}.CellConfig.LTE.EPC.EAID | D3: EAID | E3: EPCEAID | F3: A | H3: / | I3: RW | J3: unsignedInt[0:16777216] | K3: 突发事件区域ID | L3: TR系列规范(TR098/TR181/TR196) | M3: 修正参数类型
B4: InternetGatewayDevice.Services.FAPService.{i}.CellConfig.LTE.EPC.TAC | C4: Device.Services.FAPService.{i}.CellConfig.LTE.EPC.TAC | D4: TAC | E4: TAC | F4: A | H4: Tac | I4: RW | J4: unsignedInt[0:65535] | K4: 跟踪区代码 | L4: TR系列规范(TR098/TR181/TR196)/NRM数据配置要求
A5: MME地址 | B5: InternetGatewayDevice.Services.FAPService.{i}.CellConfig.LTE.MmePoolConfigParam.{i}.PLMNID | C5: Device.Services.FAPService.{i}.CellConfig.LTE.MmePoolConfigParam.{i}.PLMNID | D5: PLMNID | E5: MMEPLMN标识 | F5: CA | G5: AN | H5: GlobalUniqueMmeId | I5: R | J5: string(6) | K5: / | L5: NRM数据配置要求 | M5: 修正参数类型为string(6)
B6: InternetGatewayDevice.Services.FAPService.{i}.CellConfig.LTE.MmePoolConfigParam.{i}.MMEGroupID | C6: Device.Services.FAPService.{i}.CellConfig.LTE.MmePoolConfigParam.{i}.MMEGroupID | D6: MMEGroupID | E6: MMEGroup标识 | F6: CA | H6: GlobalUniqueMmeId | I6: R | J6: unsignedInt[0:65535] | K6: / | L6: NRM数据配置要求
B7: InternetGatewayDevice.Services.FAPService.{i}.CellConfig.LTE.MmePoolConfigParam.{i}.MMECode | C7: Device.Services.FAPService.{i}.CellConfig.LTE.MmePoolConfigParam.{i}.MMECode | D7: MMECode | E7: MME代码 | F7: CA | H7: GlobalUniqueMmeId | I7: R | J7: unsignedInt[0:255] | K7: / | L7: NRM数据配置要求
B8: InternetGatewayDevice.Services.FAPService.{i}.CellConfig.LTE.MmePoolConfigParam.{i}.MMEIp1 | C8: Device.Services.FAPService.{i}.CellConfig.LTE.MmePoolConfigParam.{i}.MMEIp1 | D8: MMEIp1 | E8: MMEIP1 | F8: CA | H8: FarEndIpAddrList | I8: R | J8: string(64) | K8: / | L8: NRM数据配置要求
B9: InternetGatewayDevice.Services.FAPService.{i}.CellConfig.LTE.MmePoolConfigParam.{i}.MMEIp2 | C9: Device.Services.FAPService.{i}.CellConfig.LTE.MmePoolConfigParam.{i}.MMEIp2 | D9: MMEIp2 | E9: MMEIP2 | F9: CA | H9: FarEndIpAddrList | I9: R | J9: string(64) | K9: / | L9: NRM数据配置要求
A10: S1-U对象 | B10: InternetGatewayDevice.Services.FAPService.{i}.CellConfig.LTE.S1U.{i}.LocIpAddrList | C10: Device.Services.FAPService.{i}.CellConfig.LTE.S1U.{i}.LocIpAddrList | D10: LocIpAddrList | E10: 本地IP地址列表 | F10: A | G10: AI | H10: LocIpAddrList | I10: R | J10: string(64) | K10: / | L10: NRM数据配置要求
B11: InternetGatewayDevice.Services.FAPService.{i}.CellConfig.LTE.S1U.{i}.FarIpSubnetworkList | C11: Device.Services.FAPService.{i}.CellConfig.LTE.S1U.{i}.FarIpSubnetworkList | D11: FarIpSubnetworkList | E11: 远端IP地址列表 | F11: A | H11: FarIpSubnetworkList | I11: R | J11: string(64) | K11: / | L11: NRM数据配置要求
A12: 安全网关参数管理 | B12: InternetGatewayDevice.Services.FAPService.{i}.FAPControl.LTE.Gateway.SecGWServer1 | C12: Device.Services.FAPService.{i}.FAPControl.LTE.Gateway.SecGWServer1 | D12: SecGWServer1 | E12: 安全网关1 | F12: A | G12: AX、AY | H12: FarEndIpAddrList | I12: RW | J12: string(64) | L12: TR系列规范(TR098/TR181/TR196)/NRM数据配置要求
B13: InternetGatewayDevice.Services.FAPService.{i}.FAPControl.LTE.Gateway.SecGWServer2 | C13: Device.Services.FAPService.{i}.FAPControl.LTE.Gateway.SecGWServer2 | D13: SecGWServer2 | E13: 安全网关2 | F13: A | H13: FarEndIpAddrList | I13: RW | J13: string(64) | L13: TR系列规范(TR098/TR181/TR196)/NRM数据配置要求
B14: InternetGatewayDevice.Services.FAPService.{i}.FAPControl.LTE.Gateway.SecGWServer3 | C14: Device.Services.FAPService.{i}.FAPControl.LTE.Gateway.SecGWServer3 | D14: SecGWServer3 | E14: 安全网关3 | F14: A | H14: FarEndIpAddrList | I14: RW | J14: string(64) | L14: TR系列规范(TR098/TR181/TR196)/NRM数据配置要求
A15: 接入网关参数管理 | B15: InternetGatewayDevice.Services.FAPService.{i}.FAPControl.LTE.Gateway.AGServerEnable | C15: Device.Services.FAPService.{i}.FAPControl.LTE.Gateway.AGServerEnable | D15: AGServerEnable | E15: HeGW方式接入 | F15: CA | H15: AccessHegw | I15: RW | J15: boolean | K15: 控制小基站采用信令网关地址或MME地址来连接 (0=采用MME地址,1=采用信令网关地址) | L15: NRM数据配置要求
B16: InternetGatewayDevice.Services.FAPService.{i}.FAPControl.LTE.Gateway.AGServerIp1 | C16: Device.Services.FAPService.{i}.FAPControl.LTE.Gateway.AGServerIp1 | D16: AGServerIp1 | E16: 接入网关1 | F16: CA | H16: FarEndIpAddrList | I16: RW | J16: string(64)
B17: InternetGatewayDevice.Services.FAPService.{i}.FAPControl.LTE.Gateway.AGServerIp2 | C17: Device.Services.FAPService.{i}.FAPControl.LTE.Gateway.AGServerIp2 | D17: AGServerIp2 | E17: 接入网关2 | F17: CA | H17: FarEndIpAddrList | I17: RW | J17: string(64)
B18: InternetGatewayDevice.Services.FAPService.{i}.FAPControl.LTE.Gateway.AGServerIp3 | C18: Device.Services.FAPService.{i}.FAPControl.LTE.Gateway.AGServerIp3 | D18: AGServerIp3 | E18: 接入网关3 | F18: CA | H18: FarEndIpAddrList | I18: RW | J18: string(64)
B19: InternetGatewayDevice.Services.FAPService.{i}.FAPControl.LTE.Gateway.AGPort1 | C19: Device.Services.FAPService.{i}.FAPControl.LTE.Gateway.AGPort1 | D19: AGPort1 | E19: 接入网关端口1 | F19: CA | H19: / | I19: RW | J19: string(64) | L19: 自定义
B20: InternetGatewayDevice.Services.FAPService.{i}.FAPControl.LTE.Gateway.AGPort2 | C20: Device.Services.FAPService.{i}.FAPControl.LTE.Gateway.AGPort2 | D20: AGPort2 | E20: 接入网关端口2 | F20: CA | H20: / | I20: RW | J20: string(64)
B21: InternetGatewayDevice.Services.FAPService.{i}.FAPControl.LTE.Gateway.AGPort3 | C21: Device.Services.FAPService.{i}.FAPControl.LTE.Gateway.AGPort3 | D21: AGPort3 | E21: 接入网关端口3 | F21: CA | H21: / | I21: RW | J21: string(64)
A22: X2连接地址 | B22: InternetGatewayDevice.Services.FAPService.{i}.FAPControl.X2IpAddrMapInfo.{i}.PLMNID | C22: Device.Services.FAPService.{i}.FAPControl.X2IpAddrMapInfo.{i}.PLMNID | D22: PLMNID | E22: PLMNID | F22: A | G22: AG | H22: / | I22: RW | J22: string(6) | K22: / | L22: 自定义 | M22: 修正参数类型为string(6)
B23: InternetGatewayDevice.Services.FAPService.{i}.FAPControl.X2IpAddrMapInfo.{i}.EnbType | C23: Device.Services.FAPService.{i}.FAPControl.X2IpAddrMapInfo.{i}.EnbType | D23: EnbType | E23: 基站类型 | F23: A | I23: RW | J23: unsignedInt | K23: /
B24: InternetGatewayDevice.Services.FAPService.{i}.FAPControl.X2IpAddrMapInfo.{i}.EnbId | C24: Device.Services.FAPService.{i}.FAPControl.X2IpAddrMapInfo.{i}.EnbId | D24: EnbId | E24: eNBID | F24: A | I24: RW | J24: unsignedInt | K24: /
B25: InternetGatewayDevice.Services.FAPService.{i}.FAPControl.X2IpAddrMapInfo.{i}.WanIpAddress | C25: Device.Services.FAPService.{i}.FAPControl.X2IpAddrMapInfo.{i}.WanIpAddress | D25: WanIpAddress | E25: WAN口IP | F25: A | H25: X2IpAddressList | I25: RW | J25: string(64) | K25: / | L25: NRM数据配置要求
B26: InternetGatewayDevice.Services.FAPService.{i}.FAPControl.X2IpAddrMapInfo.{i}.SubnetMask | C26: Device.Services.FAPService.{i}.FAPControl.X2IpAddrMapInfo.{i}.SubnetMask | D26: SubnetMask | E26: 子网掩码 | F26: A | H26: X2IpAddressList | I26: RW | J26: string(64) | K26: / | L26: NRM数据配置要求 | M26: 增加子网掩码用于配置X2连接地址
A27: 小区闭塞 | B27: InternetGatewayDevice.Services.FAPService.{i}.CellConfig.LTE.RAN.CellRestriction.CellBarred | C27: Device.Services.FAPService.{i}.CellConfig.LTE.RAN.CellRestriction.CellBarred | D27: CellBarred | E27: 小区闭塞 | F27: A | G27: AQ | H27: CellBarred | I27: RW | J27: boolean | K27: {barred, notBarred} | L27: NRM数据配置要求 | M27: 修正参数类型
A28: 接入UE数量管理 | B28: InternetGatewayDevice.Services.FAPService.{i}.AccessMgmt.LTE.UeInactiveTimer | C28: Device.Services.FAPService.{i}.Capabilities.LTE.UeInactiveTimer | D28: UeInactiveTimer | E28: 连接态UE不活动定时器 | F28: A | H28: UeInactiveTimer | I28: RW | J28: unsignedInt[0:65535] | K28: / | L28: NRM数据配置要求
B29: InternetGatewayDevice.Services.FAPService.{i}.AccessMgmt.LTE.MaxUEsServed | C29: Device.Services.FAPService.{i}.AccessMgmt.LTE.MaxUEsServed | D29: SupportRRCNumbers | E29: 同时支持RRC连接最大用户数 | F29: A | H29: SupportRRCNumbers | I29: R | J29: int[-1:] | K29: / | L29: TR系列规范(TR098/TR181/TR196)/NRM数据配置要求 | M29: 修正参数类型
B30: InternetGatewayDevice.Services.FAPService.{i}.AccessMgmt.LTE.SupportActiveRRCNumbers | C30: Device.Services.FAPService.{i}.Capabilities.LTE.SupportActiveRRCNumbers | D30: SupportActiveRRCNumbers | E30: 同时支持RRC激活最大用户数 | F30: A | H30: SupportActiveRRCNumbers | I30: R | J30: unsignedInt[0:65535] | K30: / | L30: NRM数据配置要求
A31: 基站PLMN参数列表 | B31: InternetGatewayDevice.Services.FAPService.{i}.CellConfig.LTE.EPC.PLMNList.{i}.PLMNID | C31: Device.Services.FAPService.{i}.CellConfig.LTE.EPC.PLMNList.{i}.PLMNID | D31: PLMNID | E31: 小区PLMNID | F31: A | H31: PlmnIdList | I31: RW | J31: string(6) | K31: 由MCC和MNC组成 | L31: TR系列规范(TR098/TR181/TR196)/NRM数据配置要求 | M31: 修正参数类型
B32: InternetGatewayDevice.Services.FAPService.{i}.CellConfig.LTE.EPC.PLMNList.{i}.CellReservedForOperatorUse | C32: Device.Services.FAPService.{i}.CellConfig.LTE.EPC.PLMNList.{i}.CellReservedForOperatorUse | D32: CellReservedForOperatorUse | E32: 小区预留标识 | F32: A | H32: / | I32: RW | J32: boolean | K32: 供运营商使用的小区预留标志 | L32: TR系列规范(TR098/TR181/TR196)/NRM数据配置要求
A33: 广播参数管理 | B33: InternetGatewayDevice.Services.FAPService.{i}.CellConfig.SysInfoCtrlParam.MultiBandInfoListSIB1 | C33: Device.Services.FAPService.{i}.CellConfig.SysInfoCtrlParam.MultiBandInfoListSIB1 | D33: MultiBandInfoListSIB1 | E33: SIB1中多频段指示参数 | F33: CA | H33: MultiBandInfoListSIB1 | I33: RW | J33: unsignedInt[1:64] | K33: / | L33: NRM数据配置要求
B34: InternetGatewayDevice.Services.FAPService.{i}.CellConfig.SysInfoCtrlParam.MultiBandInfoListSIB5 | C34: Device.Services.FAPService.{i}.CellConfig.SysInfoCtrlParam.MultiBandInfoListSIB5 | D34: MultiBandInfoListSIB5 | E34: SIB5中多频段指示参数 | F34: CA | H34: MultiBandInfoListSIB5 | I34: RW | J34: unsignedInt[1:64] | K34: / | L34: NRM数据配置要求
A35: 小区参数管理 | B35: InternetGatewayDevice.Services.FAPService.{i}.CellConfig.LTE.RAN.RF.UserLabel | C35: Device.Services.FAPService.{i}.CellConfig.LTE.RAN.RF.UserLabel | D35: UserLabel | E35: 用户友好名 | F35: A | G35: AJ | H35: UserLabel | I35: RW | J35: string | K35: 字段必须与OMC系统内配置资源名称保持一致。且要求UserLabel与告警、性能数据中同一资源对象使用的网元用户友好名保持一致，即用户有好名在OMC内部以及北向接口交互过程中全局唯一。OMC系统内配置资源命名建议参考《中国移动网络资源命名规范-无线分册》，基站命名要求。 | L35: 技术规范_NanoCell eNB网元统计数据需求规范-NRM(V2.9.0)
B36: InternetGatewayDevice.Services.FAPService.{i}.CellConfig.LTE.RAN.RF.EARFCNDL | C36: Device.Services.FAPService.{i}.CellConfig.LTE.RAN.RF.EARFCNDL | D36: EARFCNDL | E36: 下行EARFCN | F36: A | G36: AJ、AG | H36: Earfcn | I36: RW | J36: string(128) | K36: 下行EARFCN | L36: TR系列规范(TR098/TR181/TR196)/NRM数据配置要求 | M36: 修正参数类型
B37: InternetGatewayDevice.Services.FAPService.{i}.CellConfig.LTE.RAN.RF.PhyCellID | C37: Device.Services.FAPService.{i}.CellConfig.LTE.RAN.RF.PhyCellID | D37: PhyCellID | E37: PCI | F37: A | H37: Pci | I37: RW | J37: string(512) | K37: PCI | L37: TR系列规范(TR098/TR181/TR196)/NRM数据配置要求 | M37: 修正参数类型，修改参数名大小写，保持和TR196一致
B38: InternetGatewayDevice.Services.FAPService.{i}.CellConfig.LTE.RAN.RF.DLBandwidth | C38: Device.Services.FAPService.{i}.CellConfig.LTE.RAN.RF.DLBandwidth | D38: DLBandwidth | E38: 下行带宽 | F38: A | H38: BandWidth | I38: RW | J38: string(32) | K38: 下行带宽 | L38: TR系列规范(TR098/TR181/TR196)/NRM数据配置要求 | M38: 修正参数类型
B39: InternetGatewayDevice.Services.FAPService.{i}.CellConfig.LTE.RAN.RF.ULBandwidth | C39: Device.Services.FAPService.{i}.CellConfig.LTE.RAN.RF.ULBandwidth | D39: ULBandwidth | E39: 上行带宽 | F39: A | H39: / | I39: RW | J39: string(32) | K39: 上行带宽 | L39: TR系列规范(TR098/TR181/TR196) | M39: 修正参数类型
B40: InternetGatewayDevice.Services.FAPService.{i}.CellConfig.LTE.RAN.RF.PSCHPowerOffset | C40: Device.Services.FAPService.{i}.CellConfig.LTE.RAN.RF.PSCHPowerOffset | D40: PSCHPowerOffset | E40: PSCH功率偏置 | F40: A | I40: RW | J40: string(512) | K40: 主同步信道相对ReferenceSignalPower的功率偏置 | L40: TR系列规范(TR098/TR181/TR196) | M40: 修正参数类型
...

Sheet SG
A1: 归类 | B1: 网管数据模型(TR098) | C1: 网管数据模型(TR181) | D1: 参数名称 | E1: 中文名 | F1: 重要性 | G1: 北向Index | H1: 北向NRM参数映射 | I1: 网管读写权限 | J1: 类型 | K1: 描述 | L1: 来源 | M1: 备注
A2: SCTP参数管理 | B2: InternetGatewayDevice.Services.FAPService.{i}.Transport.SCTP.Enable | C2: Device.Services.FAPService.{i}.Transport.SCTP.Enable | D2: Enable | E2: 使能开关 | F2: A | H2: / | I2: RW | J2: Boolean | K2: / | L2: TR系列规范(TR098/TR181/TR196)
B3: InternetGatewayDevice.Services.FAPService.{i}.Transport.SCTP.RTOInitial | C3: Device.Services.FAPService.{i}.Transport.SCTP.RTOInitial | D3: RTOInitial | E3: 重传超时的初始值 | F3: A | I3: RW | J3: unsignedInt | K3: / | L3: TR系列规范(TR098/TR181/TR196)
B4: InternetGatewayDevice.Services.FAPService.{i}.Transport.SCTP.RTOMin | C4: Device.Services.FAPService.{i}.Transport.SCTP.RTOMin | D4: RTOMin | E4: 重传超时的最小值 | F4: A | I4: RW | J4: unsignedInt | K4: / | L4: TR系列规范(TR098/TR181/TR196)
B5: InternetGatewayDevice.Services.FAPService.{i}.Transport.SCTP.RTOMax | C5: Device.Services.FAPService.{i}.Transport.SCTP.RTOMax | D5: RTOMax | E5: 重传超时的最大值 | F5: A | I5: RW | J5: unsignedInt | K5: / | L5: TR系列规范(TR098/TR181/TR196)
B6: InternetGatewayDevice.Services.FAPService.{i}.Transport.SCTP.MaxInitRetransmits | C6: Device.Services.FAPService.{i}.Transport.SCTP.MaxInitRetransmits | D6: MaxInitRetransmits | E6: 最大初始重传数 | F6: A | I6: RW | J6: unsignedInt | K6: / | L6: TR系列规范(TR098/TR181/TR196)
B7: InternetGatewayDevice.Services.FAPService.{i}.Transport.SCTP.HBInterval | C7: Device.Services.FAPService.{i}.Transport.SCTP.HBInterval | D7: HBInterval | E7: 心跳时间间隔 | F7: A | I7: RW | J7: unsignedInt[1:] | K7: / | L7: TR系列规范(TR098/TR181/TR196)
B8: InternetGatewayDevice.Services.FAPService.{i}.Transport.SCTP.MaxPathRetransmits | C8: Device.Services.FAPService.{i}.Transport.SCTP.MaxPathRetransmits | D8: MaxPathRetransmits | E8: 最大重传次数 | F8: A | I8: RW | J8: unsignedInt | K8: / | L8: TR系列规范(TR098/TR181/TR196)
B9: InternetGatewayDevice.Services.FAPService.{i}.Transport.SCTP.MaxAssociationRetransmits | C9: Device.Services.FAPService.{i}.Transport.SCTP.MaxAssociationRetransmits | D9: MaxAssociationRetransmits | E9: 本端的最大连续重传数目 | F9: A | I9: RW | J9: unsignedInt | K9: / | L9: TR系列规范(TR098/TR181/TR196)
B10: InternetGatewayDevice.Services.FAPService.{i}.Transport.SCTP.ValCookieLife | C10: Device.Services.FAPService.{i}.Transport.SCTP.ValCookieLife | D10: ValCookieLife | E10: 有效cookie的生命周期 | F10: A | I10: RW | J10: unsignedInt | K10: / | L10: TR系列规范(TR098/TR181/TR196)
B11: InternetGatewayDevice.Services.FAPService.{i}.Transport.SCTP.Assoc.{i}.SCTPAssocLocalAddr | C11: Device.Services.FAPService.{i}.Transport.SCTP.Assoc.{i}.SCTPAssocLocalAddr | D11: SCTPAssocLocalAddr | E11: 本端IP地址 | F11: A | H11: SCTPAssocLocalAddr | I11: R | J11: string(64) | K11: / | L11: NRM配置要求 | M11: 北向对应关系重新匹配
B12: InternetGatewayDevice.Services.FAPService.{i}.Transport.SCTP.Assoc.{i}.LocalPort | C12: Device.Services.FAPService.{i}.Transport.SCTP.Assoc.{i}.LocalPort | D12: LocalPort | E12: 本端端口 | F12: A | H12: SCTPAssocLocalAddr | I12: R | J12: unsignedInt | K12: /
B13: InternetGatewayDevice.Services.FAPService.{i}.Transport.SCTP.Assoc.{i}.PrimaryPeerAddress | C13: Device.Services.FAPService.{i}.Transport.SCTP.Assoc.{i}.PrimaryPeerAddress | D13: PrimaryPeerAddress | E13: 远端IP地址 | F13: A | G13: AP | H13: SCTPAssocRemoteAddr | I13: R | J13: string(64) | K13: /
B14: InternetGatewayDevice.Services.FAPService.{i}.Transport.SCTP.Assoc.{i}.RemotePort | C14: Device.Services.FAPService.{i}.Transport.SCTP.Assoc.{i}.RemotePort | D14: RemotePort | E14: 远端端口 | F14: A | H14: SCTPAssocRemoteAddr | I14: R | J14: unsignedInt | K14: /

Sheet SH
A1: 类型 | B1: 网管数据模型(TR098) | C1: 网管数据模型(TR181) | D1: 参数名称 | E1: 中文名 | F1: 重要性 | G1: 北向Index | H1: 北向NRM参数映射 | I1: 网管读写权限 | J1: 类型 | K1: 描述 | L1: 来源 | M1: 修改说明
A2: 物理层参数管理 | B2: InternetGatewayDevice.Services.FAPService.{i}.CellConfig.LTE.RAN.PHY.MBSFN.NeighCellConfig | C2: Device.Services.FAPService.{i}.CellConfig.LTE.RAN.PHY.MBSFN.NeighCellConfig | D2: NeighCellConfig | E2: 邻区配置 | F2: CA | G2: AJ、AV | H2: / | I2: RW | J2: unsignedInt[0:3] | K2: 提供邻小区的MBSFN和TDDUL/DL配置信息。 0：不是所有的小区与服务小区有相同的MBSFN子帧分配； 1：所有邻小区没有MBSFN子帧； 2：所有邻小区的MBSFN子帧分配与服务小区相同或者是服务小区的自己； 3：对于TDD，邻小区的UL/DL分配与服务小区的不同。 | L2: TR系列规范(TR098/TR181/TR196)
B3: InternetGatewayDevice.Services.FAPService.{i}.CellConfig.LTE.RAN.PHY.MBSFN.SFConfigList.{i}.RadioframeAllocationOffset | C3: Device.Services.FAPService.{i}.CellConfig.LTE.RAN.PHY.MBSFN.SFConfigList.{i}.RadioframeAllocationOffset | D3: RadioframeAllocationOffset | E3: 无线帧分配偏置 | F3: CA | H3: / | I3: RW | J3: unsignedInt[0:6] | K3: radioFrameAllocationPeriod=radioFrameAllocationOffset时，生成包含MBSFN子帧的无线帧。当radioFrameAllocationSize等于4时，等式定义分配的前四个帧。n1 对应1，n2对应2等。当 radioFrameAllocationSize等于4 时，值n1,n2不再适用 | L3: TR系列规范(TR098/TR181/TR196)/NRM数据配置要求 | M3: 北向对应关系重新匹配
B4: InternetGatewayDevice.Services.FAPService.{i}.CellConfig.LTE.RAN.PHY.MBSFN.SFConfigList.{i}.RadioFrameAllocationPeriod | C4: Device.Services.FAPService.{i}.CellConfig.LTE.RAN.PHY.MBSFN.SFConfigList.{i}.RadioFrameAllocationPeriod | D4: RadioFrameAllocationPeriod | E4: 无线帧分配周期 | F4: CA | H4: / | I4: RW | J4: unsignedInt[0:8] | K4: radioFrameAllocationPeriod=radioFrameAllocationOffset时，生成包含MBSFN子帧的无线帧。n1代表1，n2代表2 | L4: TR系列规范(TR098/TR181/TR196)/NRM数据配置要求 | M4: 北向对应关系重新匹配
B5: InternetGatewayDevice.Services.FAPService.{i}.CellConfig.LTE.RAN.PHY.MBSFN.SFConfigList.{i}.RadioFrameAllocationSize | C5: Device.Services.FAPService.{i}.CellConfig.LTE.RAN.PHY.MBSFN.SFConfigList.{i}.RadioFrameAllocationSize | D5: RadioFrameAllocationSize | E5: MBSFN连续无线帧数 | F5: CA | H5: / | I5: RW | J5: unsignedInt[1,4] | K5: 代表MBSFN分配适合的连续帧的数，rf1对应1，rf4对应4， 取值范围：1,4 1代表rf1,4代表rf4 | L5: TR系列规范(TR098/TR181/TR196)
B6: InternetGatewayDevice.Services.FAPService.{i}.CellConfig.LTE.RAN.PHY.MBSFN.SFConfigList.{i}.SubFrameAllocations | C6: Device.Services.FAPService.{i}.CellConfig.LTE.RAN.PHY.MBSFN.SFConfigList.{i}.SubFrameAllocations | D6: SubFrameAllocations | E6: MBSFN子帧分配样式 | F6: CA | H6: / | I6: RW | J6: string(64) | K6: 分配的子帧数，如果radioFrameAllocationSize为1，有效位为低6位，如果radioFrameAllocationSize为4，有效位为低24位 | L6: TR系列规范(TR098/TR181/TR196)
B7: InternetGatewayDevice.Services.FAPService.{i}.CellConfig.LTE.RAN.PHY.MBSFN.SFConfigList.{i}.SyncStratumID | C7: Device.Services.FAPService.{i}.CellConfig.LTE.RAN.PHY.MBSFN.SFConfigList.{i}.SyncStratumID | D7: SyncStratumID | E7: 空口同步等级 | F7: CA | H7: / | I7: RW | J7: unsignedInt[1:8] | K7: 定义MBSFN配置适用的同步层级别 | L7: TR系列规范(TR098/TR181/TR196)
B8: InternetGatewayDevice.Services.FAPService.{i}.CellConfig.LTE.RAN.PHY.PRACH.ConfigurationIndex | C8: Device.Services.FAPService.{i}.CellConfig.LTE.RAN.PHY.PRACH.ConfigurationIndex | D8: ConfigurationIndex | E8: PRACH配置索引 | F8: A | H8: / | I8: RW | J8: string(256) | K8: PRACH配置资源索引，由该值可确定系统所用的前导码格式及PRACH资源的时域位置 | L8: TR系列规范(TR098/TR181/TR196) | M8: 修正参数类型
B9: InternetGatewayDevice.Services.FAPService.{i}.CellConfig.LTE.RAN.PHY.PRACH.FreqOffset | C9: Device.Services.FAPService.{i}.CellConfig.LTE.RAN.PHY.PRACH.FreqOffset | D9: FreqOffset | E9: PRACH频率偏移 | F9: A | H9: / | I9: RW | J9: string(256) | K9: 第一个PRACH可用的物理资源块，表示为一个物理资源块序号。该参数仅对前导格式0~3有效 | L9: TR系列规范(TR098/TR181/TR196)
B10: InternetGatewayDevice.Services.FAPService.{i}.CellConfig.LTE.RAN.PHY.PRACH.HighSpeedFlag | C10: Device.Services.FAPService.{i}.CellConfig.LTE.RAN.PHY.PRACH.HighSpeedFlag | D10: HighSpeedFlag | E10: 高速状态标识 | F10: A | H10: / | I10: RW | J10: boolean | K10: 决定使用不受限制的前导码集(FALSE)还是受限制的前导码集(TRUE) | L10: TR系列规范(TR098/TR181/TR196)
B11: InternetGatewayDevice.Services.FAPService.{i}.CellConfig.LTE.RAN.PHY.PRACH.RootSequenceIndex | C11: Device.Services.FAPService.{i}.CellConfig.LTE.RAN.PHY.PRACH.RootSequenceIndex | D11: RootSequenceIndex | E11: 逻辑根序列索引 | F11: A | H11: RootSequenceIndex | I11: RW | J11: string(512) | K11: 决定小区中可用的64个物理RACH前导码序列 | L11: TR系列规范(TR098/TR181/TR196)/NRM数据配置要求 | M11: 修正参数类型
B12: InternetGatewayDevice.Services.FAPService.{i}.CellConfig.LTE.RAN.PHY.PRACH.ZeroCorrelationZoneConfig | C12: Device.Services.FAPService.{i}.CellConfig.LTE.RAN.PHY.PRACH.ZeroCorrelationZoneConfig | D12: ZeroCorrelationZoneConfig | E12: 零相关配置 | F12: A | H12: / | I12: RW | J12: string(64) | K12: 该参数用在前导码序列生成中 | L12: TR系列规范(TR098/TR181/TR196)
B13: InternetGatewayDevice.Services.FAPService.{i}.CellConfig.LTE.RAN.PHY.SRS.SRSEnabled | C13: Device.Services.FAPService.{i}.CellConfig.LTE.RAN.PHY.SRS.SRSEnabled | D13: SRSEnabled | E13: SRS使能开关 | F13: A | H13: / | I13: RW | J13: Boolean | K13: SRS使能开关 1=true,0=false | L13: TR系列规范(TR098/TR181/TR196) | M13: 修正笔误 修改参数名为SRSEnabled，与TR196对齐
B14: InternetGatewayDevice.Services.FAPService.{i}.CellConfig.LTE.RAN.PHY.SRS.SRSBandwidthConfig | C14: Device.Services.FAPService.{i}.CellConfig.LTE.RAN.PHY.SRS.SRSBandwidthConfig | D14: SRSBandwidthConfig | E14: SRS带宽配置 | F14: A | H14: / | I14: RW | J14: string(32) | K14: 代表包含小区SRSBandwidthConfiguration的表格的索引 | L14: TR系列规范(TR098/TR181/TR196) | M14: 修改参数名大小写，与TR196保持一致
B15: InternetGatewayDevice.Services.FAPService.{i}.CellConfig.LTE.RAN.PHY.SRS.SRSMaxUpPTS | C15: Device.Services.FAPService.{i}.CellConfig.LTE.RAN.PHY.SRS.SRSMaxUpPTS | D15: SRSMaxUpPTS | E15: SRSUpPTS带宽重配指示 | F15: A | H15: / | I15: RW | J15: Boolean | K15: 重配置SRS是否适用于UpPTS;1=true,0=false | L15: TR系列规范(TR098/TR181/TR196) | M15: 修改参数名大小写，与TR196保持一致
B16: InternetGatewayDevice.Services.FAPService.{i}.CellConfig.LTE.RAN.PHY.SRS.AckNackSRSSimultaneousTransmission | C16: Device.Services.FAPService.{i}.CellConfig.LTE.RAN.PHY.SRS.AckNackSRSSimultaneousTransmission | D16: AckNackSRSSimultaneousTransmission | E16: SRS/ACK/NACK同时传输标识 | F16: A | H16: / | I16: RW | J16: Boolean | K16: 定义UE能否同时传输SRS和ACK/NACK (0=可以同时传输,1=不能同属传输) | L16: TR系列规范(TR098/TR181/TR196)
B17: InternetGatewayDevice.Services.FAPService.{i}.CellConfig.LTE.RAN.PHY.PUCCH.DeltaPUCCHShift | C17: Device.Services.FAPService.{i}.CellConfig.LTE.RAN.PHY.PUCCH.DeltaPUCCHShift | D17: DeltaPUCCHShift | E17: PUCCH循环移位间隔 | F17: A | H17: / | I17: RW | J17: string | K17: 代表PUCCHformat1/1a/1b资源的循环位移 | L17: TR系列规范(TR098/TR181/TR196) | M17: 修正参数类型
B18: InternetGatewayDevice.Services.FAPService.{i}.CellConfig.LTE.RAN.PHY.PUCCH.NRBCQI | C18: Device.Services.FAPService.{i}.CellConfig.LTE.RAN.PHY.PUCCH.NRBCQI | D18: NRBCQI | E18: PUCCH2/2a/2b占用RB数 | F18: A | H18: / | I18: RW | J18: string | K18: 即N2RB参数，代表PUCCH域中预留用于传输CQI的PUCCH域个数 | L18: TR系列规范(TR098/TR181/TR196)
B19: InternetGatewayDevice.Services.FAPService.{i}.CellConfig.LTE.RAN.PHY.PUCCH.NCSAN | C19: Device.Services.FAPService.{i}.CellConfig.LTE.RAN.PHY.PUCCH.NCSAN | D19: NCSAN | E19: PUCCH1/1a/1b预留资源数 | F19: A | H19: / | I19: RW | J19: unsignedInt[0:7] | K19: 即N(1)cs参数，在混合使用1/1a/1b和2/2a/2b格式的资源块中，代表预留给PUCCH1/1a/1b格式的循环位移 | L19: TR系列规范(TR098/TR181/TR196) | M19: 修正参数类型
B20: InternetGatewayDevice.Services.FAPService.{i}.CellConfig.LTE.RAN.PHY.PUCCH.N1PUCCHAN | C20: Device.Services.FAPService.{i}.CellConfig.LTE.RAN.PHY.PUCCH.N1PUCCHAN | D20: N1PUCCHAN | E20: SPSACK/NACK及SR预留资源数 | F20: A | H20: / | I20: RW | J20: string(512) | K20: 即N(1)PUCCH参数，表示预留给半持续调度（SPS）的ACK/NACK和SR请求的PUCCHformat1静态资源数 | L20: TR系列规范(TR098/TR181/TR196) | M20: 修正参数类型
B21: InternetGatewayDevice.Services.FAPService.{i}.CellConfig.LTE.RAN.PHY.PUCCH.CQIPUCCHResourceIndex | C21: Device.Services.FAPService.{i}.CellConfig.LTE.RAN.PHY.PUCCH.CQIPUCCHResourceIndex | D21: CQIPUCCHResourceIndex | E21: CQI报告使用PUCCH资源索引 | F21: A | H21: / | I21: RW | J21: string(512) | K21: 为UE分配的用于CQI上报的PUCCHformat2资源索引 | L21: TR系列规范(TR098/TR181/TR196)
B22: InternetGatewayDevice.Services.FAPService.{i}.CellConfig.LTE.RAN.PHY.PUCCH.K | C22: Device.Services.FAPService.{i}.CellConfig.LTE.RAN.PHY.PUCCH.K | D22: K | E22: 子带CQI报告带宽 | F22: A | H22: / | I22: RW | J22: unsignedInt[1:4] | K22: 子波段报告模式中的子波段大小， 以物理资源块为单位 | L22: TR系列规范(TR098/TR181/TR196)
B23: InternetGatewayDevice.Services.FAPService.{i}.CellConfig.LTE.RAN.PHY.PaParam.PUSCHPowerCtrlSwitch | C23: Device.Services.FAPService.{i}.CellConfig.LTE.RAN.PHY.PaParam.PUSCHPowerCtrlSwitch | D23: PUSCHPowerCtrlSwitch | E23: 上行PUSCH闭环功控开关 | F23: A | H23: PuschPcSwitch | I23: RW | J23: unsignedInt[0:1] | K23: ON=1,OFF=0 | L23: NRM数据配置要求
B24: InternetGatewayDevice.Services.FAPService.{i}.CellConfig.LTE.RAN.PHY.PaParam.PUCCHPowerCtrlSwitch | C24: Device.Services.FAPService.{i}.CellConfig.LTE.RAN.PHY.PaParam.PUCCHPowerCtrlSwitch | D24: PUCCHPowerCtrlSwitch | E24: 上行PUCCH闭环功控开关 | F24: A | H24: PucchPcSwitch | I24: RW | J24: unsignedInt[0:1] | K24: ON=1,OFF=0 | L24: NRM数据配置要求 | M24: 增加PUCCHPcSwitch参数适配北向参数
B25: InternetGatewayDevice.Services.FAPService.{i}.CellConfig.LTE.RAN.PHY.PUSCH.Enable64QAM | C25: Device.Services.FAPService.{i}.CellConfig.LTE.RAN.PHY.PUSCH.Enable64QAM | D25: Enable64QAM | E25: PUSCH64QAM使能开关 | F25: A | H25: / | I25: RW | J25: Boolean | K25: TRUE代表允许64QAM，FALSE代表不允许64QAM; 64QAM,1=64QAM | L25: TR系列规范(TR098/TR181/TR196)
B26: InternetGatewayDevice.Services.FAPService.{i}.CellConfig.LTE.RAN.PHY.PUSCH.HoppingMode | C26: Device.Services.FAPService.{i}.CellConfig.LTE.RAN.PHY.PUSCH.HoppingMode | D26: HoppingMode | E26: PUSCH跳频模式 | F26: A | H26: / | I26: RW | J26: string | K26: 决定跳跃是“子帧间跳跃”还是“子帧间与子帧内跳跃” | L26: TR系列规范(TR098/TR181/TR196)
B27: InternetGatewayDevice.Services.FAPService.{i}.CellConfig.LTE.RAN.PHY.PUSCH.HoppingOffset | C27: Device.Services.FAPService.{i}.CellConfig.LTE.RAN.PHY.PUSCH.HoppingOffset | D27: HoppingOffset | E27: PUSCH跳频偏置 | F27: A | H27: / | I27: RW | J27: string(256) | K27: 如果上行链路频率跳跃模式启用，该参数用来计算需要用来在PUSCH传输的物理资源块 | L27: TR系列规范(TR098/TR181/TR196)
B28: InternetGatewayDevice.Services.FAPService.{i}.CellConfig.LTE.RAN.PHY.PUSCH.NSB | C28: Device.Services.FAPService.{i}.CellConfig.LTE.RAN.PHY.PUSCH.NSB | D28: NSB | E28: 跳频子带个数 | F28: A | H28: / | I28: RW | J28: unsignedInt[1:4] | K28: 代表次频带的数目 | L28: TR系列规范(TR098/TR181/TR196)
