Workbook
Name _Toc375818453: SA!#REF!
Name _Toc375818454: SA!#REF!
Name _Toc375818456: SA!#REF!

Sheet 设备参数数据表
A1: 分类 | B1: 节点 | C1: 英文名称 | D1: 中文名称 | E1: 取值范围 | F1: 默认值 | G1: 类型 | H1: OAM读写权限 | I1: 网管读写权限 | J1: 前置条件 | K1: 后置影响 | L1: 注意事项 | M1: 规范/厂家定义
A2: OAM/专业/系统 | B2: 专业 | E2: （包括单位） | H2: 专业写 | I2: OAM/系统写 | J2: 专业/算法/系统 | K2: 专业/算法/系统 | L2: 填写参数的功能描述和特殊注意事项
B3: 网管信息参数表 | C3: IuhIpAddr | D3: AU板iuh口IP | G3: String(20) | I3: RW | L3: AU板iuh口IP，IP协议层所使用的IP。
B4: 网管信息参数表 | C4: IuhPort | D4: AU板iuh口port | G4: unsignedInt | I4: RW | L4: AU板iuh口port。
A5: 不在网管上显示 | B5: 网管信息参数表 | C5: SrcIpAddr | D5: AU板上层源ip | G5: String | L5: AU板上层源ip。未有用到。
A6: 不在网管上显示 | B6: 网管信息参数表 | C6: SrcPort | D6: AU板上层源port | G6: unsignedInt | L6: AU板上层源port，未有用到。
B7: 网管信息参数表 | C7: FapAddr1 | D7: GU网关ip | G7: String(20) | I7: RW | L7: GU网关ip 一
B8: 网管信息参数表 | C8: FapAddr2 | D8: GU网关ip | G8: String(20) | I8: RW | L8: GU网关ip 二（未有用到）
A9: 不在网管上显示 | B9: 网管信息参数表 | C9: FapAddr3 | D9: GU网关ip | G9: String | L9: GU网关ip 三（未有用到）
B10: 网管信息参数表 | C10: SecIpAddr1 | D10: 安全网关ip1 | G10: String(20) | I10: RW | L10: 安全网关ip一。
B11: 网管信息参数表 | C11: SecIpAddr2 | D11: 安全网关ip2 | G11: String(20) | I11: RW | L11: 安全网关ip二（未有用到）
A12: 不在网管上显示 | B12: 网管信息参数表 | C12: SecIpAddr3 | D12: 安全网关ip3 | G12: String | L12: 安全网关ip三（未有用到）
B13: 网管信息参数表 | C13: Seckey | D13: 安全网关建立密钥 | G13: String(64) | I13: R | L13: 安全网关建立密钥
B14: 网管信息参数表 | C14: SecUseImsi | D14: 建立安全网关imsi | G14: String(16) | I14: R | L14: 建立安全网关imsi
B15: 网管信息参数表 | C15: FapPort | D15: GU网关port | E15: 0~4294967295 | F15: 29169 | G15: unsignedInt | I15: RW | L15: GU网关port。
B16: 网管信息参数表 | C16: IpSecStartAllowedInd | D16: IPSec是否启动开关 | E16: true、false | F16: true | G16: boolean | I16: RW | L16: IpSec开关。 取值false：关闭Ipsec功能 取值true：打开Ipsec功能
B17: 网管信息参数表 | C17: IpSecRekeyTime | D17: ipSec rekey时间 | E17: 0~4294967295(分钟） | F17: 80000 | G17: unsignedInt | I17: RW | L17: IpSec重协商时间。单位：分钟
B18: 网管信息参数表 | C18: IpSecSaLifetime | D18: IPSec SA的生命周期 | E18: 0~4294967295（秒） | F18: 30 | G18: unsignedInt | I18: RW | L18: IPSec SA的生命周期。单位：秒
B19: 网管信息参数表 | C19: IpSecLivenessTimeInterval | D19: liveness时间间隔 | G19: unsignedInt | I19: RW | L19: liveness时间间隔。
A20: 不在网管上显示 | B20: 网管信息参数表 | C20: FapPcSocketIpAddr | D20: 调试日志放置设备IP | G20: String | L20: 调试日志放置设备IP（调试电脑）
A21: 不在网管上显示 | B21: 网管信息参数表 | C21: FapPcSocketPort | D21: 调试日志放置设备端口 | G21: unsignedInt | L21: 调试日志放置设备端口（调试电脑）
B22: 网管信息参数表 | C22: RealIpAddrToPing | D22: 用于ping功能的真实站点IpAddr | G22: String | I22: R | L22: 用于ping功能的真实站点IpAddr
B23: 网管信息参数表 | C23: GateWaySupported | D23: 指示当前所要连接的网关能力 | G23: unsignedInt | I23: RW | L23: 用于指示当前所要连接的网关能力 取值0：网关支持E1+Surf 取值1：网关支持STM-1+ATCA9100 取值2：网关支持AoIP
B24: 网管信息参数表 | C24: Mode | D24: 认证模式 | E24: 0~2 | G24: int | I24: RW | L24: mode为0,为PSK认证，mode为1为usim卡认证，mode为2为sim卡证（预留），-1为非法值，mode为其它值暂时保留
B25: 公共参数表 | C25: AuId | D25: AU注册是使用的基站Id | E25: 0~65535 | G25: unsignedInt | I25: RW | L25: AU注册是使用的基站Id。 取值范围：0~65535
B26: 公共参数表 | C26: A50 | D26: 是否支持A5_0类型加密 | E26: true、false | F26: true | G26: boolean | I26: RW | L26: 物理层是否支持A5_0类型加密。 取值false：不支持 取值true：支持
B27: 公共参数表 | C27: A51 | D27: 是否支持A5_1类型加密 | E27: true、false | F27: true | G27: boolean | I27: RW | L27: 物理层是否支持A5_1类型加密。 取值false：不支持 取值true：支持
B28: 公共参数表 | C28: A52 | D28: 是否支持A5_2类型加密 | E28: true、false | F28: true | G28: boolean | I28: RW | L28: 物理层是否支持A5_2类型加密。 取值false：不支持 取值true：支持
B29: 公共参数表 | C29: A53 | D29: 是否支持A5_3类型加密 | E29: true、false | F29: true | G29: boolean | I29: RW | L29: 物理层是否支持A5_3类型加密。 取值false：不支持 取值true：支持
B30: 公共参数表 | C30: A54 | D30: 是否支持A5_4类型加密 | E30: true、false | F30: false | G30: boolean | I30: RW | L30: 物理层是否支持A5_4类型加密。 取值false：不支持 取值true：支持
B31: 公共参数表 | C31: A55 | D31: 是否支持A5_5类型加密 | E31: true、false | F31: false | G31: boolean | I31: RW | L31: 物理层是否支持A5_5类型加密。 取值false：不支持 取值true：支持
B32: 公共参数表 | C32: A56 | D32: 是否支持A5_6类型加密 | E32: true、false | F32: false | G32: boolean | I32: RW | L32: 物理层是否支持A5_6类型加密。 取值false：不支持 取值true：支持
B33: 公共参数表 | C33: A57 | D33: 是否支持A5_7类型加密 | E33: true、false | F33: false | G33: boolean | I33: RW | L33: 物理层是否支持A5_7类型加密。 取值false：不支持 取值true：支持
A34: 不在网管上显示 | B34: 公共参数表 | C34: AuUserAccessMax | D34: 户型允许接入的用户数上限 | G34: unsignedInt | L34: 根据户型允许接入的用户数上限。 该参数上层暂时未有使用，保留。
A35: 不在网管上显示 | B35: 公共参数表 | C35: AuAlowPwrMax | D35: 户型允许最大发射功率 | G35: unsignedInt | L35: 根据户型允许最大发射功率 该参数上层暂时未有使用，保留。
B36: 公共参数表 | C36: LogTotalSize | D36: 单个日志文件大小 | E36: 0~4294967295(KByte) | F36: 3*1024 | G36: unsignedInt | I36: RW | L36: 日志文件的总大小，以1k Byte为单位
A37: 不在网管上显示 | B37: 公共参数表 | C37: LogTxtNumberMax | D37: 同类型日志文件存储最大文件个数 | G37: unsignedInt | L37: 同类型日志文件存储最大文件个数。 该参数上层暂时未有使用，保留。
B38: 公共参数表 | C38: LogOutputLevel | D38: 日志输出类型 | E38: 0~4 | F38: 1 | G38: unsignedInt | I38: RW | L38: 日志输出级别。 取值范围：0~4 取值0：DEBUG 取值1：INFO 取值2：TRACE 取值3：WARN 取值4：ERROR
A39: 不在网管上显示 | B39: 公共参数表 | C39: AuProductType | D39: Au产品类型 | L39: Au产品类型,取值范围：0~3 取值0：普通型原型机产品 取值1：企业级大容量产品 取值2：企业级eNB 3+1产品 取值3：普通型降成本产品
A40: 不在网管上显示 | B40: 公共参数表 | C40: AuRfWorkBandCapability | D40: 基站射频支持的工作频段能力 | E40: 0~3 | F40: 0 | G40: unsignedInt | L40: 基站射频支持的工作频段能力，取值范围：0~3 取值0：基站支持1800工作频段 取值1：基站支持900工作频段 取值2：基站支持900E工作频段 取值3：基站支持1900工作频段
...

Sheet 修订历史
C2: 中国移动5G扩展型皮基站网管南向接口数据模型规范
A4: 版本 | B4: 日期 | C4: 修订内容 | D4: 修订人
A5: v1.0.0 | B5: 43453 | C5: 创建初稿 | D5: 苏翰、张欢、赫祎诺
A6: v1.1.0.1 | B6: 2020-9-25--2020-11--05 | C6: 修订： SA 页： 1.设备信息参数管理，会议讨论决定Device.DeviceInfo.后增加 MU.{i}.表示机框； 2.设备信息参数管理，会议讨论决定Device.DeviceInfo.后增加 MU.{i}.Slot.{i}.表示槽位板卡； 3.设备信息参数管理，会议讨论决定定义Device.DeviceInfo.MU.{i}.Slot.{i}.EU.{i}.表示 EU，并将SR页 EU设备级 参数融合到该对象中； 4.设备信息参数管理，会议讨论决定定义Device.DeviceInfo.MU.{i}.Slot.{i}.EU.{i}.RU.{i}.表示 RU，并将SR页 RU设备级 参数融合到该对象中； 5.按照机框板卡定义参数 SB 页： 1.增加系统当前版本说明，指gNB整体大版本，MU、EU、RU各自版本号在SA页的软件版本中查询 2.激活备份版本由A改为CB SH 页： 1. 删除小区最大发射功率 ST 页： 1. 扩展型一体化皮站-主单元（MU）参数管理，Device.Services.FAPService.{i}.FAPControl.LTE.SourcedSignalEnable和 Device.Services.FAPService.{i}.FAPControl.LTE.SourcedSignalEnable参数，经会议讨论，京信、锐捷、赛特斯、H3C厂商并没有该参数，建议移除 2. 扩展型一体化皮站-扩展单元（EU）参数管理，经会议讨论EU的参数除Device.DeviceInfo.EU.{i}.Reboot外融合到 SA页设备管理参数中 3. 扩展型一体化皮站-远端单元（RU）参数管理，经会议讨论除Device.DeviceInfo.EU.{i}.RU.{i}.Reboot、Device.DeviceInfo.EU.{i}.RU.{i}.MaxTxPower、Device.DeviceInfo.EU.{i}.RU.{i}.RFTxStatus及 Device.DeviceInfo.EU.{i}.RU.{i}.LTECell.{i}.ECI外，其他参数融合到 SA页 4.修订RW类可配置参数的路径，由Device.DeviceInfo.改为Device.Services.FAPService.{i}.FAPControl. 5.增加本地分流规则模型 v1.1.0.3SF 页： 1.修订Device.Services.FAPService.{i}.CellConfig.NR.5GC.PLMNList{i}.为Device.Services.FAPService.{i}.CellConfig.NR.5GC.PLMNList 2.修订Xn接口，增加NR.级别 3.修订AMF地址，由Cellconfig改为FAPControl 4.Device.Services.FAPService.{i}.Capabilities.MaxTxPower修改为Device.Services.FAPService.{i}.CellConfig.NR.MaxTxPower SE 页： 1.增加日志告警级别 SN 页： 1.增加Interface名称Name 2.修改“外部IP地址”为“IP地址” 3.将Device.IP.Interface.{i}.修改为Device.Ethernet.Interface.{i} SF 页： 1.新加SF页，定义基站级管理参数 SG 页： 1.新加SG页，定义基站级能力参数 ST页： 1.新增软采配置 SK页： 1.修订RNAU周期由Enumerate改为UnsignInt | D6: 苏翰，马键，李响，杨文英
A7: V1.1.1 | B7: 44151 | C7: 形成V1.1.1版本 | D7: 苏瀚，马键，贾辉，李响
A8: V1.1.1.0 | B8: 44162 | C8: 1.目录页修订SL、SM页路径增加多实例{i}.和NR. 2.SA页增加RU的状态信息Device.DeviceInfo.MU.{i}.Slot.{i}.EU.{i}.RU.{i}.Status 3.多实例页增加本地分流节点 | D8: 李响
A9: V1.1.1.0 | B9: 44168 | C9: SF页： 1.Device.Services.FAPService.{i}.FAPControl.NR.AdminState，修订备注，删除“射频"，指对小基站的整体使能开关，当"关闭"时，小基站基带、射频都处于关闭状态 2.Device.Services.FAPService.{i}.FAPControl.NR.AdminState修订为Device.Services.FAPService.{i}.FAPControl.NR.CellEnable.{i}.AdminState，指对每个小区的开关操作 3.Device.Services.FAPService.{i}.FAPControl.NR.OpState取值由“禁止/开启"修改为“可用/不可用” 4.Device.Services.FAPService.{i}.FAPControl.NR.OpState指所有小区都不能提供服务的场景，该值为“不可用” SM页： 1.修订Device.Services.FAPService.{i}.CellConfig.{i}.LTE.RAN.Mobility.IdleMode.InterFreq.Carrier.{i}.ThreshXLowP为Device.Services.FAPService.{i}.CellConfig.{i}.NR.RAN.Mobility.IdleMode.InterFreq.Carrier.{i}.ThreshXLowP SJ页： 1.Device.Services.FAPService.{i}.CellConfig.{i}.SysInfoCtrlParam.MultiBandInfoListSIB1修改为Device.Services.FAPService.{i}.CellConfig.{i}.NR.RAN.SysInfoCtrlParam.MultiBandInfoListSIB1 2.Device.Services.FAPService.{i}.CellConfig.{i}.SysInfoCtrlParam.MultiBandInfoListSIB5修订为Device.Services.FAPService.{i}.CellConfig.{i}.NR.RAN.SysInfoCtrlParam.MultiBandInfoListSIB5 | D9: 李响
A10: V1.1.1.1 | B10: 44175 | C10: SF页： 删除Device.Services.FAPService.{i}.FAPControl.NR.CellEnable.{i}.AdminState SJ页： 增加Device.Services.FAPService.{i}.CellConfig.{i}.NR.RAN.CellEnable.AdminState | D10: 李响
A11: V1.1.1.2 | B11: 44182 | C11: SA页： 增加MU reboot SK页： 17&23：Device.Services.FAPService.{i}.CellConfig.{i}.NR.RAN.PHY.TddULDLConfigurationCommon.pattern1.DlULTransmissionPeriodicity删除空格 | D11: 李响
A12: V1.1.1.3 | B12: 44194 | C12: SK页： 1.Device.Services.FAPService.{i}.CellConfig.{i}.NR.RAN.PHY.PDCCH.CommonControlResourceSet.CceRegMappingType.RegBundleSize，大写CommonControlResourceSet SF页： 1.AmfPoolConfigParam.{i}修改为AMFPoolConfigParam.{i}，子节点由AMF改为Amf 2.增加GUAMI.{i}.到AmfRegionID&AmfSetID&AmfPointer，并将此三个参数修改为只读 SK页： 1.RACH-ConfigGeneric修改为RACHConfigGeneric SH页： 1.Rulelist修改为RuleList 其他： 1.取值范围增加“无效值” SJ页： 1.删除Device.Services.FAPService.{i}.CellConfig.{i}.NR.5GC.TAC 2.删除Device.Services.FAPService.{i}.CellConfig.{i}.NR.5GC.PLMNList.{i}.PLMNID | D12: 李响
A13: V1.1.1.4 | B13: 44200 | C13: SI页： 删除Capability相关参数 SJ页： 将Capability补充道Cell级别 NR.RAN.CellEnable.AdminState修改为小区管理状态 SA页： 增加Device.DeviceInfo.MU.{i}.Slot.{i}.DataModelSpecVersion SH页： 增加Device.Services.FAPService.{i}.FAPControl.LocalBreakout.IpRules.RuleList.{i}.MeasurementPeriod 增加Device.Services.FAPService.{i}.FAPControl.LocalBreakout.IpRules.RuleList.{i}.Thoughput ST页： 增加Device.FAP.SCMgmt.Config.{i}.SCIPAddress 增加Device.FAP.SCMgmt.Config.{i}.SCPort 增加Device.FAP.SCMgmt.Config.{i}.SCLoginID | D13: 李响
A14: V1.1.1.5 | B14: 44203 | C14: SJ页： Device.Services.FAPService.{i}.CellConfig.{i}.NR.RAN.CellRestriction.CellBarred修订类型（0：解闭塞，1闭塞） SA页： 增加Device.DeviceInfo.MU.{i}.Slot.{i}.EU.{i}.SwUpgrade.FailureCause说明升级失败原因 | D14: 李响
A15: V1.1.1.6 | B15: 2021-1-13，19，20，21 | C15: SA页： 增加Device.DeviceInfo.MU.{i}.Slot.{i}.EU.{i}.RU.{i}.SwUpgrade.Stage和Device.DeviceInfo.MU.{i}.Slot.{i}.EU.{i}.RU.{i}.SwUpgrade.Status备注说明 修订Device.DeviceInfo.AddEndPoint和Device.DeviceInfo.DelEndPoint描述，修订DelEndPonit为DelEndPoint 增加Device.DeviceInfo.MU.{i}.Slot.{i}.SwUpgrade.failureCause,Device.DeviceInfo.MU.{i}.Slot.{i}.EU.{i}.SwUpgrade.failureCause，Device.DeviceInfo.MU.{i}.Slot.{i}.EU.{i}.RU.{i}.SwUpgrade.FailureCause 修改Device.DeviceInfo.MU.{i}.Slot.{i}.EU.{i}.RU.{i}.RouteIndex的中文名称为“射频单元路由指示” 增加Device.DeviceInfo.MU.{i}.Slot.{i}.EU.{i}.RU.{i}.RouteIndex备注：“MU、EU和RU的端口从1开始” 增加Device.DeviceInfo.MU.{i}.Slot.{i}.EU.{i}.{i}.RouteIndex备注：“MU、EU和RU的端口从1开始” SK页： 修订RACH-ConfigGeneric为RACHConfigGeneric 修订NR.RAN.PHY.RACHConfigCommon.Msg1Subcarrier Spacing为NR.RAN.PHY.RACHConfigCommon.Msg1SubcarrierSpacing 删除OffsetToPointA、Msg3DeltaPreamble、RootType、TotalNumberOfRAPreambles、RaMsg3SizeGroupA、MessagePowerOffsetGroupB、RsrpThresholdSSB末尾空格 增加Device.Services.FAPService.{i}.CellConfig.{i}.NR.RAN.PHY.Antenna.NumOfTxAntenna和Device.Services.FAPService.{i}.CellConfig.{i}.NR.RAN.PHY.Antenna.NumOfRxAntenna SM页： 删除IntraFreqReselection、ThresholdRSRP、ThreshXHighP、ThreshXHighQ末尾空格 SS页： 删除PerfMgmt.Config.{i}.Enable、URL、Username、Password、PeriodicUploadInterval末尾空格 ST页： XnETRIEVEUECONTEXTREQUESTEnable修订为XnRETRIEVEUECONTEXTREQUESTEnable Device.FAP.SCMgmt.Config.{i}.XnDATAFORWARDINGADDRESSINDICATIONEnable改为：Device.FAP.SCMgmt.Config.{i}.XnUADDRESSINDICATIONEnable 3.将Device.FAP.SCMgmt.Config.{i}.XnE-UTRA–NRCELLRESOURCECOORDINATIONREQUESTEnable 改为Device.FAP.SCMgmt.Config.{i}.XnE-UTRA-NRCELLRESOURCECOORDINATIONREQUESTEnable（3和4是破折号采用了中文类型的破折号，应改为英文类型的） 4.将 Device.FAP.SCMgmt.Config.{i}.XnE-UTRA–NRCELLRESOURCECOORDINATIONRESPONSEEnable改为Device.FAP.SCMgmt.Config.{i}.XnE-UTRA-NRCELLRESOURCECOORDINATIONRESPONSEEnable 5.增加Device.FAP.SCMgmt.Config.{i}.SCGID只读属性 SO： 增加Ipv6，VLAN接口信息 SJ： 增加Device.Services.FAPService.{i}.CellConfig.{i}.NR.RAN.Common.gNBIdLength | D15: 李响
A16: V1.1.2 | B16: 44267 | C16: SH页： 增加IPv6参数 SO页： 增加IPv6 ST页： 修改SCAIP为string64 | D16: 李响
A17: V1.1.2 | B17: 44274 | C17: SF页： Device.Services.FAPService.{i}.FAPControl.NR.AMFPoolConfigParam.{i}.AmfName参数类型修订为string（150）； Device.Services.FAPService.{i}.FAPControl.NR.XnIpAddrMapInfo.{i}.remoteaddress修改为Device.Services.FAPService.{i}.FAPControl.NR.XnIpAddrMapInfo.{i}.RemoteAddress； Device.Services.FAPService.{i}.FAPControl.NR.XnIpAddrMapInfo.{i}.SubnetMask修改为只读属性； Device.Services.FAPService.{i}.FAPControl.NR.XnIpAddrMapInfo.{i}.localaddress修改为Device.Services.FAPService.{i}.FAPControl.NR.XnIpAddrMapInfo.{i}.LocalAddress，属性修改为只读； SH页： 修订标题为本地分流策略管理 SJ页： 增加Device.Services.FAPService.{i}.CellConfig.{i}.NR.RAN.RF.SsbFrequency Device.Services.FAPService.{i}.CellConfig.{i}.NR.RAN.RF.NRARFCNUL和Device.Services.FAPService.{i}.CellConfig.{i}.NR.RAN.RF.NRARFCNDL数据类型修订为unsignInt[1:3279165]; Device.Services.FAPService.{i}.CellConfig.{i}.NR.RAN.SysInfoCtrlParam.MultiBandInfoListSIB5修订为Device.Services.FAPService.{i}.CellConfig.{i}.NR.RAN.SysInfoCtrlParam.IdleModeRATMobile.{i}.MultiBandInfoListSIB5； Device.Services.FAPService.{i}.CellConfig.{i}.NR.Capabilities.UeInactiveTimer修改取值范围为[0:7200] | D17: 李响
A18: V1.1.2 | B18: 44284 | C18: SF页： 1.Device.Services.FAPService.{i}.FAPControl.NR.XnIpAddrMapInfo.{i}.TAC修订为TAISupportList.{i}.TAC 2.增加Device.Services.FAPService.{i}.FAPControl.NR.XnIpAddrMapInfo.{i}.BoardcastPLMNs.PLMNID 3.删除Device.Services.FAPService.{i}.FAPControl.NR.XnIpAddrMapInfo.{i}.PLMNID SK页： 1.Device.Services.FAPService.{i}.CellConfig.{i}.NR.RAN.PHY.FrequencyInfoDLSIB.OffsetToPointA修订为只读 2.删除Device.Services.FAPService.{i}.CellConfig.{i}.NR.RAN.PHY.FrequencyInfoULSIB.AbsoluteFrequencyPointA计算得到不需要配置，删除 3.删除Device.Services.FAPService.{i}.CellConfig.{i}.NR.RAN.PHY.SSB.SsPBCHBlockPower重复配置SJ 4.Device.Services.FAPService.{i}.CellConfig.{i}.NR.RAN.PHY.SSB.SsbSubcarrierOffset修改只读 5.增加BWP及对应信道参数修改 | D18: 李响
A19: V1.1.2 | B19: 44285 | C19: SJ页： 1.增加VoNRSupport SK页： 1.DlULTransmissionPeriodicity增加无效值0x0000FFFF SA页： 增加RU的底噪测量NoisePwdBm SJ页： 增加小区底噪测量NoisePwdBm | D19: 李响
A20: V1.1.2 | B20: 44294 | C20: SA页： 修订EU和RU的RouteIndex描述 SJ页： PyhicalCellId取值修订为[0:1007] 修订DLBandwidth和ULBandwidth取值为整型 修订NrCellIdentity的数值类型从unsignedInt修改为unsignedLong | D20: 李响
A21: V1.1.2 | B21: 44299 | C21: SK页: 1. 修订BWO以及对应信道参数修改，按3GPP协议调整节点顺序； | D21: 李响
A22: V1.1.2 | B22: 44308 | C22: SS页： 根据接口规范删除600 | D22: 李响
A23: V1.1.2 | B23: 44329 | C23: SO页： 增加本地路由配置 | D23: 李响
A24: V1.1.2 | B24: 44329 | C24: SA页： 1.增修改FailureCause长度为String512 2.增删Object中string(64)改为string(128) SH页： 1.删除IP五元组测量周期和吞吐量，增加流量限制规则和吞吐量统计 SJ页： 1.修订gNBIDLength为unsignedint[22:32] 2.删除gNBID、Name、Length 3.增加共享小区配置模型 SF页： 1.增加gNBID、Name、Length SK页： 1.修订BWPID由[1:5]改为[0:4] SM页： 1.InterFreq.SNonIntraSearchQ&InterFreq.SNonIntraSearchP修改为IntraFreq.SNonIntraSearchQ&IntraFreq.SNonIntraSearchP SC页： 1.UDPConnectionRequestAddress修改为只读属性 | D24: 李响
A25: V1.1.2 | B25: 44334 | C25: SG页： 增加自动开站参数模型 SA页： 删除RU MaxTxPower 增加RU下RFChannel的TxPower 修订RU.{i}.NoisePwdBm为RU.{i}.RF.{i}.NoisePwdBm 增加节能管理参数 SJ页： 增加RU和小区关联关系 增加小区最大发射功率 增加节能管理参数 增加IPv6的默认网关 SO页： 删除路由配置表的接口interface{i} SH页： 修改DNS优先级 修改流量统计规则IP、DNS、PLMN、SNSSAI为只读属性，取值根据本地分流规则自动产生 SC页： STUN改为CB类 SR页： 增加NCGI小区列表 | D25: 李响
A26: V1.1.2 | B26: 44340 | C26: SJ页： 增加节能策略 VoNR不需要List多实例，删除，增加VoNR开关 SA页： 删除RU下的节能参数 修改RU TxPower为TxGain SK页： 增加PCCH寻呼参数配置 SM页： 修改Smeasure在NR下 SG页： 增加PCI冲突混淆检测开关 | D26: 李响
A27: V1.2 | B27: 44356 | C27: MU&Slot,SerialNumber增加描述“设备序列号，以“-NR”结尾” | D27: 李响
... A32: V1.6 | B32: 44385 | C32: SD页，增加alarmLocation | D32: 李响
A33: V1.7 | B33: 44398 | C33: SD页，History增加alarmLocation

Sheet 封面
B3: TD-LTE NanoCell南向数据配置模型规范(推荐版)
B5: 概述（详细问题请查阅正文内容）：
B6: TD-LTE NanoCell南向数据配置模型规范(推荐版)
B7: 文档适应的产品 | D7: 移动 NanoCell
B10: 文档详细信息 | D10: 版本 | E10: 作者 | F10: 时间 | G10: 来源 | H10: 注释
B11: TD-LTE NanoCell网管数据模型规范(初稿) | D11: 首发 | E11: 京信团队 | F11: 42535
G15: 京信通信系统（广州）有限公司

Sheet 目录
A1: 索引 | B1: 参数管理类别 | C1: 参数管理说明 | D1: A类属性数 | E1: B类属性数 | F1: CA类属性数 | G1: CB类属性数 | H1: 小计
A2: SA | B2: DeviceInfo | C2: 设备信息参数管理 | D2: =COUNTIF(SA!$E:$E,"A") -> 83 | E2: =COUNTIF(SA!$E:$E,"B") -> 2 | F2: =COUNTIF(SA!$E:$E,"CA") -> 0 | G2: =COUNTIF(SA!$E:$E,"CB") -> 0 | H2: =SUM($D2:$G2) -> 85
A3: SB | B3: SoftwareCtrl | C3: 软件版本参数管理 | D3: =COUNTIF(SB!$E:$E,"A") -> 3 | E3: =COUNTIF(SB!$E:$E,"B") -> 0 | F3: =COUNTIF(SB!$E:$E,"CA") -> 0 | G3: =COUNTIF(SB!$E:$E,"CB") -> 2 | H3: =SUM($D3:$G3) -> 5
A4: SC | B4: ManagementServer | C4: 基站网管参数管理 | D4: =COUNTIF(SC!$E:$E,"A") -> 12 | E4: =COUNTIF(SC!$E:$E,"B") -> 0 | F4: =COUNTIF(SC!$E:$E,"CA") -> 0 | G4: =COUNTIF(SC!$E:$E,"CB") -> 7 | H4: =SUM($D4:$G4) -> 19
A5: SD | B5: FaultMgmt | C5: 告警参数管理 | D5: =COUNTIF(SD!$E:$E,"A") -> 55 | E5: =COUNTIF(SD!$E:$E,"B") -> 0 | F5: =COUNTIF(SD!$E:$E,"CA") -> 0 | G5: =COUNTIF(SD!$E:$E,"CB") -> 0 | H5: =SUM($D5:$G5) -> 55
A6: SE | B6: DeviceLogMgmt | C6: 日志参数管理 | D6: =COUNTIF(SE!$E:$E,"A") -> 6 | E6: =COUNTIF(SE!$E:$E,"B") -> 0 | F6: =COUNTIF(SE!$E:$E,"CA") -> 0 | G6: =COUNTIF(SE!$E:$E,"CB") -> 0 | H6: =SUM($D6:$G6) -> 6
A7: SF | B7: Services.FAPService.{i}.FAPControl.NR | C7: 基站配置参数管理 | D7: 18 | E7: 0 | F7: 0 | G7: 0 | H7: 18
A8: SG | B8: Services.FAPService.{i}.FAPControl.SelfConfig.SONConfigParam | C8: SON参数管理 | D8: =COUNTIF(SG!$E:$E,"A") -> 19 | E8: =COUNTIF(SG!$E:$E,"B") -> 0 | F8: =COUNTIF(SG!$E:$E,"CA") -> 0 | G8: =COUNTIF(SG!$E:$E,"CB") -> 18 | H8: =SUM($D8:$G8) -> 37
A9: SH | B9: Services.FAPService.{i}.FAPControl.LocalBreakout | C9: 本地分流规则 | D9: 0 | E9: 0 | F9: 0 | G9: 36 | H9: 36
A10: SI | B10: Services.FAPService.{i}.Capabilities.NR | C10: 基站能力参数管理 | D10: 1 | E10: 0 | F10: 0 | G10: 0 | H10: 1
A11: SJ | B11: Services.FAPService.{i}.CellConfig.{i}.NR | C11: 小区服务参数管理（总体） | D11: =COUNTIF(SJ!$E:$E,"A") -> 48 | E11: =COUNTIF(SJ!$E:$E,"B") -> 9 | F11: =COUNTIF(SJ!$E:$E,"CA") -> 5 | G11: =COUNTIF(SJ!$E:$E,"CB") -> 2 | H11: =SUM($D11:$G11) -> 64
A12: SK | B12: Services.FAPService.{i}.CellConfig.{i}.NR.RAN | C12: RAN协议栈参数 | D12: =COUNTIF(SK!$E:$E,"A") -> 123 | E12: =COUNTIF(SK!$E:$E,"B") -> 10 | F12: =COUNTIF(SK!$E:$E,"CA") -> 4 | G12: =COUNTIF(SK!$E:$E,"CB") -> 5 | H12: =SUM($D12:$G12) -> 142
A13: SL | B13: Services.FAPService.{i}.CellConfig.{i}.NR.RAN.NeighborList | C13: 邻区参数管理 | D13: =COUNTIF(SL!$E:$E,"A") -> 28 | E13: =COUNTIF(SL!$E:$E,"B") -> 1 | F13: =COUNTIF(SL!$E:$E,"CA") -> 0 | G13: =COUNTIF(SL!$E:$E,"CB") -> 0 | H13: =SUM($D13:$G13) -> 29
A14: SM | B14: Services.FAPService.{i}.CellConfig.{i}.NR.RAN.Mobility | C14: 移动性参数管理 | D14: =COUNTIF(SM!$E:$E,"A") -> 207 | E14: =COUNTIF(SM!$E:$E,"B") -> 65 | F14: =COUNTIF(SM!$E:$E,"CA") -> 59 | G14: =COUNTIF(SM!$E:$E,"CB") -> 13 | H14: =SUM($D14:$G14) -> 344
A15: SN | B15: Services.FAPService.{i}.Transport.SCTP | C15: SCTP参数管理 | D15: =COUNTIF(SN!$E:$E,"A") -> 9 | E15: =COUNTIF(SN!$E:$E,"B") -> 0 | F15: =COUNTIF(SN!$E:$E,"CA") -> 0 | G15: =COUNTIF(SN!$E:$E,"CB") -> 0 | H15: =SUM($D15:$G15) -> 9
A16: SO | B16: WANDevice | C16: WAN口配置参数管理 | D16: =COUNTIF(SO!$E:$E,"A") -> 31 | E16: =COUNTIF(SO!$E:$E,"B") -> 6 | F16: =COUNTIF(SO!$E:$E,"CA") -> 0 | G16: =COUNTIF(SO!$E:$E,"CB") -> 0 | H16: =SUM($D16:$G16) -> 37
A17: SP | B17: Time | C17: 时间服务器参数管理 | D17: =COUNTIF(SP!$E:$E,"A") -> 5 | E17: =COUNTIF(SP!$E:$E,"B") -> 0 | F17: =COUNTIF(SP!$E:$E,"CA") -> 3 | G17: =COUNTIF(SP!$E:$E,"CB") -> 0 | H17: =SUM($D17:$G17) -> 8
A18: SQ | B18: FAP.GPS | C18: GPS信息参数管理 | D18: 0 | E18: =COUNTIF(SQ!$E:$E,"B") -> 0 | F18: =COUNTIF(SQ!$E:$E,"CA") -> 0 | G18: =COUNTIF(SQ!$E:$E,"CB") -> 3 | H18: =SUM($D18:$G18) -> 3
A19: SR | B19: FAP.MRMgmt | C19: MR参数管理 | D19: =COUNTIF(SR!$E:$E,"A") -> 1 | E19: =COUNTIF(SR!$E:$E,"B") -> 14 | F19: =COUNTIF(SR!$E:$E,"CA") -> 0 | G19: =COUNTIF(SR!$E:$E,"CB") -> 0 | H19: =SUM($D19:$G19) -> 15
A20: SS | B20: FAP.Config.{i}.PerfMgmt | C20: 性能参数管理 | D20: =COUNTIF(SS!$E:$E,"A") -> 10 | E20: =COUNTIF(SS!$E:$E,"B") -> 0 | F20: =COUNTIF(SS!$E:$E,"CA") -> 0 | G20: =COUNTIF(SS!$E:$E,"CB") -> 0 | H20: =SUM($D20:$G20) -> 10
A21: ST | B21: FAP.SCMgmt | C21: 软采规则 | D21: 148 | E21: =COUNTIF(SH!$E:$E,"B") -> 0 | F21: 0 | G21: =COUNTIF(SS!$E:$E,"CB") -> 0 | H21: =SUM($D21:$G21) -> 148
A22: 合计 | D22: =SUM(D2:D21) -> 807 | E22: =SUM(E2:E21) -> 107 | F22: =SUM(F2:F21) -> 71 | G22: =SUM(G2:G21) -> 86 | H22: =SUM($D22:$G22) -> 1071
B23: 说明： 1.LDN的组成方式，按照《中国移动室分系统OMC南向接口要求 第2部分：皮基站技术要求_0611_clean》规范中附录B3.2的样例： i. gNB的LDN的组成如：localDn="ManagedElement=SN,Type=gNB",其中，ManagedElement的SN取SA页Device.DeviceInfo.MU.{i}.SerialNumber ii. CU的LDN组成如：localDn="ManagedElement=SN,Type=CU,gNBID=123,CUId=123，其中CUId取值为gNBID的值 iii. DU的LDN组成如：localDn="ManagedElement=SN,Type=DU,gNBID=123,DUId=22"，其中DUId取值为NrcellIdentity iv. 对于CU小区的LDN，其组成如localDn="Type=Cell,Mode=SA,gNBID=123,NrCI=22,CUId=123" v. 对于DU小区的LDN，其组成如localDn="Type=Cell,Mode=SA,gNBID=123,NrCI=22,DUId=22" vi. EU的LDN组成如：localDn="ManagedElement=SN,Type=EU,EU=EUSN",其中，EUSN取SA页Device.DeviceInfo.MU.{i}.Slot.{i}.EU.{i}.SerialNumber vii. RU的LDN组成如：localDn="ManagedElement=SN,Type=RU,RU=RUSN",其中，RUSN取SA页Device.DeviceInfo.MU.{i}.Slot.{i}.EU.{i}.RU.{i}.SerialNumber viii. 网卡的LDN组成如：localDn="ManagedElement=SN,Type=NIC,PortLocation=..." 2.SD页告警ManagedObjectInstance须填写DN，DN后以"|"结尾，并可以携带其他辅助信息，信息以"|"分割 样例(Device.DeviceInfo.MU.{i}.SerialNumber=1234567,告警源CU的SN=7654321，告警源DU的SN=123456789)： 1. MU产生告警，则MOI中信息如： "DN='DC=BJ,SubNetwork=1,ManagedElement=1234567,Type=gNB'|......" 2. MU.1.Slot.1产生CU告警，则MOI中信息如："DN='DC=BJ,SubNetwork=1,ManagedElement=1234567,Type=CU,gNBID=123,CUId=123'|......" 3. MU.1.Slot.1产生DU告警, 则MOI中信息如："DN='DC=BJ,SubNetwork=1,ManagedElement=1234567,Type=DU,gNBID=123,DUId=22'|......" 4. MU.1.Slot.1产生CU小区告警，则MOI中信息如："DN='DC=BJ,SubNetwork=1,ManagedElement=1234567,Type=Cell,Mode=SA,gNBID=123,NrCI=22,CUId=123|......" 5. MU.1.Slot.1产生DU小区告警, 则MOI中信息如："DN='DC=BJ,SubNetwork=1,ManagedElement=1234567,Type=Cell,Mode=SA,gNBID=123,NrCI=22,DUId=22|......" 6. MU.1.Slot.1产生网卡告警，则MOI中信息如："DN='DC=BJ,SubNetwork=1,ManagedElement=1234567,Type=NIC,PortLocation=...|......"

Sheet SA
A1: 归类 | B1: 网管数据模型(TR181) | C1: 参数名称 | D1: 中文名 | E1: 重要性 | F1: 北向Index | G1: 北向NRM参数映射 | H1: 网管读写权限 | I1: 类型 | J1: 描述 | K1: 来源 | L1: 备注
A2: 主机单元（MU）设备信息参数管理 | B2: Device.DeviceInfo.MU.{i}.UserLabel | C2: UserLabel | D2: 用户友好名 | E2: A | F2: AA | G2: UserLabel | H2: RW | I2: string | J2: 字段必须与OMC系统内配置资源名称保持一致。且要求UserLabel与告警、性能数据中同一资源对象使用的网元用户友好名保持一致，即用户有好名在OMC内部以及北向接口交互过程中全局唯一。OMC系统内配置资源命名建议参考《中国移动网络资源命名规范-无线分册》，基站命名要求。默认不填写为空字符串 | K2: 5G SA gNB网元统计数据需求规范-NRM(V1.4.2)
B3: Device.DeviceInfo.MU.{i}.DnPrefix | C3: DnPrefix | D3: DN前缀 | E3: A | F3: / | G3: / | H3: RW | I3: string | J3: 默认不填写为空字符串 | K3: 中国移动室分系统OMC南向接口要求 第2部分：皮基站技术要求_0611_clean
B4: Device.DeviceInfo.MU.{i}.ManufacturerOUI | C4: ManufacturerOUI | D4: 制造商OUI | E4: A | F4: / | G4: / | H4: R | I4: string(6) | J4: / | K4: TR系列规范(TR098/TR181)/NRM数据配置要求
B5: Device.DeviceInfo.MU.{i}.Manufacturer | C5: Manufacturer | D5: 制造商 | E5: A | F5: / | G5: / | H5: R | I5: string(64) | J5: / | K5: TR系列规范(TR098/TR181)/NRM数据配置要求
B6: Device.DeviceInfo.MU.{i}.ModelName | C6: ModelName | D6: 设备型号 | E6: A | F6: AA | G6: NeType | H6: R | I6: string(64) | J6: / | K6: TR系列规范(TR098/TR181)/NRM数据配置要求
B7: Device.DeviceInfo.MU.{i}.VendorUnitFamilyType | C7: VendorUnitFamilyType | D7: 归属类型 | E7: A | F7: AE | G7: VendorUnitFamilyType | H7: R | I7: string | J7: 由供应商提供的便于记忆的资产单元的归属类型 | K7: 5G SA gNB网元统计数据需求规范-NRM(V1.4.2)
B8: Device.DeviceInfo.MU.{i}.VendorUnitTypeNumber | C8: VendorUnitTypeNumber | D8: 资产单元类型版本号 | E8: A | F8: AE | G8: VendorUnitTypeNumber | H8: R | I8: string | J8: 由供应商提供的可唯一识别资产单元类型及版本的号码 | K8: 5G SA gNB网元统计数据需求规范-NRM(V1.4.2)
B9: Device.DeviceInfo.MU.{i}.SerialNumber | C9: SerialNumber | D9: 序列号 | E9: A | F9: AB AC | G9: SerialNumber | H9: R | I9: string(64) | J9: 设备序列号，以“-NR”结尾 | K9: TR系列规范(TR098/TR181)/NRM数据配置要求
B10: Device.DeviceInfo.MU.{i}.HardwareVersion | C10: HardwareVersion | D10: 硬件版本 | E10: A | F10: AA | G10: Version | H10: R | I10: string(64) | J10: / | K10: TR系列规范(TR098/TR181)/NRM数据配置要求
B11: Device.DeviceInfo.MU.{i}.SoftwareVersion | C11: SoftwareVersion | D11: 软件版本 | E11: A | F11: AA | G11: SwVersion | H11: R | I11: string(64) | J11: / | K11: TR系列规范(TR098/TR181)/NRM数据配置要求
B12: Device.DeviceInfo.MU.{i}.HardwarePlatform | C12: HardwarePlatform | D12: 硬件平台 | E12: A | F12: AA | G12: HardwarePlatform | H12: R | I12: string(64) | J12: / | K12: NRM数据配置要求
B13: Device.DeviceInfo.MU.{i}.AdditionalHardwareVersion | C13: AdditionalHardwareVersion | D13: 附加硬件版本 | E13: A | F13: / | G13: / | H13: R | I13: string(64) | J13: / | K13: TR系列规范(TR098/TR181)/NRM数据配置要求
B14: Device.DeviceInfo.MU.{i}.AdditionalSoftwareVersion | C14: AdditionalSoftwareVersion | D14: 附加软件版本 | E14: A | F14: / | G14: / | H14: R | I14: string(64) | J14: / | K14: TR系列规范(TR098/TR181)/NRM数据配置要求
... B17: Device.DeviceInfo.MU.{i}.Status | C17: Status | D17: 机框/服务器状态 | E17: A | F17: / | G17: / | H17: R | I17: unsignedInt[1:3] | J17: 1:正常 2:离线 3:告警 | K17: TR系列规范(TR098/TR182)/NRM数据配置要求
B18: Device.DeviceInfo.MU.{i}.Reboot | C18: Reboot | D18: 重启开关 | E18: A | F18: / | G18: / | H18: RW | I18: boolean | J18: 0:不重启 1:重启
B19: Device.DeviceInfo.MU.{i}.UpTime | C19: UpTime | D19: 运行时间 | E19: A | F19: / | G19: / | H19: R | I19: unsignedInt | J19: / | K19: TR系列规范(TR098/TR181)/NRM数据配置要求
B20: Device.DeviceInfo.MU.{i}.FirstUseDate | C20: FirstUseDate | D20: 首次使用日期 | E20: A | F20: / | G20: / | H20: R | I20: dateTime | J20: / | K20: TR系列规范(TR098/TR181)/NRM数据配置要求
B21: Device.DeviceInfo.MU.{i}.ClockSource | C21: ClockSource | D21: 时钟源类型 | E21: A | F21: AA | G21: ClockSource | H21: R | I21: unsignedInt[1:11} | J21: Enumerate{ GPS, GLONASS, BDS, 1588v2, GPS/GLONASS, // GPS 为主，GLONASS 为从 BDS/GPS， GPS/BDS， GALILEO， GPS/GALILEO， // GPS/GALILEO/GLONASS, GPS/GALILEO/BDS } | K21: 《5G SA gNB网元统计数据需求规范-NRM(V1.4.2)》
B22: Device.DeviceInfo.MU.{i}.SwUpgrade.Stage | C22: Stage | D22: 升级阶段 | E22: A | F22: / | G22: / | H22: R | I22: unsignedInt[1:5] | J22: 1:初始化 2:下载 3:安装 4:等待激活 5.激活
B23: Device.DeviceInfo.MU.{i}.SwUpgrade.FailureCause | C23: FailureCause | D23: 升级失败原因 | E23: A | F23: / | G23: / | H23: R | I23: string(512) | J23: 升级失败原因描述
B24: Device.DeviceInfo.MU.{i}.SwUpgrade.Status | C24: Status | D24: 状态 | E24: A | F24: / | G24: / | H24: R | I24: unsignedInt[1:3] | J24: 1:成功 2:失败
B25: Device.DeviceInfo.MU.{i}.DateOfLastService | C25: DateOfLastService | D25: 最近服务的日期（最近一次恢复工作正常状态的时间） | E25: A | F25: AE | G25: DateOfLastService | H25: R | I25: dateTime | J25: 生产日期 | K25: 5G SA gNB网元统计数据需求规范-NRM(V1.5.0)
B26: Device.DeviceInfo.MU.{i}.DateOfManufacture | C26: DateOfManufacture | D26: 生产日期 | E26: A | F26: AE | G26: DateOfManufacture | H26: R | I26: dateTime | J26: 最近服务的日期（最近一次恢复工作正常状态的时间） | K26: 5G SA gNB网元统计数据需求规范-NRM(V1.5.0)
B27: Device.DeviceInfo.MU.{i}.ManufacturerData | C27: ManufacturerData | D27: 特殊信息 | E27: A | F27: AE | G27: ManufacturerData | H27: R | I27: string | J27: 设备商填写的特殊信息 | K27: 5G SA gNB网元统计数据需求规范-NRM(V1.5.0)
B28: Device.DeviceInfo.MU.{i}.SlotsInformation | C28: SlotsInformation | D28: 插槽信息 | E28: A | F28: AC | G28: SlotsInformation | H28: R | I28: string | J28: 框内所有插槽、描述及占用状态。List of Struct{槽位号（字符串），描述(字符串)，占用状态（枚举)}。其中其中描述信息由厂家自行决定，占用状态为枚举{Unused,Used} | K28: 5G SA gNB网元统计数据需求规范-NRM(V1.5.0)
B29: Device.DeviceInfo.MU.{i}.Slot.{i}.PackPosition | C29: PackPosition | D29: 板卡位置 | E29: A | F29: AD | G29: PackPosition | H29: R | I29: string(64) | J29: 板卡在机框内的相对位置，通常用编号表示。数据格式定义为“机柜-机框-槽号”
B30: Device.DeviceInfo.MU.{i}.Slot.{i}.SlotsOccupied | C30: SlotsOccupied | D30: 占用槽位 | E30: A | F30: AD | G30: SlotsOccupied | H30: R | I30: string(64) | J30: 应表示板卡占用的槽位号列表。（注：一些板卡较宽，可能会占用两个或以上槽位）
B31: Device.DeviceInfo.MU.{i}.Slot.{i}.ManufacturerOUI | C31: ManufacturerOUI | D31: 制造商OUI | E31: A | F31: / | G31: / | H31: R | I31: string(6) | J31: / | K31: TR系列规范(TR098/TR181)/NRM数据配置要求
B32: Device.DeviceInfo.MU.{i}.Slot.{i}.Manufacturer | C32: Manufacturer | D32: 制造商 | E32: A | F32: / | G32: / | H32: R | I32: string(64) | J32: / | K32: TR系列规范(TR098/TR181)/NRM数据配置要求
B33: Device.DeviceInfo.MU.{i}.Slot.{i}.ModelName | C33: ModelName | D33: 设备型号 | E33: A | F33: / | G33: / | H33: R | I33: string(64) | J33: /
B34: Device.DeviceInfo.MU.{i}.Slot.{i}.SerialNumber | C34: SerialNumber | D34: 序列号 | E34: A | F34: AD | G34: SerialNumber | H34: R | I34: string(64) | J34: /
B35: Device.DeviceInfo.MU.{i}.Slot.{i}.HardwareVersion | C35: HardwareVersion | D35: 硬件版本 | E35: A | F35: / | G35: / | H35: R | I35: string(64) | J35: /
B36: Device.DeviceInfo.MU.{i}.Slot.{i}.SoftwareVersion | C36: SoftwareVersion | D36: 软件版本 | E36: A | F36: / | G36: / | H36: R | I36: string(64) | J36: /
B37: Device.DeviceInfo.MU.{i}.Slot.{i}.ProvisioningCode | C37: ProvisioningCode | D37: 供应商代号 | E37: A | F37: / | G37: / | H37: R | I37: string(64) | J37: / | K37: TR系列规范(TR098/TR181)/NRM数据配置要求
B38: Device.DeviceInfo.MU.{i}.Slot.{i}.VendorUnitFamilyType | C38: VendorUnitFamilyType | D38: 板卡类型 | E38: A | F38: AD | G38: VendorUnitFamilyType | H38: R | I38: string(64) | J38: 描述板卡功能类型。List of Enum{ 板卡类型（枚举）}。其中板卡类型的为Enumerate{MainControl，Carrier，Trans，Other}，分别表示主控板、载频板、传输板、其他板卡类型。对跨类型的板卡，列表中应包括该板卡的全部功能类型。（必须上报）
B39: Device.DeviceInfo.MU.{i}.Slot.{i}.UpTime | C39: UpTime | D39: 运行时间 | E39: A | F39: / | G39: / | H39: R | I39: unsignedInt | J39: / | K39: TR系列规范(TR098/TR181)/NRM数据配置要求
B40: Device.DeviceInfo.MU.{i}.Slot.{i}.DataModelSpecVersion | C40: DataModelSpecVersion | D40: 数据模型版本 | E40: A | F40: / | G40: / | H40: R | I40: string | J40: 描述中国移动技术规范发布的小基站南向数据模型版本号
B41: Device.DeviceInfo.MU.{i}.Slot.{i}.3GPPSpecVersion | C41: 3GPPSpecVersion | D41: 3GPP协议版本 | E41: A | F41: / | G41: / | H41: R | I41: string | J41: / | K41: TR系列规范(TR098/TR181)/NRM数据配置要求
B42: Device.DeviceInfo.MU.{i}.Slot.{i}.FirstUseDate | C42: FirstUseDate | D42: 首次使用日期 | E42: A | F42: / | G42: / | H42: R | I42: dateTime | J42: / | K42: TR系列规范(TR098/TR181)/NRM数据配置要求
...

Sheet SB
A1: 归类 | B1: 网管数据模型(TR181) | C1: 参数名称 | D1: 中文名 | E1: 重要性 | F1: 北向Index | G1: 北向NRM参数映射 | H1: 网管读写权限 | I1: 类型 | J1: 描述 | K1: 来源 | L1: 备注
A2: 版本参数管理 | B2: Device.SoftwareCtrl.AutoActivateEnable | C2: AutoActivateEnable | D2: 立即激活目标升级版本使能开关 | E2: A | F2: / | G2: / | H2: RW | I2: boolean | J2: (0=false,1=true)，立即激活目标升级版本使能开关，当为true时，设备下载成功目标升级版本后立即激活版本，当为flase时，需要和ActivateTime这两个参数一起使用。 | K2: 自定义
B3: Device.SoftwareCtrl.ActivateTime | C3: ActivateTime | D3: 软件激活时间 | E3: A | H3: RW | I3: dateTime | J3: 激活时间，格式如：2012-12-11T19:15:00Z，下发命令后设备只要在大于等于激活时间里开启，就会激活系统备份版本。
B4: Device.SoftwareCtrl.ActivateEnable | C4: ActivateEnable | D4: 激活备份版本使能开关 | E4: CB | H4: RW | I4: boolean | J4: (0=false,1=true)激活备份版本使能开关，当为true时立即激活备份版本。
B5: Device.SoftwareCtrl.SystemCurrentVersion | C5: SystemCurrentVersion | D5: 系统当前版本 | E5: A | H5: R | I5: string(64) | J5: 系统正在使用的版本。表示gNB整体版本。
B6: Device.SoftwareCtrl.SystemBackupVersion | C6: SystemBackupVersion | D6: 系统备份版本 | E6: CB | H6: R | I6: string(64) | J6: 系统备份版本，新下载的或以前使用的版本。

Sheet SC
A1: 归类 | B1: 网管数据模型(TR181) | C1: 参数名称 | D1: 中文名 | E1: 重要性 | F1: 北向Index | G1: 北向NRM参数映射 | H1: 网管读写权限 | I1: 类型 | J1: 描述 | K1: 来源 | L1: 备注
A2: 网管参数管理 | B2: Device.ManagementServer.URL | C2: URL | D2: 网管服务器URL | E2: A | F2: / | G2: / | H2: RW | I2: string(256) | J2: ACS使用CWMP连接ACS的URL。格式必须为合法的HTTP/HTTPS的形式。 | K2: TR系列规范(TR098/TR181)
B3: Device.ManagementServer.Username | C3: Username | D3: 连接用户名 | E3: A | F3: / | G3: / | H3: RW | I3: string(256) | J3: ACS使用CWMP连接基站时使用的认证用户名。仅用于基站的基于HTTP的认证。 | K3: TR系列规范(TR098/TR181)
B4: Device.ManagementServer.Password | C4: Password | D4: 连接密码 | E4: A | F4: / | G4: / | H4: RW | I4: string(256) | J4: 基站使用CWMP连接ACS时使用的认证密码。仅用于基站的基于HTTP的认证。读取时返回一个空字符串. | K4: TR系列规范(TR098/TR181)
B5: Device.ManagementServer.PeriodicInformEnable | C5: PeriodicInformEnable | D5: 连接使能开关 | E5: A | F5: / | G5: / | H5: RW | I5: boolean | J5: 基站是否必须利用Inform方法调用定时向服务器端发送基站信息。当PeriodicInformEnable=true时，PeriodicInformInterval才起作用 | K5: TR系列规范(TR098/TR181)
B6: Device.ManagementServer.PeriodicInformTime | C6: PeriodicInformTime | D6: 上报周期 | E6: A | F6: / | G6: / | H6: RW | I6: dateTime | J6: 2012-12-11T19:15:00Z | K6: TR系列规范(TR098/TR181)
B7: Device.ManagementServer.PeriodicInformInterval | C7: PeriodicInformInterval | D7: 周期上报时间间隔 | E7: A | F7: / | G7: / | H7: RW | I7: unsignedInt[1:] | J7: 在PeriodicInformEnable为真时，基站必须尝试连接ACS并调用Inform方法的时间间隔。当PeriodicInformEnable=true才生效 | K7: TR系列规范(TR098/TR181)
B8: Device.ManagementServer.ParameterKey | C8: ParameterKey | D8: 键值 | E8: A | F8: / | G8: / | H8: R | I8: string(32) | J8: 来自于服务器的最新的 SetParameterValues，AddObject 或 DeleteObject 方法调用的 ParameterKey 自变量数值。如果没有此类调用，此数值为空。 | K8: TR系列规范(TR098/TR181)
B9: Device.ManagementServer.ConnectionRequestURL | C9: ConnectionRequestURL | D9: 连接请求URL | E9: A | F9: AA | G9: ManagementIpAddress | H9: R | I9: string(256) | J9: ACS向基站发起连接请求通知时所使用的HTTPURL。其形式如下：http://host:port/SOAP/HNBServlet?a=1的"主机"部分可以是基站管理接口的IP地址，用以替代域名。 | K9: TR系列规范(TR098/TR181)
B10: Device.ManagementServer.ConnectionRequestUsername | C10: ConnectionRequestUsername | D10: 连接请求用户名 | E10: A | F10: / | G10: / | H10: RW | I10: string(256) | J10: ACS向基站发起连接请求时，鉴权过程使用的用户名。 | K10: TR系列规范(TR098/TR181)
B11: Device.ManagementServer.ConnectionRequestPassword | C11: ConnectionRequestPassword | D11: 连接请求密码 | E11: A | F11: / | G11: / | H11: RW | I11: string(256) | J11: ACS向基站发起连接请求时，鉴权过程使用的密码。在被读取时，该参数会忽略实际值而返回一个空字符串。 | K11: TR系列规范(TR098/TR181)
B12: Device.ManagementServer.UDPConnectionRequestAddress | C12: UDPConnectionRequestAddress | D12: UDP连接请求地址 | E12: A | F12: / | G12: / | H12: R | I12: string(256) | J12: / | K12: TR系列规范(TR098/TR181)
B13: Device.ManagementServer.STUNEnable | C13: STUNEnable | D13: STUN使能开关 | E13: CB | F13: / | G13: / | H13: RW | I13: boolean | J13: (0=false,1=true) | K13: TR系列规范(TR098/TR181)
B14: Device.ManagementServer.STUNServerAddress | C14: STUNServerAddress | D14: STUN服务器地址 | E14: CB | F14: / | G14: / | H14: RW | I14: string(256) | J14: / | K14: TR系列规范(TR098/TR181)
... B20: Device.ManagementServer.NATDetected | C20: NATDetected | D20: NAT转换地址 | E20: A | F20: / | G20: / | H20: R | I20: boolean | J20: (0=false,1=true) | K20: TR系列规范(TR098/TR181)

Sheet SD
A1: 类型 | B1: 网管数据模型(TR181) | C1: 参数名称 | D1: 中文名 | E1: 重要性 | F1: 北向Index | G1: 北向NRM参数映射 | H1: 网管读写权限 | I1: 类型 | J1: 描述 | K1: 来源 | L1: 备注
A2: 告警管理 | B2: Device.FaultMgmt.SupportedAlarmNumberOfEntries | C2: SupportedAlarmNumberOfEntries | D2: 最大告警实例数量 | E2: A | F2: / | G2: / | H2: R | I2: unsignedInt | J2: / | K2: TR系列规范(TR098/TR181/中国移动Nanocell基站设备网络管理南向接口技术规范v1.3.0)
B3: Device.FaultMgmt.MaxCurrentAlarmEntries | C3: MaxCurrentAlarmEntries | D3: 最大当前告警实例数量 | E3: A | F3: / | G3: / | H3: R | I3: unsignedInt | J3: /
B4: Device.FaultMgmt.CurrentAlarmNumberOfEntries | C4: CurrentAlarmNumberOfEntries | D4: 当前告警实例数量 | E4: A | F4: / | G4: / | H4: R | I4: unsignedInt | J4: /
B5: Device.FaultMgmt.HistoryEventNumberOfEntries | C5: HistoryEventNumberOfEntries | D5: 历史事件实例数量 | E5: A | F5: / | G5: / | H5: R | I5: unsignedInt | J5: /
B6: Device.FaultMgmt.ExpeditedEventNumberOfEntries | C6: ExpeditedEventNumberOfEntries | D6: 紧急事件实例数量 | E6: A | F6: / | G6: / | H6: R | I6: unsignedInt | J6: /
B7: Device.FaultMgmt.QueuedEventNumberOfEntries | C7: QueuedEventNumberOfEntries | D7: 队列事件实例数量 | E7: A | F7: / | G7: / | H7: R | I7: unsignedInt | J7: /
B8: Device.FaultMgmt.SupportedAlarm.{i}.EventType | C8: EventType | D8: 告警类型 | E8: A | F8: / | G8: / | H8: R | I8: string(64) | J8: 设备上报告警消息中的告警类型，包括通讯告警、环境告警、设备告警、处理错误告警、服务质量告警等
B9: Device.FaultMgmt.SupportedAlarm.{i}.ProbableCause | C9: ProbableCause | D9: 告警原因 | E9: A | F9: / | G9: / | H9: R | I9: string(64) | J9: /
B10: Device.FaultMgmt.SupportedAlarm.{i}.SpecificProblem | C10: SpecificProblem | D10: 告警描述 | E10: A | F10: / | G10: / | H10: R | I10: string(128) | J10: /
B11: Device.FaultMgmt.SupportedAlarm.{i}.PerceivedSeverity | C11: PerceivedSeverity | D11: 支持告警级别 | E11: A | F11: / | G11: / | H11: R | I11: string | J11: 设备上报告警消息中的告警级别：Critical,严重；Major,重要；Minor,次要；Warning,警告；
B12: Device.FaultMgmt.SupportedAlarm.{i}.ReportingMechanism | C12: ReportingMechanism | D12: 告警上报机制 | E12: A | F12: / | G12: / | H12: RW | I12: string | J12: / | L12: 修改网管读写权限
B13: Device.FaultMgmt.CurrentAlarm.{i}.AlarmIdentifier | C13: AlarmIdentifier | D13: 该告警的唯一序列号 | E13: A | F13: / | G13: / | H13: R | I13: string(20) | J13: /
B14: Device.FaultMgmt.CurrentAlarm.{i}.AlarmRaisedTime | C14: AlarmRaisedTime | D14: 告警发生时间 | E14: A | F14: / | G14: / | H14: R | I14: dateTime | J14: /
B15: Device.FaultMgmt.CurrentAlarm.{i}.AlarmChangedTime | C15: AlarmChangedTime | D15: 告警改变时间 | E15: A | F15: / | G15: / | H15: R | I15: dateTime | J15: /
B16: Device.FaultMgmt.CurrentAlarm.{i}.FaultLocation | C16: FaultLocation | D16: 告警源定位信息 | E16: A | F16: / | G16: / | H16: R | I16: string(512) | J16: 表示故障源对应的资源对象信息，通常用管理对象实例（MOI）的DN表示。其中对于MOI的DN定义，5G皮基站参考《中国移动5G扩展型皮基站网管南向接口数据模型规范》相关说明，4G皮基站参考《中国移动一体化皮站_飞站基站设备网络管理南向接口数据配置模型规范》相关说明 | L16: 《中国移动无线三方设备综合OMC南向接口要求 第2部分：皮基站技术要求_0629》
B17: Device.FaultMgmt.CurrentAlarm.{i}.ManagedObjectInstance | C17: ManagedObjectInstance | D17: 管理对象实例 | E17: A | F17: / | G17: / | H17: R | I17: string(512) | J17: 定义了承载该对象实例DN时发生的基站告警的信息对象等级的实例 | L17: 手动同步告警采用该模型节点上报
B18: Device.FaultMgmt.CurrentAlarm.{i}.EventType | C18: EventType | D18: 告警类型 | E18: A | F18: / | G18: / | H18: R | I18: string(64) | J18: 设备上报告警消息中的告警类型，包括通讯告警、环境告警、设备告警、处理错误告警、服务质量告警等
B19: Device.FaultMgmt.CurrentAlarm.{i}.ProbableCause | C19: ProbableCause | D19: 告警原因 | E19: A | F19: / | G19: / | H19: R | I19: string(64) | J19: /
B20: Device.FaultMgmt.CurrentAlarm.{i}.SpecificProblem | C20: SpecificProblem | D20: 告警描述 | E20: A | F20: / | G20: / | H20: R | I20: string(128) | J20: /
B21: Device.FaultMgmt.CurrentAlarm.{i}.PerceivedSeverity | C21: PerceivedSeverity | D21: 当前告警级别 | E21: A | F21: / | G21: / | H21: R | I21: string | J21: 设备上报告警消息中的告警级别：Critical,严重；Major,重要；Minor,次要；Warning,警告；
B22: Device.FaultMgmt.CurrentAlarm.{i}.AdditionalText | C22: AdditionalText | D22: 告警附加文本 | E22: A | F22: / | G22: / | H22: R | I22: string(256) | J22: 本规范规定内容为厂家告警编码
B23: Device.FaultMgmt.CurrentAlarm.{i}.AdditionalInformation | C23: AdditionalInformation | D23: 告警附加信息 | E23: A | F23: / | G23: / | H23: R | I23: string(256) | J23: （格式：英文）统一采用此参数作为告警附加信息，映射到北向的AlarmText字段
B24: Device.FaultMgmt.HistoryEvent.{i}.EventTime | C24: EventTime | D24: 告警发生、改变、清除的时间 | E24: A | F24: / | G24: / | H24: R | I24: dateTime | J24: /
B25: Device.FaultMgmt.HistoryEvent.{i}.AlarmIdentifier | C25: AlarmIdentifier | D25: 该告警的唯一序列号 | E25: A | F25: / | G25: / | H25: R | I25: string(20) | J25: /
B26: Device.FaultMgmt.HistoryEvent.{i}.NotificationType | C26: NotificationType | D26: 通知类型 | E26: A | F26: / | G26: / | H26: R | I26: string | J26: /
B27: Device.FaultMgmt.HistoryEvent.{i}.FaultLocation | C27: FaultLocation | D27: 告警源定位信息 | E27: A | F27: / | G27: / | H27: R | I27: string(512) | J27: 表示故障源对应的资源对象信息，通常用管理对象实例（MOI）的DN表示。其中对于MOI的DN定义，5G皮基站参考《中国移动5G扩展型皮基站网管南向接口数据模型规范》相关说明，4G皮基站参考《中国移动一体化皮站_飞站基站设备网络管理南向接口数据配置模型规范》相关说明 | L27: 《中国移动无线三方设备综合OMC南向接口要求 第2部分：皮基站技术要求_0629》
B28: Device.FaultMgmt.HistoryEvent.{i}.ManagedObjectInstance | C28: ManagedObjectInstance | D28: 管理对象实例 | E28: A | F28: / | G28: / | H28: R | I28: string(512) | J28: 定义了承载该对象实例DN时发生的基站告警的信息对象等级的实例
B29: Device.FaultMgmt.HistoryEvent.{i}.EventType | C29: EventType | D29: 告警类型 | E29: A | F29: / | G29: / | H29: R | I29: string(64) | J29: 设备上报告警消息中的告警类型，包括通讯告警、环境告警、设备告警、处理错误告警、服务质量告警等
B30: Device.FaultMgmt.HistoryEvent.{i}.ProbableCause | C30: ProbableCause | D30: 告警原因 | E30: A | F30: / | G30: / | H30: R | I30: string(64) | J30: /
B31: Device.FaultMgmt.HistoryEvent.{i}.SpecificProblem | C31: SpecificProblem | D31: 告警描述 | E31: A | F31: / | G31: / | H31: R | I31: string(128) | J31: /
B32: Device.FaultMgmt.HistoryEvent.{i}.PerceivedSeverity | C32: PerceivedSeverity | D32: 告警级别 | E32: A | F32: / | G32: / | H32: R | I32: string | J32: 设备上报告警消息中的告警级别：Critical,严重；Major,重要；Minor,次要；Warning,警告；
B33: Device.FaultMgmt.HistoryEvent.{i}.AdditionalText | C33: AdditionalText | D33: 告警附加文本 | E33: A | F33: / | G33: / | H33: R | I33: string(256) | J33: 本规范规定内容为厂家告警编码
B34: Device.FaultMgmt.HistoryEvent.{i}.AdditionalInformation | C34: AdditionalInformation | D34: 告警附加信息 | E34: A | F34: / | G34: / | H34: R | I34: string(256) | J34: 格式：英文。统一采用此参数作为告警附加信息，映射到北向的AlarmText字段
B35: Device.FaultMgmt.ExpeditedEvent.{i}.EventTime | C35: EventTime | D35: 告警发生、改变、清除的时间 | E35: A | F35: / | G35: / | H35: R | I35: dateTime | J35: /
B36: Device.FaultMgmt.ExpeditedEvent.{i}.AlarmIdentifier | C36: AlarmIdentifier | D36: 该告警的唯一序列号 | E36: A | F36: / | G36: / | H36: R | I36: string(20) | J36: /
B37: Device.FaultMgmt.ExpeditedEvent.{i}.NotificationType | C37: NotificationType | D37: 通知类型 | E37: A | F37: / | G37: / | H37: R | I37: string | J37: /
B38: Device.FaultMgmt.ExpeditedEvent.{i}.FaultLocation | C38: FaultLocation | D38: 告警源定位信息 | E38: A | F38: / | G38: / | H38: R | I38: string(512) | J38: 表示故障源对应的资源对象信息，通常用管理对象实例（MOI）的DN表示。其中对于MOI的DN定义，5G皮基站参考《中国移动5G扩展型皮基站网管南向接口数据模型规范》相关说明，4G皮基站参考《中国移动一体化皮站_飞站基站设备网络管理南向接口数据配置模型规范》相关说明 | L38: 《中国移动无线三方设备综合OMC南向接口要求 第2部分：皮基站技术要求_0629》
B39: Device.FaultMgmt.ExpeditedEvent.{i}.ManagedObjectInstance | C39: ManagedObjectInstance | D39: 管理对象实例 | E39: A | F39: / | G39: / | H39: R | I39: string(512) | J39: 定义了承载该对象实例DN时发生的基站告警的信息对象等级的实例
B40: Device.FaultMgmt.ExpeditedEvent.{i}.EventType | C40: EventType | D40: 告警类型 | E40: A | F40: / | G40: / | H40: R | I40: string(64) | J40: 设备上报告警消息中的告警类型，包括通讯告警、环境告警、设备告警、处理错误告警、服务质量告警等
...

Sheet SE
A1: 归类 | B1: 网管数据模型(TR181) | C1: 参数名称 | D1: 中文名 | E1: 重要性 | F1: 北向Index | G1: 北向NRM参数映射 | H1: 网管读写权限 | I1: 类型 | J1: 描述 | K1: 来源 | L1: 备注
A2: 日志参数管理 | B2: Device.LogMgmt.PeriodicUploadEnable | C2: PeriodicUploadEnable | D2: 日志周期上传使能开关 | E2: A | F2: / | G2: / | H2: RW | I2: boolean | J2: (0=false,1=true),禁止或启用将设备日志周期性地发送到指定的文件服务器。在使能开关开启的情况下，如果还未达到上报周期，设备日志文件已达到存储容量上限，则应立即将该时段的增量日志上报到HeMS，并开启一个新的上报周期的要求。 | K2: 中国移动5G一体化皮基站扩展型一体化皮基站网管南向接口技术要求v1.1.1.docx
B3: Device.LogMgmt.URL | C3: URL | D3: 日志上传URL | E3: A | H3: RW | I3: string(256) | J3: 指定了目的日志的位置，没有以任何方式指明需要上传的本地文件的名字和位置
B4: Device.LogMgmt.Username | C4: Username | D4: 日志管理用户名 | E4: A | H4: RW | I4: string(256) | J4: 用户名用于设备到日志服务器的鉴权，如果不需要鉴权，此字符串为空，当PeriodicUploadEnable=true时，才生效。
B5: Device.LogMgmt.Password | C5: Password | D5: 日志管理密码 | E5: A | H5: RW | I5: string(256) | J5: 密码用于设备到日志服务器的鉴权，如果不需要鉴权，此字符串为空 当为读时，该参数返回一个空字符串，而不是一个实际的值，当PeriodicUploadEnable=true时，才生效。
B6: Device.LogMgmt.PeriodicUploadInterval | C6: PeriodicUploadInterval | D6: 日志周期上传时间间隔 | E6: A | H6: RW | I6: unsignedInt[1:65535] | J6: (300,600,900,1800,3600)
B7: Device.LogMgmt.LogLevel | C7: LogLevel | D7: 日志重要等级 | E7: A | H7: RW | I7: string(64) | J7: 日志重要等级： Enumerate{ASSERT_LOG;ERROR;WARN;INFO;DEBUG;VERBOSE}

Sheet SF
A1: 归类 | B1: 网管数据模型(TR181) | C1: 参数名称 | D1: 中文名 | E1: 重要性 | F1: 北向Index | G1: 北向NRM参数映射 | H1: 网管读写权限 | I1: 类型 | J1: 描述 | K1: 来源 | L1: 备注
A2: AMF地址 | B2: Device.Services.FAPService.{i}.FAPControl.NR.AMFPoolConfigParam.{i}.AmfName | C2: AMFName | D2: AMFName | E2: A | F2: / | G2: / | H2: R | I2: string(150) | J2: / | K2: NRM数据配置要求 | L2: 修正参数类型为string(6)
B3: Device.Services.FAPService.{i}.FAPControl.NR.AMFPoolConfigParam.{i}.PLMNID | C3: PLMNID | D3: AMFPLMN标识 | E3: A | F3: / | G3: / | H3: RW | I3: string(6) | J3: 核心网相关参数，初始化网管通过TR069协议报文ParameterList字段下发扩展型皮基站 | K3: NRM数据配置要求 | L3: 修正参数类型为string(6)
B4: Device.Services.FAPService.{i}.FAPControl.NR.AMFPoolConfigParam.{i}.GUAMI.{i}.AmfRegionID | C4: AMFRegionID | D4: AMFRegionID | E4: A | F4: / | G4: / | H4: R | I4: string(8) | J4: 核心网相关参数，初始化网管通过TR069协议报文ParameterList字段下发扩展型皮基站 | K4: NRM数据配置要求
B5: Device.Services.FAPService.{i}.FAPControl.NR.AMFPoolConfigParam.{i}.GUAMI.{i}.AmfSetID | C5: AMFSetID | D5: AMFSetID | E5: A | F5: / | G5: / | H5: R | I5: string(10) | J5: 核心网相关参数，初始化网管通过TR069协议报文ParameterList字段下发扩展型皮基站 | K5: NRM数据配置要求
B6: Device.Services.FAPService.{i}.FAPControl.NR.AMFPoolConfigParam.{i}.GUAMI.{i}.AmfPointer | C6: AMFPointer | D6: AMFPointer | E6: A | F6: / | G6: / | H6: R | I6: string(6) | J6: 核心网相关参数，初始化网管通过TR069协议报文ParameterList字段下发扩展型皮基站
B7: Device.Services.FAPService.{i}.FAPControl.NR.AMFPoolConfigParam.{i}.RelativeAmfCapacity | C7: RelativeAMFCapacity | D7: RelativeAMFCapacity | E7: A | F7: / | G7: / | H7: R | I7: unsignedInt[0:255] | J7: / | K7: NRM数据配置要求
B8: Device.Services.FAPService.{i}.FAPControl.NR.AMFPoolConfigParam.{i}.AmfIP1 | C8: AMFIP1 | D8: AMFIP1 | E8: A | F8: / | G8: / | H8: RW | I8: string(64) | J8: 核心网相关参数，初始化网管通过TR069协议报文ParameterList字段下发扩展型皮基站 | K8: NRM数据配置要求
B9: Device.Services.FAPService.{i}.FAPControl.NR.AMFPoolConfigParam.{i}.AmfIP2 | C9: AMFIP2 | D9: AMFIP2 | E9: A | F9: / | G9: / | H9: RW | I9: string(64) | J9: 核心网相关参数，初始化网管通过TR070协议报文ParameterList字段下发扩展型皮基站 | K9: NRM数据配置要求
A10: Xn链接信息 | B10: Device.Services.FAPService.{i}.FAPControl.NR.XnIpAddrMapInfo.{i}.TAISupportList.{i}.TAC | C10: TAC | D10: 跟踪区编码 | E10: A | F10: / | G10: / | H10: R | I10: string(24) | J10: / | K10: 3GPP,TS38.423,9.2.3.20
B11: Device.Services.FAPService.{i}.FAPControl.NR.XnIpAddrMapInfo.{i}.TAISupportList.{i}.BroadcastPLMNs.{i}.PLMNID | C11: PLMNID | D11: PLMNID | E11: A | F11: / | G11: / | H11: R | I11: string(6) | J11: / | K11: 3GPP,TS38.423,9.2.3.20
B12: Device.Services.FAPService.{i}.FAPControl.NR.XnIpAddrMapInfo.{i}.gNBID | C12: gNBID | D12: gNBID | E12: A | F12: / | G12: / | H12: RW | I12: unsignedInt | J12: /
B13: Device.Services.FAPService.{i}.FAPControl.NR.XnIpAddrMapInfo.{i}.RemoteAddress | C13: RemoteAddress | D13: 对端IP | E13: A | F13: / | G13: / | H13: RW | I13: string(64) | J13: / | K13: NRM数据配置要求
B14: Device.Services.FAPService.{i}.FAPControl.NR.XnIpAddrMapInfo.{i}.SubnetMask | C14: SubnetMask | D14: 子网掩码 | E14: A | F14: / | G14: / | H14: R | I14: string(64) | J14: / | K14: NRM数据配置要求 | L14: 增加子网掩码用于配置Xn连接地址
B15: Device.Services.FAPService.{i}.FAPControl.NR.XnIpAddrMapInfo.{i}.LocalAddress | C15: LocalAddress | D15: 本端地址 | E15: A | F15: / | G15: / | H15: R | I15: string(64) | J15: / | K15: NRM数据配置要求
A16: gNB参数 | B16: Device.Services.FAPService.{i}.FAPControl.NR.RAN.Common.gNBIdLength | C16: gNBIdLength | D16: gNB标识长度 | E16: A | F16: AG | G16: gNBIdLength | H16: RW | I16: unsignedint[22:32] | J16: gNB标识长度 | K16: 3GPP TS38.413 | L16: 根据设备规范，gNBIdLength取值为24
B17: Device.Services.FAPService.{i}.FAPControl.NR.RAN.Common.gNBId | C17: gNBId | D17: gNB标识 | E17: A | F17: AG | G17: gNBId | H17: RW | I17: unsignedInt[0:‭4294967295‬] | J17: 小区gNBiD(32bit) | K17: TR系列规范(TR098/TR181/TR196)/NRM数据配置要求 | L17: This IE is used to globally identify a gNB. Equal to the leftmost bits of the NR Cell Identity IE contained in the NR CGI IE of each cell served by the gNB.
B18: Device.Services.FAPService.{i}.FAPControl.NR.RAN.Common.gNBName | C18: gNBName | D18: gNB名称 | E18: A | F18: AA&AF | G18: UserLabel | H18: RW | I18: string(150) | J18: gNB名称 | K18: 自定义
B19: Device.Services.FAPService.{i}.FAPControl.NR.RAN.Common.AdminState | C19: AdminState | D19: 基站的管理状态 | E19: A | F19: AA | G19: AdministrativeState | H19: RW | I19: unsignedInt[1:3] | J19: 管理的状态，取值范围为{Locked，Unlocked，ShuttingDown}，依据x.731的状态转换来上报。 | K19: 《5G SA gNB网元统计数据需求规范-NRM(V1.4.2)》

Sheet SG
A1: 归类 | B1: 网管数据模型(TR181) | C1: 参数名称 | D1: 中文名称 | E1: 重要性 | F1: 北向Index | G1: 北向NRM参数映射 | H1: 网管读写权限 | I1: 类型 | J1: 描述 | K1: 来源 | L1: 备注
A2: SON参数管理 | B2: Device.Services.FAPService.{i}.FAPControl.NR.SelfConfig.SONConfigParam.SONSysMode | C2: SONSysMode | D2: SON系统模式 | E2: CB | F2: / | G2: / | H2: RW | I2: string | J2: SON系统模式（分布式，集中式）,{Distributed，Centralized} | K2: NRM数据配置要求
B3: Device.Services.FAPService.{i}.FAPControl.NR.SelfConfig.SONConfigParam.SONWorkMode | C3: SONWorkMode | D3: SON模式设置 | E3: CB | F3: / | G3: / | H3: RW | I3: string | J3: 自优化模式（自由模式，受控模式）,{Free，Control}，自由模式下系统给出的参数优化建议无需人工确认，可直接执行；受控模式下系统给出的参数优化建议需要人工确认同意才可执行，否则（不同意或超时）不执行优化，保持原参数配置不变。
B4: Device.Services.FAPService.{i}.FAPControl.NR.SelfConfig.SONConfigParam.PCI.Enable | C4: Enable | D4: PCI冲突和混淆检测功能开关 | E4: A | F4: / | G4: / | H4: RW | I4: boolean | J4: PCI冲突和混淆检测功能开关,(0=false,1=true) | L4: <<5G NR扩展型皮基站设备规范—SON分册>>
B5: Device.Services.FAPService.{i}.FAPControl.NR.SelfConfig.SONConfigParam.PCIOptEnable | C5: PCIOptEnable | D5: PCI自优化算法开关 | E5: CB | F5: / | G5: / | H5: RW | I5: boolean | J5: PCI自优化算法开关,(0=false,1=true)
B6: Device.Services.FAPService.{i}.FAPControl.NR.SelfConfig.SONConfigParam.PCIReconfigWaitTime | C6: PCIReconfigWaitTime | D6: PCI重配等待定时器 | E6: CB | F6: / | G6: / | H6: RW | I6: unsignedInt | J6: 表征PCI重配置等待时间，在PCI自优化阶段，该计时器超时后使用新的PCI
B7: Device.Services.FAPService.{i}.FAPControl.NR.SelfConfig.SONConfigParam.CandidateARFCNList | C7: CandidateARFCNList | D7: 候选频点列表 | E7: CB | F7: / | G7: / | H7: RW | I7: string(64) | J7: 候选频点列表
B8: Device.Services.FAPService.{i}.FAPControl.NR.SelfConfig.SONConfigParam.CandidatePCIList | C8: CandidatePCIList | D8: 候选PCI列表 | E8: CB | F8: / | G8: / | H8: RW | I8: string(64) | J8: 候选PCI列表
B9: Device.Services.FAPService.{i}.FAPControl.NR.SelfConfig.SONConfigParam.ANR.Enable | C9: Enable | D9: ANR算法总开关 | E9: A | F9: / | G9: / | H9: RW | I9: boolean | J9: (0=false,1=true)，ANR算法总开关 | L9: <<5G NR扩展型皮基站设备规范—SON分册>>
B10: Device.Services.FAPService.{i}.FAPControl.NR.SelfConfig.SONConfigParam.ANR.InterFeqEnable | C10: InterFeqEnable | D10: NR异频ANR算法开关 | E10: A | F10: / | G10: / | H10: RW | I10: boolean | J10: (0=false,1=true)，NR异频ANR算法开关 | L10: <<5G NR扩展型皮基站设备规范—SON分册>>
B11: Device.Services.FAPService.{i}.FAPControl.NR.SelfConfig.SONConfigParam.ANR.InterFeqCandidateARFCNList | C11: InterFeqCandidateARFCNList | D11: SSB频点号 | E11: A | H11: RW | I11: string(64) | J11: 小区载频的SSB ARFCN列表，ARFCN间以“,”分割 | L11: <<5G NR扩展型皮基站设备规范—SON分册>>
B12: Device.Services.FAPService.{i}.FAPControl.NR.SelfConfig.SONConfigParam.ANR.EUTRANEnable | C12: EUTRANEnable | D12: E-UTRAN异系统ANR算法开关 | E12: A | F12: / | G12: / | H12: RW | I12: boolean | J12: (0=false,1=true)，E-UTRAN异系统ANR算法开关 | L12: <<5G NR扩展型皮基站设备规范—SON分册>>
B13: Device.Services.FAPService.{i}.FAPControl.NR.SelfConfig.SONConfigParam.ANR.BiNRCellEnable | C13: BiNRCellEnable | D13: ANR双向邻区添加开关 | E13: A | F13: / | G13: / | H13: RW | I13: boolean | J13: (0=false,2=true)，ANR双向邻区添加开关 | L13: <<5G NR扩展型皮基站设备规范—SON分册>>
B14: Device.Services.FAPService.{i}.FAPControl.NR.SelfConfig.SONConfigParam.ANR.RSRPReferenceEnable | C14: RSRPReferenceEnable | D14: 事件性MR添加邻区依照绝对电平开关 | E14: A | F14: / | G14: / | H14: RW | I14: boolean | J14: (0=false,1=true)，该开关打开后，添加邻区需同时考虑绝对电平和相对电平 | L14: <<5G NR扩展型皮基站设备规范—SON分册>>
B15: Device.Services.FAPService.{i}.FAPControl.NR.SelfConfig.SONConfigParam.ANR.A3RSRPOffset | C15: A3RSRPOffset | D15: 邻区添加相对电平强度 | E15: A | F15: / | G15: / | H15: RW | I15: unsignedInt[0:127] | J15: 用于NR测量中,邻区添加相对电平强度，与A3 RSRP的偏移量 | L15: <<5G NR扩展型皮基站设备规范—SON分册>>
B16: Device.Services.FAPService.{i}.FAPControl.NR.SelfConfig.SONConfigParam.ANR.RSRPThreshold | C16: RSRPThreshold | D16: 邻区添加绝对电平强度 | E16: A | F16: / | G16: / | H16: RW | I16: unsignedInt[0:127] | J16: 用于NR测量中,邻区添加绝对电平强度，测量的RSRP | L16: <<5G NR扩展型皮基站设备规范—SON分册>>
B17: Device.Services.FAPService.{i}.FAPControl.NR.SelfConfig.SONConfigParam.ANR.KPIPeriod | C17: KPIPeriod | D17: 邻区优化KPI统计周期 | E17: A | F17: / | G17: / | H17: RW | I17: unsignedInt | J17: 包括邻区邻区添加、删除、属性调整相关的KPI，例如发现次数，切换次数，切换成功率等KPI的统计周期 以分钟为单位，支持按天、小时、分钟为粒度进行设置 | L17: <<5G NR扩展型皮基站设备规范—SON分册>>
B18: Device.Services.FAPService.{i}.FAPControl.NR.SelfConfig.SONConfigParam.ANR.AutoAdjustEnable | C18: AutoAdjustEnable | D18: 邻区属性自动调整的使能开关 | E18: A | F18: / | G18: / | H18: RW | I18: boolean | J18: (0=false,1=true)，开启该开关后，邻区属性自动调整机制生效 | L18: <<5G NR扩展型皮基站设备规范—SON分册>>
B19: Device.Services.FAPService.{i}.FAPControl.NR.SelfConfig.SONConfigParam.ANR.BlackList.NoHOThreshold | C19: NoHOThreshold | D19: 邻区被设为黑名单的切换次数门限 | E19: A | F19: / | G19: / | H19: RW | I19: unsignedInt | J19: 若在统计周期内切换次数高于此门限且成功率低于此门限，则系统自动将邻区设置为“No HO” | L19: <<5G NR扩展型皮基站设备规范—SON分册>>
B20: Device.Services.FAPService.{i}.FAPControl.NR.SelfConfig.SONConfigParam.ANR.BlackList.HOSuccessThreshold | C20: HOSuccessThreshold | D20: 邻区被设为黑名单的切换成功率门限 | E20: A | F20: / | G20: / | H20: RW | I20: unsignedInt[0:100] | J20: 若在统计周期内切换次数高于此门限且成功率低于此门限，则系统自动将邻区设置为“No HO”，指切换成功率百分比，例如：填写为“50”指50%的切换成功率 | L20: <<5G NR扩展型皮基站设备规范—SON分册>>
B21: Device.Services.FAPService.{i}.FAPControl.NR.SelfConfig.SONConfigParam.ANR.AutoRemoveEnable | C21: AutoRemoveEnable | D21: 邻区自动删除的使能开关 | E21: A | F21: / | G21: / | H21: RW | I21: boolean | J21: (0=false,1=true)，开启该开关后，邻区自动删除机制生效 | L21: <<5G NR扩展型皮基站设备规范—SON分册>>
B22: Device.Services.FAPService.{i}.FAPControl.NR.SelfConfig.SONConfigParam.ANR.AutoRemovePeriod | C22: AutoRemovePeriod | D22: 邻区自动删除功能触发周期 | E22: A | F22: / | G22: / | H22: RW | I22: unsignedInt | J22: 以分钟为单位，支持按天、小时、分钟为粒度进行设置 | L22: <<5G NR扩展型皮基站设备规范—SON分册>>
B23: Device.Services.FAPService.{i}.FAPControl.NR.SelfConfig.SONConfigParam.ANR.AutoRemoveMaxCell | C23: AutoRemoveMaxCell | D23: 邻区自动删除功能单周期内可删除最大个数 | E23: A | F23: / | G23: / | H23: RW | I23: unsignedInt | J23: 支持单周期内可删除最大个数可配置 | L23: <<5G NR扩展型皮基站设备规范—SON分册>>
B24: Device.Services.FAPService.{i}.FAPControl.NR.SelfConfig.SONConfigParam.ARFCNEnable | C24: ARFCNEnable | D24: 频点自配置算法开关 | E24: CB | F24: / | G24: / | H24: RW | I24: boolean | J24: (0=false,1=true)，频点自配置算法开关 | L24: 扩展型皮基站重要性为CB
B25: Device.Services.FAPService.{i}.FAPControl.NR.SelfConfig.SONConfigParam.MaxNRNeighbourCellNum | C25: MaxNRNeighbourCellNum | D25: 最大NR邻区数 | E25: CB | F25: / | G25: / | H25: RW | I25: unsignedInt | J25: 最大NR邻区数
B26: Device.Services.FAPService.{i}.FAPControl.NR.SelfConfig.SONConfigParam.MaxLTENeighbourCellNum | C26: MaxLTENeighbourCellNum | D26: 最大LTE邻区数 | E26: CB | F26: / | G26: / | H26: RW | I26: unsignedInt | J26: 最大LTE邻区数
B27: Device.Services.FAPService.{i}.FAPControl.NR.SelfConfig.SONConfigParam.ReSynCellEnable | C27: ReSynCellEnable | D27: 重新同步小区使能开关 | E27: CB | F27: / | G27: / | H27: RW | I27: boolean | J27: (0=false,1=true),手动触发重新同步小区使能开关，取值为true时立即执行小区重新同步流程
B28: Device.Services.FAPService.{i}.FAPControl.NR.SelfConfig.SONConfigParam.PowerEnable | C28: PowerEnable | D28: 功率自配置算法开关 | E28: CB | F28: / | G28: / | H28: RW | I28: boolean | J28: (0=false,1=true),基站发射功率自配值算法开关
B29: Device.Services.FAPService.{i}.FAPControl.NR.SelfConfig.SONConfigParam.NRSnifferFreqBandList | C29: NRSnifferFreqBandList | D29: NR侦听频段列表 | E29: CB | F29: / | G29: / | H29: RW | I29: string(64) | J29: NR侦听频段列表（NRSnifferFreqBandList和NRSnifferChannelList二选一）
B30: Device.Services.FAPService.{i}.FAPControl.NR.SelfConfig.SONConfigParam.NRSnifferChannelList | C30: NRSnifferChannelList | D30: NR侦听频点列表 | E30: CB | F30: / | G30: / | H30: RW | I30: string(64) | J30: NR侦听频点列表（ARFCN格式列表）（NRSnifferFreqBandList和NRSnifferChannelList二选一） | L30: 扩展型皮基站重要性为CB
B31: Device.Services.FAPService.{i}.FAPControl.NR.SelfConfig.SONConfigParam.LTESnifferFreqBandList | C31: LTESnifferFreqBandList | D31: LTE侦听频段列表 | E31: CB | F31: / | G31: / | H31: RW | I31: string(64) | J31: LTE侦听频段列表(188000..192000,257000..262000,230000..237000)频段随机组合（LTESnifferFreqBandList和LTESnifferChannelList二选一）
B32: Device.Services.FAPService.{i}.FAPControl.NR.SelfConfig.SONConfigParam.LTESnifferChannelList | C32: LTESnifferChannelList | D32: LTE侦听频点列表 | E32: CB | F32: / | G32: / | H32: RW | I32: string(64) | J32: LTE侦听频点列表（ARFCN格式列表）（LTESnifferFreqBandList和LTESnifferChannelList二选一） | L32: 扩展型皮基站重要性为CB
B33: Device.Services.FAPService.{i}.FAPControl.NR.SelfConfig.SONConfigParam.MROEnable | C33: MROEnable | D33: 邻区鲁棒性优化功能开关 | E33: CB | F33: / | G33: / | H33: RW | I33: boolean | J33: 邻区鲁棒性优化功能开关
B34: Device.Services.FAPService.{i}.FAPControl.NR.SelfConfig.SONConfigParam.SHEnable | C34: SHEnable | D34: 自治愈功能开关 | E34: CB | F34: / | G34: / | H34: RW | I34: boolean | J34: 自治愈功能开关
B35: Device.Services.FAPService.{i}.FAPControl.NR.SelfConfig.SONConfigParam.SyncMode | C35: SyncMode | D35: 时钟同步模式 | E35: CB | F35: / | G35: / | H35: R | I35: string(64) | J35: 时钟同步模式，取值范围： GNSS IEEE1588V2 Sniffer Freedom | K35: 自定义
A36: 自动开站阶段 | B36: Device.Services.FAPService.{i}.FAPControl.SelfConfig.Startup.Stage | C36: Stage | D36: 开站阶段 | E36: A | F36: / | G36: / | H36: R | I36: unsignedInt[1:3] | J36: 开站阶段取值如下： 1:参数校验 2:参数配置 3:小区激活
A37: 自动开站结果 | B37: Device.Services.FAPService.{i}.FAPControl.SelfConfig.Startup.Status | C37: Status | D37: 开站状态 | E37: A | F37: / | G37: / | H37: R | I37: unsignedInt[1:2] | J37: 1：开站成功（全部小区被激活，即标记为开站成功） 2：开站失败（存在一个小区未激活，即标记为开站失败）
B38: Device.Services.FAPService.{i}.FAPControl.SelfConfig.Startup.FailureCause | C38: FailureCause | D38: 开站失败原因 | E38: A | F38: / | G38: / | H38: R | I38: string(512) | J38: 开站失败原因描述

Sheet SH
A1: 归类 | B1: 网管数据模型(TR181) | C1: 参数名称 | D1: 中文名 | E1: 重要性 | F1: 北向index | G1: 北向NRM参数映射 | H1: 网管读写权限 | I1: 类型 | J1: 描述 | K1: 来源
A2: 本地分流规则开关 | B2: Device.Services.FAPService.{i}.FAPControl.LocalBreakout.Enable | C2: Enable | D2: 本地分流规则总开关 | E2: CB | F2: / | G2: / | H2: RW | I2: boolean | J2: 0:关闭 1:开启
A3: IP五元组分流规则参数管理 | B3: Device.Services.FAPService.{i}.FAPControl.LocalBreakout.IpRules.Enable | C3: Enable | D3: IP五元组规则开关 | E3: CB | F3: / | G3: / | H3: RW | I3: boolean | J3: 0:关闭 1:开启
B4: Device.Services.FAPService.{i}.FAPControl.LocalBreakout.IpRules.RuleList.{i}.IPversion | C4: Ipversion | D4: IP版本 | E4: CB | F4: / | G4: / | H4: RW | I4: unsignedInt[1:2] | J4: 1:IPv4 2:IPv6
B5: Device.Services.FAPService.{i}.FAPControl.LocalBreakout.IpRules.RuleList.{i}.SourceIP | C5: SourceIP | D5: 源端IP地址 | E5: CB | F5: / | G5: / | H5: RW | I5: string(15) | J5: /
B6: Device.Services.FAPService.{i}.FAPControl.LocalBreakout.IpRules.RuleList.{i}.SourceMask | C6: SourceMask | D6: 源端子网掩码 | E6: CB | F6: / | G6: / | H6: RW | I6: string(15) | J6: /
B7: Device.Services.FAPService.{i}.FAPControl.LocalBreakout.IpRules.RuleList.{i}.SourceIPv6 | C7: SourceIPv6 | D7: 源端IPv6地址 | E7: CB | F7: / | G7: / | H7: RW | I7: string(64) | J7: /
B8: Device.Services.FAPService.{i}.FAPControl.LocalBreakout.IpRules.RuleList.{i}.SourcePrefixLength | C8: SourcePrefixLength | D8: 源端前缀长度 | E8: CB | F8: / | G8: / | H8: RW | I8: unsignedInt[1:128] | J8: /
B9: Device.Services.FAPService.{i}.FAPControl.LocalBreakout.IpRules.RuleList.{i}.SourcePort | C9: SourcePort | D9: 源端端口 | E9: CB | F9: / | G9: / | H9: RW | I9: string | J9: /
B10: Device.Services.FAPService.{i}.FAPControl.LocalBreakout.IpRules.RuleList.{i}.TargetIP | C10: TargetIP | D10: 目的端IP地址 | E10: CB | F10: / | G10: / | H10: RW | I10: string(15) | J10: /
B11: Device.Services.FAPService.{i}.FAPControl.LocalBreakout.IpRules.RuleList.{i}.TargetMask | C11: TargetMask | D11: 目的端子网掩码 | E11: CB | F11: / | G11: / | H11: RW | I11: string(15) | J11: /
B12: Device.Services.FAPService.{i}.FAPControl.LocalBreakout.IpRules.RuleList.{i}.TargetIPv6 | C12: TargetIPv6 | D12: 目的端IPv6地址 | E12: CB | F12: / | G12: / | H12: RW | I12: string(64) | J12: /
B13: Device.Services.FAPService.{i}.FAPControl.LocalBreakout.IpRules.RuleList.{i}.TargetPrefixLength | C13: TargetPrefixLength | D13: 目的端前缀长度 | E13: CB | F13: / | G13: / | H13: RW | I13: unsignedInt[1:128] | J13: /
B14: Device.Services.FAPService.{i}.FAPControl.LocalBreakout.IpRules.RuleList.{i}.TargetPort | C14: TargetPort | D14: 目的端端口 | E14: CB | F14: / | G14: / | H14: RW | I14: string | J14: /
B15: Device.Services.FAPService.{i}.FAPControl.LocalBreakout.IpRules.RuleList.{i}.ProtocolType | C15: ProtocolType | D15: 传输协议 | E15: CB | F15: / | G15: / | H15: RW | I15: string | J15: /
A16: DNS分流规则参数管理 | B16: Device.Services.FAPService.{i}.FAPControl.LocalBreakout.DnsRules.Enable | C16: Enable | D16: DNS规则开关 | E16: CB | F16: / | G16: / | H16: RW | I16: boolean | J16: 0:关闭 1:开启
B17: Device.Services.FAPService.{i}.FAPControl.LocalBreakout.DnsRules.RuleList.{i}.DomainName | C17: DomainName | D17: 域名 | E17: CB | F17: / | G17: / | H17: RW | I17: string(128) | J17: /
B18: Device.Services.FAPService.{i}.FAPControl.LocalBreakout.DnsRules.RuleList.{i}.DomainIpList.{i}.DomainIp | C18: DomainIp | D18: IP地址 | E18: CB | F18: / | G18: / | H18: RW | I18: string(40) | J18: /
A19: PLMN分流规则参数管理 | B19: Device.Services.FAPService.{i}.FAPControl.LocalBreakout.PlmnRules.Enable | C19: Enable | D19: PLMN规则开关 | E19: CB | F19: / | G19: / | H19: RW | I19: boolean | J19: 0:关闭 1:开启
B20: Device.Services.FAPService.{i}.FAPControl.LocalBreakout.PlmnRules.RuleList.{i}.PLMNID | C20: PLMNID | D20: 小区PLMNID | E20: CB | F20: / | G20: PlmnIdList | H20: RW | I20: string(6) | J20: 由MCC和MNC组成 | K20: TR系列规范(TR098/TR181/TR196)/NRM数据配置要求
